package com.zalthrion.zylroth.world.mapstructures;

import java.util.Random;

import net.minecraft.block.Block;
import net.minecraft.init.Blocks;
import net.minecraft.util.math.BlockPos;
import net.minecraft.world.World;
import net.minecraft.world.gen.feature.WorldGenerator;

public class BenzennHut extends WorldGenerator {
	@Override public boolean generate(World world, Random rand, BlockPos pos) {
		this.generate(world, rand, pos.getX(), pos.getY(), pos.getZ());
		return true;
	}
	
	@Deprecated private void setBlock(World world, int i, int j, int k, Block block, int meta) {
		world.setBlockState(new BlockPos(i, j, k), block.getStateFromMeta(meta));
	}
	
	@Deprecated public boolean generate(World world, Random rand, int i, int j, int k) {
		this.setBlock(world, i + 0, j + 0, k + 5, Blocks.SNOW, 0);
		this.setBlock(world, i + 0, j + 0, k + 6, Blocks.SNOW, 0);
		this.setBlock(world, i + 0, j + 0, k + 7, Blocks.SNOW, 0);
		this.setBlock(world, i + 0, j + 0, k + 8, Blocks.SNOW, 0);
		this.setBlock(world, i + 0, j + 0, k + 9, Blocks.SNOW, 0);
		this.setBlock(world, i + 0, j + 0, k + 10, Blocks.SNOW, 0);
		this.setBlock(world, i + 1, j + 0, k + 4, Blocks.SNOW, 0);
		this.setBlock(world, i + 1, j + 0, k + 5, Blocks.SNOW, 0);
		this.setBlock(world, i + 1, j + 0, k + 6, Blocks.SNOW, 0);
		this.setBlock(world, i + 1, j + 0, k + 7, Blocks.SNOW, 0);
		this.setBlock(world, i + 1, j + 0, k + 8, Blocks.SNOW, 0);
		this.setBlock(world, i + 1, j + 0, k + 9, Blocks.SNOW, 0);
		this.setBlock(world, i + 1, j + 0, k + 10, Blocks.SNOW, 0);
		this.setBlock(world, i + 1, j + 0, k + 11, Blocks.SNOW, 0);
		this.setBlock(world, i + 1, j + 1, k + 5, Blocks.SNOW, 0);
		this.setBlock(world, i + 1, j + 1, k + 6, Blocks.SNOW, 0);
		this.setBlock(world, i + 1, j + 1, k + 7, Blocks.SNOW, 0);
		this.setBlock(world, i + 1, j + 1, k + 8, Blocks.SNOW, 0);
		this.setBlock(world, i + 1, j + 1, k + 9, Blocks.SNOW, 0);
		this.setBlock(world, i + 1, j + 1, k + 10, Blocks.SNOW, 0);
		this.setBlock(world, i + 2, j + 0, k + 3, Blocks.SNOW, 0);
		this.setBlock(world, i + 2, j + 0, k + 4, Blocks.SNOW, 0);
		this.setBlock(world, i + 2, j + 0, k + 5, Blocks.SNOW, 0);
		this.setBlock(world, i + 2, j + 0, k + 6, Blocks.SNOW, 0);
		this.setBlock(world, i + 2, j + 0, k + 7, Blocks.SNOW, 0);
		this.setBlock(world, i + 2, j + 0, k + 8, Blocks.SNOW, 0);
		this.setBlock(world, i + 2, j + 0, k + 9, Blocks.SNOW, 0);
		this.setBlock(world, i + 2, j + 0, k + 10, Blocks.SNOW, 0);
		this.setBlock(world, i + 2, j + 0, k + 11, Blocks.SNOW, 0);
		this.setBlock(world, i + 2, j + 0, k + 12, Blocks.SNOW, 0);
		this.setBlock(world, i + 2, j + 1, k + 4, Blocks.SNOW, 0);
		this.setBlock(world, i + 2, j + 1, k + 5, Blocks.SNOW, 0);
		this.setBlock(world, i + 2, j + 1, k + 6, Blocks.SNOW, 0);
		this.setBlock(world, i + 2, j + 1, k + 7, Blocks.SNOW, 0);
		this.setBlock(world, i + 2, j + 1, k + 8, Blocks.SNOW, 0);
		this.setBlock(world, i + 2, j + 1, k + 9, Blocks.SNOW, 0);
		this.setBlock(world, i + 2, j + 1, k + 10, Blocks.SNOW, 0);
		this.setBlock(world, i + 2, j + 1, k + 11, Blocks.SNOW, 0);
		this.setBlock(world, i + 2, j + 2, k + 5, Blocks.SNOW, 0);
		this.setBlock(world, i + 2, j + 2, k + 6, Blocks.SNOW, 0);
		this.setBlock(world, i + 2, j + 2, k + 7, Blocks.SNOW, 0);
		this.setBlock(world, i + 2, j + 2, k + 8, Blocks.SNOW, 0);
		this.setBlock(world, i + 2, j + 2, k + 9, Blocks.SNOW, 0);
		this.setBlock(world, i + 2, j + 2, k + 10, Blocks.SNOW, 0);
		this.setBlock(world, i + 3, j + 0, k + 2, Blocks.SNOW, 0);
		this.setBlock(world, i + 3, j + 0, k + 3, Blocks.SNOW, 0);
		this.setBlock(world, i + 3, j + 0, k + 4, Blocks.SNOW, 0);
		this.setBlock(world, i + 3, j + 0, k + 5, Blocks.SNOW, 0);
		this.setBlock(world, i + 3, j + 0, k + 6, Blocks.SNOW, 0);
		this.setBlock(world, i + 3, j + 0, k + 7, Blocks.SNOW, 0);
		this.setBlock(world, i + 3, j + 0, k + 8, Blocks.SNOW, 0);
		this.setBlock(world, i + 3, j + 0, k + 9, Blocks.SNOW, 0);
		this.setBlock(world, i + 3, j + 0, k + 10, Blocks.SNOW, 0);
		this.setBlock(world, i + 3, j + 0, k + 11, Blocks.SNOW, 0);
		this.setBlock(world, i + 3, j + 0, k + 12, Blocks.SNOW, 0);
		this.setBlock(world, i + 3, j + 0, k + 13, Blocks.SNOW, 0);
		this.setBlock(world, i + 3, j + 1, k + 3, Blocks.SNOW, 0);
		this.setBlock(world, i + 3, j + 1, k + 4, Blocks.SNOW, 0);
		this.setBlock(world, i + 3, j + 1, k + 5, Blocks.SNOW, 0);
		this.setBlock(world, i + 3, j + 1, k + 6, Blocks.SNOW, 0);
		this.setBlock(world, i + 3, j + 1, k + 7, Blocks.SNOW, 0);
		this.setBlock(world, i + 3, j + 1, k + 8, Blocks.SNOW, 0);
		this.setBlock(world, i + 3, j + 1, k + 9, Blocks.SNOW, 0);
		this.setBlock(world, i + 3, j + 1, k + 10, Blocks.SNOW, 0);
		this.setBlock(world, i + 3, j + 1, k + 11, Blocks.SNOW, 0);
		this.setBlock(world, i + 3, j + 1, k + 12, Blocks.SNOW, 0);
		this.setBlock(world, i + 3, j + 2, k + 4, Blocks.SNOW, 0);
		this.setBlock(world, i + 3, j + 2, k + 5, Blocks.SNOW, 0);
		this.setBlock(world, i + 3, j + 2, k + 6, Blocks.SNOW, 0);
		this.setBlock(world, i + 3, j + 2, k + 7, Blocks.SNOW, 0);
		this.setBlock(world, i + 3, j + 2, k + 8, Blocks.SNOW, 0);
		this.setBlock(world, i + 3, j + 2, k + 9, Blocks.SNOW, 0);
		this.setBlock(world, i + 3, j + 2, k + 10, Blocks.SNOW, 0);
		this.setBlock(world, i + 3, j + 2, k + 11, Blocks.SNOW, 0);
		this.setBlock(world, i + 4, j + 0, k + 1, Blocks.SNOW, 0);
		this.setBlock(world, i + 4, j + 0, k + 2, Blocks.SNOW, 0);
		this.setBlock(world, i + 4, j + 0, k + 3, Blocks.SNOW, 0);
		this.setBlock(world, i + 4, j + 0, k + 4, Blocks.SNOW, 0);
		this.setBlock(world, i + 4, j + 0, k + 5, Blocks.SNOW, 0);
		this.setBlock(world, i + 4, j + 0, k + 6, Blocks.SNOW, 0);
		this.setBlock(world, i + 4, j + 0, k + 7, Blocks.SNOW, 0);
		this.setBlock(world, i + 4, j + 0, k + 8, Blocks.SNOW, 0);
		this.setBlock(world, i + 4, j + 0, k + 9, Blocks.SNOW, 0);
		this.setBlock(world, i + 4, j + 0, k + 10, Blocks.SNOW, 0);
		this.setBlock(world, i + 4, j + 0, k + 11, Blocks.SNOW, 0);
		this.setBlock(world, i + 4, j + 0, k + 12, Blocks.SNOW, 0);
		this.setBlock(world, i + 4, j + 0, k + 13, Blocks.SNOW, 0);
		this.setBlock(world, i + 4, j + 0, k + 14, Blocks.SNOW, 0);
		this.setBlock(world, i + 4, j + 1, k + 2, Blocks.SNOW, 0);
		this.setBlock(world, i + 4, j + 1, k + 3, Blocks.SNOW, 0);
		this.setBlock(world, i + 4, j + 1, k + 4, Blocks.SNOW, 0);
		this.setBlock(world, i + 4, j + 1, k + 5, Blocks.SNOW, 0);
		this.setBlock(world, i + 4, j + 1, k + 6, Blocks.SNOW, 0);
		this.setBlock(world, i + 4, j + 1, k + 7, Blocks.SNOW, 0);
		this.setBlock(world, i + 4, j + 1, k + 8, Blocks.SNOW, 0);
		this.setBlock(world, i + 4, j + 1, k + 9, Blocks.SNOW, 0);
		this.setBlock(world, i + 4, j + 1, k + 10, Blocks.SNOW, 0);
		this.setBlock(world, i + 4, j + 1, k + 11, Blocks.SNOW, 0);
		this.setBlock(world, i + 4, j + 1, k + 12, Blocks.SNOW, 0);
		this.setBlock(world, i + 4, j + 1, k + 13, Blocks.SNOW, 0);
		this.setBlock(world, i + 4, j + 2, k + 3, Blocks.SNOW, 0);
		this.setBlock(world, i + 4, j + 2, k + 4, Blocks.SNOW, 0);
		this.setBlock(world, i + 4, j + 2, k + 5, Blocks.SNOW, 0);
		this.setBlock(world, i + 4, j + 2, k + 6, Blocks.SNOW, 0);
		this.setBlock(world, i + 4, j + 2, k + 7, Blocks.SNOW, 0);
		this.setBlock(world, i + 4, j + 2, k + 8, Blocks.SNOW, 0);
		this.setBlock(world, i + 4, j + 2, k + 9, Blocks.SNOW, 0);
		this.setBlock(world, i + 4, j + 2, k + 10, Blocks.SNOW, 0);
		this.setBlock(world, i + 4, j + 2, k + 11, Blocks.SNOW, 0);
		this.setBlock(world, i + 4, j + 2, k + 12, Blocks.SNOW, 0);
		this.setBlock(world, i + 4, j + 3, k + 6, Blocks.STAINED_HARDENED_CLAY, 0);
		this.setBlock(world, i + 4, j + 3, k + 9, Blocks.STAINED_HARDENED_CLAY, 0);
		this.setBlock(world, i + 5, j + 0, k + 0, Blocks.SNOW, 0);
		this.setBlock(world, i + 5, j + 0, k + 1, Blocks.SNOW, 0);
		this.setBlock(world, i + 5, j + 0, k + 2, Blocks.SNOW, 0);
		this.setBlock(world, i + 5, j + 0, k + 3, Blocks.SNOW, 0);
		this.setBlock(world, i + 5, j + 0, k + 4, Blocks.SNOW, 0);
		this.setBlock(world, i + 5, j + 0, k + 5, Blocks.SNOW, 0);
		this.setBlock(world, i + 5, j + 0, k + 6, Blocks.SNOW, 0);
		this.setBlock(world, i + 5, j + 0, k + 7, Blocks.SNOW, 0);
		this.setBlock(world, i + 5, j + 0, k + 8, Blocks.SNOW, 0);
		this.setBlock(world, i + 5, j + 0, k + 9, Blocks.SNOW, 0);
		this.setBlock(world, i + 5, j + 0, k + 10, Blocks.SNOW, 0);
		this.setBlock(world, i + 5, j + 0, k + 11, Blocks.SNOW, 0);
		this.setBlock(world, i + 5, j + 0, k + 12, Blocks.SNOW, 0);
		this.setBlock(world, i + 5, j + 0, k + 13, Blocks.SNOW, 0);
		this.setBlock(world, i + 5, j + 0, k + 14, Blocks.SNOW, 0);
		this.setBlock(world, i + 5, j + 0, k + 15, Blocks.SNOW, 0);
		this.setBlock(world, i + 5, j + 1, k + 1, Blocks.SNOW, 0);
		this.setBlock(world, i + 5, j + 1, k + 2, Blocks.SNOW, 0);
		this.setBlock(world, i + 5, j + 1, k + 3, Blocks.SNOW, 0);
		this.setBlock(world, i + 5, j + 1, k + 4, Blocks.SNOW, 0);
		this.setBlock(world, i + 5, j + 1, k + 5, Blocks.SNOW, 0);
		this.setBlock(world, i + 5, j + 1, k + 6, Blocks.STAINED_HARDENED_CLAY, 0);
		this.setBlock(world, i + 5, j + 1, k + 7, Blocks.STAINED_HARDENED_CLAY, 0);
		this.setBlock(world, i + 5, j + 1, k + 8, Blocks.STAINED_HARDENED_CLAY, 0);
		this.setBlock(world, i + 5, j + 1, k + 9, Blocks.STAINED_HARDENED_CLAY, 0);
		this.setBlock(world, i + 5, j + 1, k + 10, Blocks.SNOW, 0);
		this.setBlock(world, i + 5, j + 1, k + 11, Blocks.SNOW, 0);
		this.setBlock(world, i + 5, j + 1, k + 12, Blocks.SNOW, 0);
		this.setBlock(world, i + 5, j + 1, k + 13, Blocks.SNOW, 0);
		this.setBlock(world, i + 5, j + 1, k + 14, Blocks.SNOW, 0);
		this.setBlock(world, i + 5, j + 2, k + 2, Blocks.SNOW, 0);
		this.setBlock(world, i + 5, j + 2, k + 3, Blocks.SNOW, 0);
		this.setBlock(world, i + 5, j + 2, k + 4, Blocks.SNOW, 0);
		this.setBlock(world, i + 5, j + 2, k + 5, Blocks.SNOW, 0);
		this.setBlock(world, i + 5, j + 2, k + 6, Blocks.STAINED_HARDENED_CLAY, 0);
		this.setBlock(world, i + 5, j + 2, k + 7, Blocks.STAINED_HARDENED_CLAY, 0);
		this.setBlock(world, i + 5, j + 2, k + 8, Blocks.STAINED_HARDENED_CLAY, 0);
		this.setBlock(world, i + 5, j + 2, k + 9, Blocks.STAINED_HARDENED_CLAY, 0);
		this.setBlock(world, i + 5, j + 2, k + 10, Blocks.SNOW, 0);
		this.setBlock(world, i + 5, j + 2, k + 11, Blocks.SNOW, 0);
		this.setBlock(world, i + 5, j + 2, k + 12, Blocks.SNOW, 0);
		this.setBlock(world, i + 5, j + 2, k + 13, Blocks.SNOW, 0);
		this.setBlock(world, i + 5, j + 3, k + 4, Blocks.HARDENED_CLAY, 0);
		this.setBlock(world, i + 5, j + 3, k + 5, Blocks.HARDENED_CLAY, 0);
		this.setBlock(world, i + 5, j + 3, k + 6, Blocks.STAINED_HARDENED_CLAY, 0);
		this.setBlock(world, i + 5, j + 3, k + 9, Blocks.STAINED_HARDENED_CLAY, 0);
		this.setBlock(world, i + 5, j + 3, k + 10, Blocks.HARDENED_CLAY, 0);
		this.setBlock(world, i + 5, j + 3, k + 11, Blocks.HARDENED_CLAY, 0);
		this.setBlock(world, i + 5, j + 4, k + 5, Blocks.STAINED_HARDENED_CLAY, 8);
		this.setBlock(world, i + 5, j + 4, k + 6, Blocks.STAINED_HARDENED_CLAY, 0);
		this.setBlock(world, i + 5, j + 4, k + 9, Blocks.STAINED_HARDENED_CLAY, 0);
		this.setBlock(world, i + 5, j + 4, k + 10, Blocks.STAINED_HARDENED_CLAY, 8);
		this.setBlock(world, i + 5, j + 5, k + 6, Blocks.STAINED_HARDENED_CLAY, 0);
		this.setBlock(world, i + 5, j + 5, k + 9, Blocks.STAINED_HARDENED_CLAY, 0);
		this.setBlock(world, i + 5, j + 6, k + 7, Blocks.STAINED_HARDENED_CLAY, 0);
		this.setBlock(world, i + 5, j + 6, k + 8, Blocks.STAINED_HARDENED_CLAY, 0);
		this.setBlock(world, i + 6, j + 0, k + 0, Blocks.SNOW, 0);
		this.setBlock(world, i + 6, j + 0, k + 1, Blocks.SNOW, 0);
		this.setBlock(world, i + 6, j + 0, k + 2, Blocks.SNOW, 0);
		this.setBlock(world, i + 6, j + 0, k + 3, Blocks.SNOW, 0);
		this.setBlock(world, i + 6, j + 0, k + 4, Blocks.SNOW, 0);
		this.setBlock(world, i + 6, j + 0, k + 5, Blocks.SNOW, 0);
		this.setBlock(world, i + 6, j + 0, k + 6, Blocks.SNOW, 0);
		this.setBlock(world, i + 6, j + 0, k + 7, Blocks.SNOW, 0);
		this.setBlock(world, i + 6, j + 0, k + 8, Blocks.SNOW, 0);
		this.setBlock(world, i + 6, j + 0, k + 9, Blocks.SNOW, 0);
		this.setBlock(world, i + 6, j + 0, k + 10, Blocks.SNOW, 0);
		this.setBlock(world, i + 6, j + 0, k + 11, Blocks.SNOW, 0);
		this.setBlock(world, i + 6, j + 0, k + 12, Blocks.SNOW, 0);
		this.setBlock(world, i + 6, j + 0, k + 13, Blocks.SNOW, 0);
		this.setBlock(world, i + 6, j + 0, k + 14, Blocks.SNOW, 0);
		this.setBlock(world, i + 6, j + 0, k + 15, Blocks.SNOW, 0);
		this.setBlock(world, i + 6, j + 1, k + 1, Blocks.SNOW, 0);
		this.setBlock(world, i + 6, j + 1, k + 2, Blocks.SNOW, 0);
		this.setBlock(world, i + 6, j + 1, k + 3, Blocks.SNOW, 0);
		this.setBlock(world, i + 6, j + 1, k + 4, Blocks.SNOW, 0);
		this.setBlock(world, i + 6, j + 1, k + 5, Blocks.STAINED_HARDENED_CLAY, 0);
		this.setBlock(world, i + 6, j + 1, k + 6, Blocks.STAINED_HARDENED_CLAY, 0);
		this.setBlock(world, i + 6, j + 1, k + 7, Blocks.STAINED_HARDENED_CLAY, 0);
		this.setBlock(world, i + 6, j + 1, k + 8, Blocks.STAINED_HARDENED_CLAY, 0);
		this.setBlock(world, i + 6, j + 1, k + 9, Blocks.STAINED_HARDENED_CLAY, 0);
		this.setBlock(world, i + 6, j + 1, k + 10, Blocks.STAINED_HARDENED_CLAY, 0);
		this.setBlock(world, i + 6, j + 1, k + 11, Blocks.SNOW, 0);
		this.setBlock(world, i + 6, j + 1, k + 12, Blocks.SNOW, 0);
		this.setBlock(world, i + 6, j + 1, k + 13, Blocks.SNOW, 0);
		this.setBlock(world, i + 6, j + 1, k + 14, Blocks.SNOW, 0);
		this.setBlock(world, i + 6, j + 2, k + 2, Blocks.SNOW, 0);
		this.setBlock(world, i + 6, j + 2, k + 3, Blocks.SNOW, 0);
		this.setBlock(world, i + 6, j + 2, k + 4, Blocks.SNOW, 0);
		this.setBlock(world, i + 6, j + 2, k + 5, Blocks.STAINED_HARDENED_CLAY, 0);
		this.setBlock(world, i + 6, j + 2, k + 6, Blocks.STAINED_HARDENED_CLAY, 0);
		this.setBlock(world, i + 6, j + 2, k + 9, Blocks.STAINED_HARDENED_CLAY, 0);
		this.setBlock(world, i + 6, j + 2, k + 10, Blocks.STAINED_HARDENED_CLAY, 0);
		this.setBlock(world, i + 6, j + 2, k + 11, Blocks.SNOW, 0);
		this.setBlock(world, i + 6, j + 2, k + 12, Blocks.SNOW, 0);
		this.setBlock(world, i + 6, j + 2, k + 13, Blocks.SNOW, 0);
		this.setBlock(world, i + 6, j + 3, k + 3, Blocks.HARDENED_CLAY, 0);
		this.setBlock(world, i + 6, j + 3, k + 4, Blocks.HARDENED_CLAY, 0);
		this.setBlock(world, i + 6, j + 3, k + 5, Blocks.STAINED_HARDENED_CLAY, 0);
		this.setBlock(world, i + 6, j + 3, k + 6, Blocks.STAINED_HARDENED_CLAY, 0);
		this.setBlock(world, i + 6, j + 3, k + 9, Blocks.STAINED_HARDENED_CLAY, 0);
		this.setBlock(world, i + 6, j + 3, k + 10, Blocks.STAINED_HARDENED_CLAY, 0);
		this.setBlock(world, i + 6, j + 3, k + 11, Blocks.HARDENED_CLAY, 0);
		this.setBlock(world, i + 6, j + 3, k + 12, Blocks.HARDENED_CLAY, 0);
		this.setBlock(world, i + 6, j + 4, k + 4, Blocks.STAINED_HARDENED_CLAY, 8);
		this.setBlock(world, i + 6, j + 4, k + 5, Blocks.STAINED_HARDENED_CLAY, 0);
		this.setBlock(world, i + 6, j + 4, k + 6, Blocks.STAINED_HARDENED_CLAY, 0);
		this.setBlock(world, i + 6, j + 4, k + 9, Blocks.STAINED_HARDENED_CLAY, 0);
		this.setBlock(world, i + 6, j + 4, k + 10, Blocks.STAINED_HARDENED_CLAY, 0);
		this.setBlock(world, i + 6, j + 4, k + 11, Blocks.STAINED_HARDENED_CLAY, 8);
		this.setBlock(world, i + 6, j + 5, k + 5, Blocks.STAINED_HARDENED_CLAY, 8);
		this.setBlock(world, i + 6, j + 5, k + 6, Blocks.STAINED_HARDENED_CLAY, 0);
		this.setBlock(world, i + 6, j + 5, k + 7, Blocks.STAINED_HARDENED_CLAY, 0);
		this.setBlock(world, i + 6, j + 5, k + 8, Blocks.STAINED_HARDENED_CLAY, 0);
		this.setBlock(world, i + 6, j + 5, k + 9, Blocks.STAINED_HARDENED_CLAY, 0);
		this.setBlock(world, i + 6, j + 5, k + 10, Blocks.STAINED_HARDENED_CLAY, 8);
		this.setBlock(world, i + 6, j + 6, k + 5, Blocks.STAINED_HARDENED_CLAY, 8);
		this.setBlock(world, i + 6, j + 6, k + 6, Blocks.STAINED_HARDENED_CLAY, 0);
		this.setBlock(world, i + 6, j + 6, k + 7, Blocks.STAINED_HARDENED_CLAY, 0);
		this.setBlock(world, i + 6, j + 6, k + 8, Blocks.STAINED_HARDENED_CLAY, 0);
		this.setBlock(world, i + 6, j + 6, k + 9, Blocks.STAINED_HARDENED_CLAY, 0);
		this.setBlock(world, i + 6, j + 6, k + 10, Blocks.STAINED_HARDENED_CLAY, 8);
		this.setBlock(world, i + 6, j + 7, k + 6, Blocks.STAINED_HARDENED_CLAY, 15);
		this.setBlock(world, i + 6, j + 7, k + 7, Blocks.STAINED_HARDENED_CLAY, 0);
		this.setBlock(world, i + 6, j + 7, k + 8, Blocks.STAINED_HARDENED_CLAY, 0);
		this.setBlock(world, i + 6, j + 7, k + 9, Blocks.STAINED_HARDENED_CLAY, 15);
		this.setBlock(world, i + 6, j + 8, k + 7, Blocks.STAINED_HARDENED_CLAY, 8);
		this.setBlock(world, i + 6, j + 8, k + 8, Blocks.STAINED_HARDENED_CLAY, 8);
		this.setBlock(world, i + 7, j + 0, k + 0, Blocks.SNOW, 0);
		this.setBlock(world, i + 7, j + 0, k + 1, Blocks.SNOW, 0);
		this.setBlock(world, i + 7, j + 0, k + 2, Blocks.SNOW, 0);
		this.setBlock(world, i + 7, j + 0, k + 3, Blocks.SNOW, 0);
		this.setBlock(world, i + 7, j + 0, k + 4, Blocks.SNOW, 0);
		this.setBlock(world, i + 7, j + 0, k + 5, Blocks.SNOW, 0);
		this.setBlock(world, i + 7, j + 0, k + 6, Blocks.SNOW, 0);
		this.setBlock(world, i + 7, j + 0, k + 7, Blocks.SNOW, 0);
		this.setBlock(world, i + 7, j + 0, k + 8, Blocks.SNOW, 0);
		this.setBlock(world, i + 7, j + 0, k + 9, Blocks.SNOW, 0);
		this.setBlock(world, i + 7, j + 0, k + 10, Blocks.SNOW, 0);
		this.setBlock(world, i + 7, j + 0, k + 11, Blocks.SNOW, 0);
		this.setBlock(world, i + 7, j + 0, k + 12, Blocks.SNOW, 0);
		this.setBlock(world, i + 7, j + 0, k + 13, Blocks.SNOW, 0);
		this.setBlock(world, i + 7, j + 0, k + 14, Blocks.SNOW, 0);
		this.setBlock(world, i + 7, j + 0, k + 15, Blocks.SNOW, 0);
		this.setBlock(world, i + 7, j + 1, k + 1, Blocks.SNOW, 0);
		this.setBlock(world, i + 7, j + 1, k + 2, Blocks.SNOW, 0);
		this.setBlock(world, i + 7, j + 1, k + 3, Blocks.SNOW, 0);
		this.setBlock(world, i + 7, j + 1, k + 4, Blocks.STAINED_HARDENED_CLAY, 0);
		this.setBlock(world, i + 7, j + 1, k + 5, Blocks.STAINED_HARDENED_CLAY, 0);
		this.setBlock(world, i + 7, j + 1, k + 6, Blocks.STAINED_HARDENED_CLAY, 0);
		this.setBlock(world, i + 7, j + 1, k + 7, Blocks.STAINED_HARDENED_CLAY, 0);
		this.setBlock(world, i + 7, j + 1, k + 8, Blocks.STAINED_HARDENED_CLAY, 0);
		this.setBlock(world, i + 7, j + 1, k + 9, Blocks.STAINED_HARDENED_CLAY, 0);
		this.setBlock(world, i + 7, j + 1, k + 10, Blocks.STAINED_HARDENED_CLAY, 0);
		this.setBlock(world, i + 7, j + 1, k + 11, Blocks.STAINED_HARDENED_CLAY, 0);
		this.setBlock(world, i + 7, j + 1, k + 12, Blocks.SNOW, 0);
		this.setBlock(world, i + 7, j + 1, k + 13, Blocks.SNOW, 0);
		this.setBlock(world, i + 7, j + 1, k + 14, Blocks.SNOW, 0);
		this.setBlock(world, i + 7, j + 2, k + 2, Blocks.SNOW, 0);
		this.setBlock(world, i + 7, j + 2, k + 3, Blocks.SNOW, 0);
		this.setBlock(world, i + 7, j + 2, k + 4, Blocks.STAINED_HARDENED_CLAY, 0);
		this.setBlock(world, i + 7, j + 2, k + 5, Blocks.STAINED_HARDENED_CLAY, 0);
		this.setBlock(world, i + 7, j + 2, k + 10, Blocks.STAINED_HARDENED_CLAY, 0);
		this.setBlock(world, i + 7, j + 2, k + 11, Blocks.STAINED_HARDENED_CLAY, 0);
		this.setBlock(world, i + 7, j + 2, k + 12, Blocks.SNOW, 0);
		this.setBlock(world, i + 7, j + 2, k + 13, Blocks.SNOW, 0);
		this.setBlock(world, i + 7, j + 3, k + 3, Blocks.HARDENED_CLAY, 0);
		this.setBlock(world, i + 7, j + 3, k + 4, Blocks.STAINED_HARDENED_CLAY, 0);
		this.setBlock(world, i + 7, j + 3, k + 5, Blocks.STAINED_HARDENED_CLAY, 0);
		this.setBlock(world, i + 7, j + 3, k + 10, Blocks.STAINED_HARDENED_CLAY, 0);
		this.setBlock(world, i + 7, j + 3, k + 11, Blocks.STAINED_HARDENED_CLAY, 0);
		this.setBlock(world, i + 7, j + 3, k + 12, Blocks.HARDENED_CLAY, 0);
		this.setBlock(world, i + 7, j + 4, k + 3, Blocks.STAINED_HARDENED_CLAY, 8);
		this.setBlock(world, i + 7, j + 4, k + 4, Blocks.STAINED_HARDENED_CLAY, 0);
		this.setBlock(world, i + 7, j + 4, k + 5, Blocks.STAINED_HARDENED_CLAY, 0);
		this.setBlock(world, i + 7, j + 4, k + 10, Blocks.STAINED_HARDENED_CLAY, 0);
		this.setBlock(world, i + 7, j + 4, k + 11, Blocks.STAINED_HARDENED_CLAY, 0);
		this.setBlock(world, i + 7, j + 4, k + 12, Blocks.STAINED_HARDENED_CLAY, 8);
		this.setBlock(world, i + 7, j + 5, k + 4, Blocks.STAINED_HARDENED_CLAY, 8);
		this.setBlock(world, i + 7, j + 5, k + 5, Blocks.STAINED_HARDENED_CLAY, 0);
		this.setBlock(world, i + 7, j + 5, k + 6, Blocks.STAINED_HARDENED_CLAY, 0);
		this.setBlock(world, i + 7, j + 5, k + 9, Blocks.STAINED_HARDENED_CLAY, 0);
		this.setBlock(world, i + 7, j + 5, k + 10, Blocks.STAINED_HARDENED_CLAY, 0);
		this.setBlock(world, i + 7, j + 5, k + 11, Blocks.STAINED_HARDENED_CLAY, 8);
		this.setBlock(world, i + 7, j + 6, k + 5, Blocks.STAINED_HARDENED_CLAY, 8);
		this.setBlock(world, i + 7, j + 6, k + 6, Blocks.STAINED_HARDENED_CLAY, 0);
		this.setBlock(world, i + 7, j + 6, k + 7, Blocks.STAINED_HARDENED_CLAY, 0);
		this.setBlock(world, i + 7, j + 6, k + 8, Blocks.STAINED_HARDENED_CLAY, 0);
		this.setBlock(world, i + 7, j + 6, k + 9, Blocks.STAINED_HARDENED_CLAY, 0);
		this.setBlock(world, i + 7, j + 6, k + 10, Blocks.STAINED_HARDENED_CLAY, 8);
		this.setBlock(world, i + 7, j + 7, k + 5, Blocks.STAINED_HARDENED_CLAY, 8);
		this.setBlock(world, i + 7, j + 7, k + 6, Blocks.STAINED_HARDENED_CLAY, 0);
		this.setBlock(world, i + 7, j + 7, k + 7, Blocks.STAINED_HARDENED_CLAY, 0);
		this.setBlock(world, i + 7, j + 7, k + 9, Blocks.STAINED_HARDENED_CLAY, 0);
		this.setBlock(world, i + 7, j + 7, k + 10, Blocks.STAINED_HARDENED_CLAY, 8);
		this.setBlock(world, i + 7, j + 8, k + 6, Blocks.STAINED_HARDENED_CLAY, 8);
		this.setBlock(world, i + 7, j + 8, k + 7, Blocks.STAINED_HARDENED_CLAY, 0);
		this.setBlock(world, i + 7, j + 8, k + 8, Blocks.STAINED_HARDENED_CLAY, 0);
		this.setBlock(world, i + 7, j + 8, k + 9, Blocks.STAINED_HARDENED_CLAY, 8);
		this.setBlock(world, i + 7, j + 9, k + 7, Blocks.STAINED_HARDENED_CLAY, 8);
		this.setBlock(world, i + 7, j + 9, k + 8, Blocks.STAINED_HARDENED_CLAY, 8);
		this.setBlock(world, i + 8, j + 0, k + 0, Blocks.SNOW, 0);
		this.setBlock(world, i + 8, j + 0, k + 1, Blocks.SNOW, 0);
		this.setBlock(world, i + 8, j + 0, k + 2, Blocks.SNOW, 0);
		this.setBlock(world, i + 8, j + 0, k + 3, Blocks.SNOW, 0);
		this.setBlock(world, i + 8, j + 0, k + 4, Blocks.SNOW, 0);
		this.setBlock(world, i + 8, j + 0, k + 5, Blocks.SNOW, 0);
		this.setBlock(world, i + 8, j + 0, k + 6, Blocks.SNOW, 0);
		this.setBlock(world, i + 8, j + 0, k + 7, Blocks.SNOW, 0);
		this.setBlock(world, i + 8, j + 0, k + 8, Blocks.SNOW, 0);
		this.setBlock(world, i + 8, j + 0, k + 9, Blocks.SNOW, 0);
		this.setBlock(world, i + 8, j + 0, k + 10, Blocks.SNOW, 0);
		this.setBlock(world, i + 8, j + 0, k + 11, Blocks.SNOW, 0);
		this.setBlock(world, i + 8, j + 0, k + 12, Blocks.SNOW, 0);
		this.setBlock(world, i + 8, j + 0, k + 13, Blocks.SNOW, 0);
		this.setBlock(world, i + 8, j + 0, k + 14, Blocks.SNOW, 0);
		this.setBlock(world, i + 8, j + 0, k + 15, Blocks.SNOW, 0);
		this.setBlock(world, i + 8, j + 1, k + 1, Blocks.SNOW, 0);
		this.setBlock(world, i + 8, j + 1, k + 2, Blocks.SNOW, 0);
		this.setBlock(world, i + 8, j + 1, k + 3, Blocks.SNOW, 0);
		this.setBlock(world, i + 8, j + 1, k + 4, Blocks.STAINED_HARDENED_CLAY, 0);
		this.setBlock(world, i + 8, j + 1, k + 5, Blocks.STAINED_HARDENED_CLAY, 0);
		this.setBlock(world, i + 8, j + 1, k + 6, Blocks.STAINED_HARDENED_CLAY, 0);
		this.setBlock(world, i + 8, j + 1, k + 7, Blocks.STAINED_HARDENED_CLAY, 0);
		this.setBlock(world, i + 8, j + 1, k + 8, Blocks.STAINED_HARDENED_CLAY, 0);
		this.setBlock(world, i + 8, j + 1, k + 9, Blocks.STAINED_HARDENED_CLAY, 0);
		this.setBlock(world, i + 8, j + 1, k + 10, Blocks.STAINED_HARDENED_CLAY, 0);
		this.setBlock(world, i + 8, j + 1, k + 11, Blocks.STAINED_HARDENED_CLAY, 0);
		this.setBlock(world, i + 8, j + 1, k + 12, Blocks.SNOW, 0);
		this.setBlock(world, i + 8, j + 1, k + 13, Blocks.SNOW, 0);
		this.setBlock(world, i + 8, j + 1, k + 14, Blocks.SNOW, 0);
		this.setBlock(world, i + 8, j + 2, k + 2, Blocks.SNOW, 0);
		this.setBlock(world, i + 8, j + 2, k + 3, Blocks.SNOW, 0);
		this.setBlock(world, i + 8, j + 2, k + 4, Blocks.STAINED_HARDENED_CLAY, 0);
		this.setBlock(world, i + 8, j + 2, k + 11, Blocks.STAINED_HARDENED_CLAY, 0);
		this.setBlock(world, i + 8, j + 2, k + 12, Blocks.SNOW, 0);
		this.setBlock(world, i + 8, j + 2, k + 13, Blocks.SNOW, 0);
		this.setBlock(world, i + 8, j + 3, k + 3, Blocks.HARDENED_CLAY, 0);
		this.setBlock(world, i + 8, j + 3, k + 4, Blocks.STAINED_HARDENED_CLAY, 0);
		this.setBlock(world, i + 8, j + 3, k + 11, Blocks.STAINED_HARDENED_CLAY, 0);
		this.setBlock(world, i + 8, j + 3, k + 12, Blocks.HARDENED_CLAY, 0);
		this.setBlock(world, i + 8, j + 4, k + 3, Blocks.STAINED_HARDENED_CLAY, 8);
		this.setBlock(world, i + 8, j + 4, k + 4, Blocks.STAINED_HARDENED_CLAY, 0);
		this.setBlock(world, i + 8, j + 4, k + 11, Blocks.STAINED_HARDENED_CLAY, 0);
		this.setBlock(world, i + 8, j + 4, k + 12, Blocks.STAINED_HARDENED_CLAY, 8);
		this.setBlock(world, i + 8, j + 5, k + 4, Blocks.STAINED_HARDENED_CLAY, 8);
		this.setBlock(world, i + 8, j + 5, k + 5, Blocks.STAINED_HARDENED_CLAY, 0);
		this.setBlock(world, i + 8, j + 5, k + 10, Blocks.STAINED_HARDENED_CLAY, 0);
		this.setBlock(world, i + 8, j + 5, k + 11, Blocks.STAINED_HARDENED_CLAY, 8);
		this.setBlock(world, i + 8, j + 6, k + 4, Blocks.STAINED_HARDENED_CLAY, 8);
		this.setBlock(world, i + 8, j + 6, k + 5, Blocks.STAINED_HARDENED_CLAY, 0);
		this.setBlock(world, i + 8, j + 6, k + 6, Blocks.STAINED_HARDENED_CLAY, 0);
		this.setBlock(world, i + 8, j + 6, k + 9, Blocks.STAINED_HARDENED_CLAY, 0);
		this.setBlock(world, i + 8, j + 6, k + 10, Blocks.STAINED_HARDENED_CLAY, 0);
		this.setBlock(world, i + 8, j + 6, k + 11, Blocks.STAINED_HARDENED_CLAY, 8);
		this.setBlock(world, i + 8, j + 7, k + 5, Blocks.STAINED_HARDENED_CLAY, 8);
		this.setBlock(world, i + 8, j + 7, k + 6, Blocks.STAINED_HARDENED_CLAY, 0);
		this.setBlock(world, i + 8, j + 7, k + 7, Blocks.STAINED_HARDENED_CLAY, 0);
		this.setBlock(world, i + 8, j + 7, k + 8, Blocks.STAINED_HARDENED_CLAY, 0);
		this.setBlock(world, i + 8, j + 7, k + 9, Blocks.STAINED_HARDENED_CLAY, 0);
		this.setBlock(world, i + 8, j + 7, k + 10, Blocks.STAINED_HARDENED_CLAY, 8);
		this.setBlock(world, i + 8, j + 8, k + 5, Blocks.STAINED_HARDENED_CLAY, 8);
		this.setBlock(world, i + 8, j + 8, k + 6, Blocks.STAINED_HARDENED_CLAY, 0);
		this.setBlock(world, i + 8, j + 8, k + 7, Blocks.NETHERRACK, 0);
		this.setBlock(world, i + 8, j + 8, k + 8, Blocks.NETHERRACK, 0);
		this.setBlock(world, i + 8, j + 8, k + 9, Blocks.STAINED_HARDENED_CLAY, 0);
		this.setBlock(world, i + 8, j + 8, k + 10, Blocks.STAINED_HARDENED_CLAY, 8);
		this.setBlock(world, i + 8, j + 9, k + 6, Blocks.STAINED_HARDENED_CLAY, 8);
		this.setBlock(world, i + 8, j + 9, k + 7, Blocks.FIRE, 15);
		this.setBlock(world, i + 8, j + 9, k + 8, Blocks.FIRE, 15);
		this.setBlock(world, i + 8, j + 9, k + 9, Blocks.STAINED_HARDENED_CLAY, 8);
		this.setBlock(world, i + 9, j + 0, k + 0, Blocks.SNOW, 0);
		this.setBlock(world, i + 9, j + 0, k + 1, Blocks.SNOW, 0);
		this.setBlock(world, i + 9, j + 0, k + 2, Blocks.SNOW, 0);
		this.setBlock(world, i + 9, j + 0, k + 3, Blocks.SNOW, 0);
		this.setBlock(world, i + 9, j + 0, k + 4, Blocks.SNOW, 0);
		this.setBlock(world, i + 9, j + 0, k + 5, Blocks.SNOW, 0);
		this.setBlock(world, i + 9, j + 0, k + 6, Blocks.SNOW, 0);
		this.setBlock(world, i + 9, j + 0, k + 7, Blocks.SNOW, 0);
		this.setBlock(world, i + 9, j + 0, k + 8, Blocks.SNOW, 0);
		this.setBlock(world, i + 9, j + 0, k + 9, Blocks.SNOW, 0);
		this.setBlock(world, i + 9, j + 0, k + 10, Blocks.SNOW, 0);
		this.setBlock(world, i + 9, j + 0, k + 11, Blocks.SNOW, 0);
		this.setBlock(world, i + 9, j + 0, k + 12, Blocks.SNOW, 0);
		this.setBlock(world, i + 9, j + 0, k + 13, Blocks.SNOW, 0);
		this.setBlock(world, i + 9, j + 0, k + 14, Blocks.SNOW, 0);
		this.setBlock(world, i + 9, j + 0, k + 15, Blocks.SNOW, 0);
		this.setBlock(world, i + 9, j + 1, k + 1, Blocks.SNOW, 0);
		this.setBlock(world, i + 9, j + 1, k + 2, Blocks.SNOW, 0);
		this.setBlock(world, i + 9, j + 1, k + 3, Blocks.SNOW, 0);
		this.setBlock(world, i + 9, j + 1, k + 4, Blocks.STAINED_HARDENED_CLAY, 0);
		this.setBlock(world, i + 9, j + 1, k + 5, Blocks.STAINED_HARDENED_CLAY, 0);
		this.setBlock(world, i + 9, j + 1, k + 6, Blocks.STAINED_HARDENED_CLAY, 0);
		this.setBlock(world, i + 9, j + 1, k + 7, Blocks.STAINED_HARDENED_CLAY, 0);
		this.setBlock(world, i + 9, j + 1, k + 8, Blocks.STAINED_HARDENED_CLAY, 0);
		this.setBlock(world, i + 9, j + 1, k + 9, Blocks.STAINED_HARDENED_CLAY, 0);
		this.setBlock(world, i + 9, j + 1, k + 10, Blocks.STAINED_HARDENED_CLAY, 0);
		this.setBlock(world, i + 9, j + 1, k + 11, Blocks.STAINED_HARDENED_CLAY, 0);
		this.setBlock(world, i + 9, j + 1, k + 12, Blocks.SNOW, 0);
		this.setBlock(world, i + 9, j + 1, k + 13, Blocks.SNOW, 0);
		this.setBlock(world, i + 9, j + 1, k + 14, Blocks.SNOW, 0);
		this.setBlock(world, i + 9, j + 2, k + 2, Blocks.SNOW, 0);
		this.setBlock(world, i + 9, j + 2, k + 3, Blocks.SNOW, 0);
		this.setBlock(world, i + 9, j + 2, k + 4, Blocks.STAINED_HARDENED_CLAY, 0);
		this.setBlock(world, i + 9, j + 2, k + 11, Blocks.STAINED_HARDENED_CLAY, 0);
		this.setBlock(world, i + 9, j + 2, k + 12, Blocks.SNOW, 0);
		this.setBlock(world, i + 9, j + 2, k + 13, Blocks.SNOW, 0);
		this.setBlock(world, i + 9, j + 3, k + 3, Blocks.HARDENED_CLAY, 0);
		this.setBlock(world, i + 9, j + 3, k + 4, Blocks.STAINED_HARDENED_CLAY, 0);
		this.setBlock(world, i + 9, j + 3, k + 11, Blocks.STAINED_HARDENED_CLAY, 0);
		this.setBlock(world, i + 9, j + 3, k + 12, Blocks.HARDENED_CLAY, 0);
		this.setBlock(world, i + 9, j + 4, k + 3, Blocks.STAINED_HARDENED_CLAY, 8);
		this.setBlock(world, i + 9, j + 4, k + 4, Blocks.STAINED_HARDENED_CLAY, 0);
		this.setBlock(world, i + 9, j + 4, k + 11, Blocks.STAINED_HARDENED_CLAY, 0);
		this.setBlock(world, i + 9, j + 4, k + 12, Blocks.STAINED_HARDENED_CLAY, 8);
		this.setBlock(world, i + 9, j + 5, k + 4, Blocks.STAINED_HARDENED_CLAY, 8);
		this.setBlock(world, i + 9, j + 5, k + 5, Blocks.STAINED_HARDENED_CLAY, 0);
		this.setBlock(world, i + 9, j + 5, k + 10, Blocks.STAINED_HARDENED_CLAY, 0);
		this.setBlock(world, i + 9, j + 5, k + 11, Blocks.STAINED_HARDENED_CLAY, 8);
		this.setBlock(world, i + 9, j + 6, k + 4, Blocks.STAINED_HARDENED_CLAY, 8);
		this.setBlock(world, i + 9, j + 6, k + 5, Blocks.STAINED_HARDENED_CLAY, 0);
		this.setBlock(world, i + 9, j + 6, k + 6, Blocks.STAINED_HARDENED_CLAY, 0);
		this.setBlock(world, i + 9, j + 6, k + 9, Blocks.STAINED_HARDENED_CLAY, 0);
		this.setBlock(world, i + 9, j + 6, k + 10, Blocks.STAINED_HARDENED_CLAY, 0);
		this.setBlock(world, i + 9, j + 6, k + 11, Blocks.STAINED_HARDENED_CLAY, 8);
		this.setBlock(world, i + 9, j + 7, k + 5, Blocks.STAINED_HARDENED_CLAY, 8);
		this.setBlock(world, i + 9, j + 7, k + 6, Blocks.STAINED_HARDENED_CLAY, 0);
		this.setBlock(world, i + 9, j + 7, k + 7, Blocks.STAINED_HARDENED_CLAY, 0);
		this.setBlock(world, i + 9, j + 7, k + 8, Blocks.STAINED_HARDENED_CLAY, 0);
		this.setBlock(world, i + 9, j + 7, k + 9, Blocks.STAINED_HARDENED_CLAY, 0);
		this.setBlock(world, i + 9, j + 7, k + 10, Blocks.STAINED_HARDENED_CLAY, 8);
		this.setBlock(world, i + 9, j + 8, k + 5, Blocks.STAINED_HARDENED_CLAY, 8);
		this.setBlock(world, i + 9, j + 8, k + 6, Blocks.STAINED_HARDENED_CLAY, 0);
		this.setBlock(world, i + 9, j + 8, k + 7, Blocks.NETHERRACK, 0);
		this.setBlock(world, i + 9, j + 8, k + 8, Blocks.NETHERRACK, 0);
		this.setBlock(world, i + 9, j + 8, k + 9, Blocks.STAINED_HARDENED_CLAY, 0);
		this.setBlock(world, i + 9, j + 8, k + 10, Blocks.STAINED_HARDENED_CLAY, 8);
		this.setBlock(world, i + 9, j + 9, k + 6, Blocks.STAINED_HARDENED_CLAY, 8);
		this.setBlock(world, i + 9, j + 9, k + 7, Blocks.FIRE, 15);
		this.setBlock(world, i + 9, j + 9, k + 8, Blocks.FIRE, 15);
		this.setBlock(world, i + 9, j + 9, k + 9, Blocks.STAINED_HARDENED_CLAY, 8);
		this.setBlock(world, i + 10, j + 0, k + 0, Blocks.SNOW, 0);
		this.setBlock(world, i + 10, j + 0, k + 1, Blocks.SNOW, 0);
		this.setBlock(world, i + 10, j + 0, k + 2, Blocks.SNOW, 0);
		this.setBlock(world, i + 10, j + 0, k + 3, Blocks.SNOW, 0);
		this.setBlock(world, i + 10, j + 0, k + 4, Blocks.SNOW, 0);
		this.setBlock(world, i + 10, j + 0, k + 5, Blocks.SNOW, 0);
		this.setBlock(world, i + 10, j + 0, k + 6, Blocks.SNOW, 0);
		this.setBlock(world, i + 10, j + 0, k + 7, Blocks.SNOW, 0);
		this.setBlock(world, i + 10, j + 0, k + 8, Blocks.SNOW, 0);
		this.setBlock(world, i + 10, j + 0, k + 9, Blocks.SNOW, 0);
		this.setBlock(world, i + 10, j + 0, k + 10, Blocks.SNOW, 0);
		this.setBlock(world, i + 10, j + 0, k + 11, Blocks.SNOW, 0);
		this.setBlock(world, i + 10, j + 0, k + 12, Blocks.SNOW, 0);
		this.setBlock(world, i + 10, j + 0, k + 13, Blocks.SNOW, 0);
		this.setBlock(world, i + 10, j + 0, k + 14, Blocks.SNOW, 0);
		this.setBlock(world, i + 10, j + 0, k + 15, Blocks.SNOW, 0);
		this.setBlock(world, i + 10, j + 1, k + 1, Blocks.SNOW, 0);
		this.setBlock(world, i + 10, j + 1, k + 2, Blocks.SNOW, 0);
		this.setBlock(world, i + 10, j + 1, k + 3, Blocks.SNOW, 0);
		this.setBlock(world, i + 10, j + 1, k + 4, Blocks.STAINED_HARDENED_CLAY, 0);
		this.setBlock(world, i + 10, j + 1, k + 5, Blocks.STAINED_HARDENED_CLAY, 0);
		this.setBlock(world, i + 10, j + 1, k + 6, Blocks.STAINED_HARDENED_CLAY, 0);
		this.setBlock(world, i + 10, j + 1, k + 7, Blocks.STAINED_HARDENED_CLAY, 0);
		this.setBlock(world, i + 10, j + 1, k + 8, Blocks.STAINED_HARDENED_CLAY, 0);
		this.setBlock(world, i + 10, j + 1, k + 9, Blocks.STAINED_HARDENED_CLAY, 0);
		this.setBlock(world, i + 10, j + 1, k + 10, Blocks.STAINED_HARDENED_CLAY, 0);
		this.setBlock(world, i + 10, j + 1, k + 11, Blocks.STAINED_HARDENED_CLAY, 0);
		this.setBlock(world, i + 10, j + 1, k + 12, Blocks.SNOW, 0);
		this.setBlock(world, i + 10, j + 1, k + 13, Blocks.SNOW, 0);
		this.setBlock(world, i + 10, j + 1, k + 14, Blocks.SNOW, 0);
		this.setBlock(world, i + 10, j + 2, k + 2, Blocks.SNOW, 0);
		this.setBlock(world, i + 10, j + 2, k + 3, Blocks.SNOW, 0);
		this.setBlock(world, i + 10, j + 2, k + 4, Blocks.STAINED_HARDENED_CLAY, 0);
		this.setBlock(world, i + 10, j + 2, k + 11, Blocks.STAINED_HARDENED_CLAY, 0);
		this.setBlock(world, i + 10, j + 2, k + 12, Blocks.SNOW, 0);
		this.setBlock(world, i + 10, j + 2, k + 13, Blocks.SNOW, 0);
		this.setBlock(world, i + 10, j + 3, k + 3, Blocks.HARDENED_CLAY, 0);
		this.setBlock(world, i + 10, j + 3, k + 4, Blocks.OBSIDIAN, 0);
		this.setBlock(world, i + 10, j + 3, k + 11, Blocks.OBSIDIAN, 0);
		this.setBlock(world, i + 10, j + 3, k + 12, Blocks.HARDENED_CLAY, 0);
		this.setBlock(world, i + 10, j + 4, k + 3, Blocks.STAINED_HARDENED_CLAY, 8);
		this.setBlock(world, i + 10, j + 4, k + 4, Blocks.STAINED_HARDENED_CLAY, 0);
		this.setBlock(world, i + 10, j + 4, k + 11, Blocks.STAINED_HARDENED_CLAY, 0);
		this.setBlock(world, i + 10, j + 4, k + 12, Blocks.STAINED_HARDENED_CLAY, 8);
		this.setBlock(world, i + 10, j + 5, k + 4, Blocks.STAINED_HARDENED_CLAY, 8);
		this.setBlock(world, i + 10, j + 5, k + 5, Blocks.STAINED_HARDENED_CLAY, 0);
		this.setBlock(world, i + 10, j + 5, k + 10, Blocks.STAINED_HARDENED_CLAY, 0);
		this.setBlock(world, i + 10, j + 5, k + 11, Blocks.STAINED_HARDENED_CLAY, 8);
		this.setBlock(world, i + 10, j + 6, k + 4, Blocks.STAINED_HARDENED_CLAY, 8);
		this.setBlock(world, i + 10, j + 6, k + 5, Blocks.STAINED_HARDENED_CLAY, 0);
		this.setBlock(world, i + 10, j + 6, k + 6, Blocks.STAINED_HARDENED_CLAY, 0);
		this.setBlock(world, i + 10, j + 6, k + 9, Blocks.STAINED_HARDENED_CLAY, 0);
		this.setBlock(world, i + 10, j + 6, k + 10, Blocks.STAINED_HARDENED_CLAY, 0);
		this.setBlock(world, i + 10, j + 6, k + 11, Blocks.STAINED_HARDENED_CLAY, 8);
		this.setBlock(world, i + 10, j + 7, k + 5, Blocks.STAINED_HARDENED_CLAY, 8);
		this.setBlock(world, i + 10, j + 7, k + 6, Blocks.STAINED_HARDENED_CLAY, 0);
		this.setBlock(world, i + 10, j + 7, k + 7, Blocks.STAINED_HARDENED_CLAY, 0);
		this.setBlock(world, i + 10, j + 7, k + 8, Blocks.STAINED_HARDENED_CLAY, 0);
		this.setBlock(world, i + 10, j + 7, k + 9, Blocks.STAINED_HARDENED_CLAY, 0);
		this.setBlock(world, i + 10, j + 7, k + 10, Blocks.STAINED_HARDENED_CLAY, 8);
		this.setBlock(world, i + 10, j + 8, k + 5, Blocks.STAINED_HARDENED_CLAY, 8);
		this.setBlock(world, i + 10, j + 8, k + 6, Blocks.STAINED_HARDENED_CLAY, 0);
		this.setBlock(world, i + 10, j + 8, k + 7, Blocks.NETHERRACK, 0);
		this.setBlock(world, i + 10, j + 8, k + 8, Blocks.NETHERRACK, 0);
		this.setBlock(world, i + 10, j + 8, k + 9, Blocks.STAINED_HARDENED_CLAY, 0);
		this.setBlock(world, i + 10, j + 8, k + 10, Blocks.STAINED_HARDENED_CLAY, 8);
		this.setBlock(world, i + 10, j + 9, k + 6, Blocks.STAINED_HARDENED_CLAY, 8);
		this.setBlock(world, i + 10, j + 9, k + 7, Blocks.FIRE, 15);
		this.setBlock(world, i + 10, j + 9, k + 8, Blocks.FIRE, 15);
		this.setBlock(world, i + 10, j + 9, k + 9, Blocks.STAINED_HARDENED_CLAY, 8);
		this.setBlock(world, i + 11, j + 0, k + 0, Blocks.SNOW, 0);
		this.setBlock(world, i + 11, j + 0, k + 1, Blocks.SNOW, 0);
		this.setBlock(world, i + 11, j + 0, k + 2, Blocks.SNOW, 0);
		this.setBlock(world, i + 11, j + 0, k + 3, Blocks.SNOW, 0);
		this.setBlock(world, i + 11, j + 0, k + 4, Blocks.SNOW, 0);
		this.setBlock(world, i + 11, j + 0, k + 5, Blocks.SNOW, 0);
		this.setBlock(world, i + 11, j + 0, k + 6, Blocks.SNOW, 0);
		this.setBlock(world, i + 11, j + 0, k + 7, Blocks.SNOW, 0);
		this.setBlock(world, i + 11, j + 0, k + 8, Blocks.SNOW, 0);
		this.setBlock(world, i + 11, j + 0, k + 9, Blocks.SNOW, 0);
		this.setBlock(world, i + 11, j + 0, k + 10, Blocks.SNOW, 0);
		this.setBlock(world, i + 11, j + 0, k + 11, Blocks.SNOW, 0);
		this.setBlock(world, i + 11, j + 0, k + 12, Blocks.SNOW, 0);
		this.setBlock(world, i + 11, j + 0, k + 13, Blocks.SNOW, 0);
		this.setBlock(world, i + 11, j + 0, k + 14, Blocks.SNOW, 0);
		this.setBlock(world, i + 11, j + 0, k + 15, Blocks.SNOW, 0);
		this.setBlock(world, i + 11, j + 1, k + 1, Blocks.SNOW, 0);
		this.setBlock(world, i + 11, j + 1, k + 2, Blocks.SNOW, 0);
		this.setBlock(world, i + 11, j + 1, k + 3, Blocks.SNOW, 0);
		this.setBlock(world, i + 11, j + 1, k + 4, Blocks.STAINED_HARDENED_CLAY, 0);
		this.setBlock(world, i + 11, j + 1, k + 5, Blocks.STAINED_HARDENED_CLAY, 0);
		this.setBlock(world, i + 11, j + 1, k + 6, Blocks.STAINED_HARDENED_CLAY, 0);
		this.setBlock(world, i + 11, j + 1, k + 7, Blocks.STAINED_HARDENED_CLAY, 0);
		this.setBlock(world, i + 11, j + 1, k + 8, Blocks.STAINED_HARDENED_CLAY, 0);
		this.setBlock(world, i + 11, j + 1, k + 9, Blocks.STAINED_HARDENED_CLAY, 0);
		this.setBlock(world, i + 11, j + 1, k + 10, Blocks.STAINED_HARDENED_CLAY, 0);
		this.setBlock(world, i + 11, j + 1, k + 11, Blocks.STAINED_HARDENED_CLAY, 0);
		this.setBlock(world, i + 11, j + 1, k + 12, Blocks.SNOW, 0);
		this.setBlock(world, i + 11, j + 1, k + 13, Blocks.SNOW, 0);
		this.setBlock(world, i + 11, j + 1, k + 14, Blocks.SNOW, 0);
		this.setBlock(world, i + 11, j + 2, k + 2, Blocks.SNOW, 0);
		this.setBlock(world, i + 11, j + 2, k + 3, Blocks.SNOW, 0);
		this.setBlock(world, i + 11, j + 2, k + 4, Blocks.STAINED_HARDENED_CLAY, 0);
		this.setBlock(world, i + 11, j + 2, k + 11, Blocks.STAINED_HARDENED_CLAY, 0);
		this.setBlock(world, i + 11, j + 2, k + 12, Blocks.SNOW, 0);
		this.setBlock(world, i + 11, j + 2, k + 13, Blocks.SNOW, 0);
		this.setBlock(world, i + 11, j + 3, k + 3, Blocks.HARDENED_CLAY, 0);
		this.setBlock(world, i + 11, j + 3, k + 4, Blocks.STAINED_HARDENED_CLAY, 0);
		this.setBlock(world, i + 11, j + 3, k + 11, Blocks.STAINED_HARDENED_CLAY, 0);
		this.setBlock(world, i + 11, j + 3, k + 12, Blocks.HARDENED_CLAY, 0);
		this.setBlock(world, i + 11, j + 4, k + 3, Blocks.STAINED_HARDENED_CLAY, 8);
		this.setBlock(world, i + 11, j + 4, k + 4, Blocks.STAINED_HARDENED_CLAY, 0);
		this.setBlock(world, i + 11, j + 4, k + 11, Blocks.STAINED_HARDENED_CLAY, 0);
		this.setBlock(world, i + 11, j + 4, k + 12, Blocks.STAINED_HARDENED_CLAY, 8);
		this.setBlock(world, i + 11, j + 5, k + 4, Blocks.STAINED_HARDENED_CLAY, 8);
		this.setBlock(world, i + 11, j + 5, k + 5, Blocks.STAINED_HARDENED_CLAY, 0);
		this.setBlock(world, i + 11, j + 5, k + 10, Blocks.STAINED_HARDENED_CLAY, 0);
		this.setBlock(world, i + 11, j + 5, k + 11, Blocks.STAINED_HARDENED_CLAY, 8);
		this.setBlock(world, i + 11, j + 6, k + 4, Blocks.STAINED_HARDENED_CLAY, 8);
		this.setBlock(world, i + 11, j + 6, k + 5, Blocks.STAINED_HARDENED_CLAY, 0);
		this.setBlock(world, i + 11, j + 6, k + 6, Blocks.STAINED_HARDENED_CLAY, 0);
		this.setBlock(world, i + 11, j + 6, k + 9, Blocks.STAINED_HARDENED_CLAY, 0);
		this.setBlock(world, i + 11, j + 6, k + 10, Blocks.STAINED_HARDENED_CLAY, 0);
		this.setBlock(world, i + 11, j + 6, k + 11, Blocks.STAINED_HARDENED_CLAY, 8);
		this.setBlock(world, i + 11, j + 7, k + 5, Blocks.STAINED_HARDENED_CLAY, 8);
		this.setBlock(world, i + 11, j + 7, k + 6, Blocks.STAINED_HARDENED_CLAY, 0);
		this.setBlock(world, i + 11, j + 7, k + 7, Blocks.STAINED_HARDENED_CLAY, 0);
		this.setBlock(world, i + 11, j + 7, k + 8, Blocks.STAINED_HARDENED_CLAY, 0);
		this.setBlock(world, i + 11, j + 7, k + 9, Blocks.STAINED_HARDENED_CLAY, 0);
		this.setBlock(world, i + 11, j + 7, k + 10, Blocks.STAINED_HARDENED_CLAY, 8);
		this.setBlock(world, i + 11, j + 8, k + 5, Blocks.STAINED_HARDENED_CLAY, 8);
		this.setBlock(world, i + 11, j + 8, k + 6, Blocks.STAINED_HARDENED_CLAY, 0);
		this.setBlock(world, i + 11, j + 8, k + 7, Blocks.NETHERRACK, 0);
		this.setBlock(world, i + 11, j + 8, k + 8, Blocks.NETHERRACK, 0);
		this.setBlock(world, i + 11, j + 8, k + 9, Blocks.STAINED_HARDENED_CLAY, 0);
		this.setBlock(world, i + 11, j + 8, k + 10, Blocks.STAINED_HARDENED_CLAY, 8);
		this.setBlock(world, i + 11, j + 9, k + 6, Blocks.STAINED_HARDENED_CLAY, 8);
		this.setBlock(world, i + 11, j + 9, k + 7, Blocks.FIRE, 15);
		this.setBlock(world, i + 11, j + 9, k + 8, Blocks.FIRE, 15);
		this.setBlock(world, i + 11, j + 9, k + 9, Blocks.STAINED_HARDENED_CLAY, 8);
		this.setBlock(world, i + 12, j + 0, k + 0, Blocks.SNOW, 0);
		this.setBlock(world, i + 12, j + 0, k + 1, Blocks.SNOW, 0);
		this.setBlock(world, i + 12, j + 0, k + 2, Blocks.SNOW, 0);
		this.setBlock(world, i + 12, j + 0, k + 3, Blocks.SNOW, 0);
		this.setBlock(world, i + 12, j + 0, k + 4, Blocks.SNOW, 0);
		this.setBlock(world, i + 12, j + 0, k + 5, Blocks.SNOW, 0);
		this.setBlock(world, i + 12, j + 0, k + 6, Blocks.SNOW, 0);
		this.setBlock(world, i + 12, j + 0, k + 7, Blocks.SNOW, 0);
		this.setBlock(world, i + 12, j + 0, k + 8, Blocks.SNOW, 0);
		this.setBlock(world, i + 12, j + 0, k + 9, Blocks.SNOW, 0);
		this.setBlock(world, i + 12, j + 0, k + 10, Blocks.SNOW, 0);
		this.setBlock(world, i + 12, j + 0, k + 11, Blocks.SNOW, 0);
		this.setBlock(world, i + 12, j + 0, k + 12, Blocks.SNOW, 0);
		this.setBlock(world, i + 12, j + 0, k + 13, Blocks.SNOW, 0);
		this.setBlock(world, i + 12, j + 0, k + 14, Blocks.SNOW, 0);
		this.setBlock(world, i + 12, j + 0, k + 15, Blocks.SNOW, 0);
		this.setBlock(world, i + 12, j + 1, k + 1, Blocks.SNOW, 0);
		this.setBlock(world, i + 12, j + 1, k + 2, Blocks.SNOW, 0);
		this.setBlock(world, i + 12, j + 1, k + 3, Blocks.SNOW, 0);
		this.setBlock(world, i + 12, j + 1, k + 4, Blocks.STAINED_HARDENED_CLAY, 0);
		this.setBlock(world, i + 12, j + 1, k + 5, Blocks.STAINED_HARDENED_CLAY, 0);
		this.setBlock(world, i + 12, j + 1, k + 6, Blocks.STAINED_HARDENED_CLAY, 0);
		this.setBlock(world, i + 12, j + 1, k + 7, Blocks.STAINED_HARDENED_CLAY, 0);
		this.setBlock(world, i + 12, j + 1, k + 8, Blocks.STAINED_HARDENED_CLAY, 0);
		this.setBlock(world, i + 12, j + 1, k + 9, Blocks.STAINED_HARDENED_CLAY, 0);
		this.setBlock(world, i + 12, j + 1, k + 10, Blocks.STAINED_HARDENED_CLAY, 0);
		this.setBlock(world, i + 12, j + 1, k + 11, Blocks.STAINED_HARDENED_CLAY, 0);
		this.setBlock(world, i + 12, j + 1, k + 12, Blocks.SNOW, 0);
		this.setBlock(world, i + 12, j + 1, k + 13, Blocks.SNOW, 0);
		this.setBlock(world, i + 12, j + 1, k + 14, Blocks.SNOW, 0);
		this.setBlock(world, i + 12, j + 2, k + 2, Blocks.SNOW, 0);
		this.setBlock(world, i + 12, j + 2, k + 3, Blocks.SNOW, 0);
		this.setBlock(world, i + 12, j + 2, k + 4, Blocks.STAINED_HARDENED_CLAY, 0);
		this.setBlock(world, i + 12, j + 2, k + 8, Blocks.BRICK_BLOCK, 0);
		this.setBlock(world, i + 12, j + 2, k + 11, Blocks.STAINED_HARDENED_CLAY, 0);
		this.setBlock(world, i + 12, j + 2, k + 12, Blocks.SNOW, 0);
		this.setBlock(world, i + 12, j + 2, k + 13, Blocks.SNOW, 0);
		this.setBlock(world, i + 12, j + 3, k + 3, Blocks.HARDENED_CLAY, 0);
		this.setBlock(world, i + 12, j + 3, k + 4, Blocks.STAINED_HARDENED_CLAY, 0);
		this.setBlock(world, i + 12, j + 3, k + 11, Blocks.STAINED_HARDENED_CLAY, 0);
		this.setBlock(world, i + 12, j + 3, k + 12, Blocks.HARDENED_CLAY, 0);
		this.setBlock(world, i + 12, j + 4, k + 3, Blocks.STAINED_HARDENED_CLAY, 8);
		this.setBlock(world, i + 12, j + 4, k + 4, Blocks.STAINED_HARDENED_CLAY, 0);
		this.setBlock(world, i + 12, j + 4, k + 11, Blocks.STAINED_HARDENED_CLAY, 0);
		this.setBlock(world, i + 12, j + 4, k + 12, Blocks.STAINED_HARDENED_CLAY, 8);
		this.setBlock(world, i + 12, j + 5, k + 4, Blocks.STAINED_HARDENED_CLAY, 8);
		this.setBlock(world, i + 12, j + 5, k + 5, Blocks.STAINED_HARDENED_CLAY, 0);
		this.setBlock(world, i + 12, j + 5, k + 10, Blocks.STAINED_HARDENED_CLAY, 0);
		this.setBlock(world, i + 12, j + 5, k + 11, Blocks.STAINED_HARDENED_CLAY, 8);
		this.setBlock(world, i + 12, j + 6, k + 4, Blocks.STAINED_HARDENED_CLAY, 8);
		this.setBlock(world, i + 12, j + 6, k + 5, Blocks.STAINED_HARDENED_CLAY, 0);
		this.setBlock(world, i + 12, j + 6, k + 6, Blocks.STAINED_HARDENED_CLAY, 0);
		this.setBlock(world, i + 12, j + 6, k + 7, Blocks.STAINED_HARDENED_CLAY, 0);
		this.setBlock(world, i + 12, j + 6, k + 8, Blocks.STAINED_HARDENED_CLAY, 0);
		this.setBlock(world, i + 12, j + 6, k + 9, Blocks.STAINED_HARDENED_CLAY, 0);
		this.setBlock(world, i + 12, j + 6, k + 10, Blocks.STAINED_HARDENED_CLAY, 0);
		this.setBlock(world, i + 12, j + 6, k + 11, Blocks.STAINED_HARDENED_CLAY, 8);
		this.setBlock(world, i + 12, j + 7, k + 5, Blocks.STAINED_HARDENED_CLAY, 8);
		this.setBlock(world, i + 12, j + 7, k + 6, Blocks.STAINED_HARDENED_CLAY, 0);
		this.setBlock(world, i + 12, j + 7, k + 7, Blocks.STAINED_HARDENED_CLAY, 0);
		this.setBlock(world, i + 12, j + 7, k + 8, Blocks.STAINED_HARDENED_CLAY, 0);
		this.setBlock(world, i + 12, j + 7, k + 9, Blocks.STAINED_HARDENED_CLAY, 0);
		this.setBlock(world, i + 12, j + 7, k + 10, Blocks.STAINED_HARDENED_CLAY, 8);
		this.setBlock(world, i + 12, j + 8, k + 5, Blocks.STAINED_HARDENED_CLAY, 8);
		this.setBlock(world, i + 12, j + 8, k + 6, Blocks.STAINED_HARDENED_CLAY, 8);
		this.setBlock(world, i + 12, j + 8, k + 7, Blocks.STAINED_HARDENED_CLAY, 0);
		this.setBlock(world, i + 12, j + 8, k + 8, Blocks.STAINED_HARDENED_CLAY, 0);
		this.setBlock(world, i + 12, j + 8, k + 9, Blocks.STAINED_HARDENED_CLAY, 8);
		this.setBlock(world, i + 12, j + 8, k + 10, Blocks.STAINED_HARDENED_CLAY, 8);
		this.setBlock(world, i + 12, j + 9, k + 7, Blocks.STAINED_HARDENED_CLAY, 8);
		this.setBlock(world, i + 12, j + 9, k + 8, Blocks.STAINED_HARDENED_CLAY, 8);
		this.setBlock(world, i + 13, j + 0, k + 0, Blocks.SNOW, 0);
		this.setBlock(world, i + 13, j + 0, k + 1, Blocks.SNOW, 0);
		this.setBlock(world, i + 13, j + 0, k + 2, Blocks.SNOW, 0);
		this.setBlock(world, i + 13, j + 0, k + 3, Blocks.SNOW, 0);
		this.setBlock(world, i + 13, j + 0, k + 4, Blocks.SNOW, 0);
		this.setBlock(world, i + 13, j + 0, k + 5, Blocks.SNOW, 0);
		this.setBlock(world, i + 13, j + 0, k + 6, Blocks.SNOW, 0);
		this.setBlock(world, i + 13, j + 0, k + 7, Blocks.SNOW, 0);
		this.setBlock(world, i + 13, j + 0, k + 8, Blocks.SNOW, 0);
		this.setBlock(world, i + 13, j + 0, k + 9, Blocks.SNOW, 0);
		this.setBlock(world, i + 13, j + 0, k + 10, Blocks.SNOW, 0);
		this.setBlock(world, i + 13, j + 0, k + 11, Blocks.SNOW, 0);
		this.setBlock(world, i + 13, j + 0, k + 12, Blocks.SNOW, 0);
		this.setBlock(world, i + 13, j + 0, k + 13, Blocks.SNOW, 0);
		this.setBlock(world, i + 13, j + 0, k + 14, Blocks.SNOW, 0);
		this.setBlock(world, i + 13, j + 0, k + 15, Blocks.SNOW, 0);
		this.setBlock(world, i + 13, j + 1, k + 1, Blocks.SNOW, 0);
		this.setBlock(world, i + 13, j + 1, k + 2, Blocks.SNOW, 0);
		this.setBlock(world, i + 13, j + 1, k + 3, Blocks.SNOW, 0);
		this.setBlock(world, i + 13, j + 1, k + 4, Blocks.SNOW, 0);
		this.setBlock(world, i + 13, j + 1, k + 5, Blocks.STAINED_HARDENED_CLAY, 0);
		this.setBlock(world, i + 13, j + 1, k + 6, Blocks.STAINED_HARDENED_CLAY, 0);
		this.setBlock(world, i + 13, j + 1, k + 7, Blocks.STAINED_HARDENED_CLAY, 0);
		this.setBlock(world, i + 13, j + 1, k + 8, Blocks.STAINED_HARDENED_CLAY, 0);
		this.setBlock(world, i + 13, j + 1, k + 9, Blocks.STAINED_HARDENED_CLAY, 0);
		this.setBlock(world, i + 13, j + 1, k + 10, Blocks.STAINED_HARDENED_CLAY, 0);
		this.setBlock(world, i + 13, j + 1, k + 11, Blocks.SNOW, 0);
		this.setBlock(world, i + 13, j + 1, k + 12, Blocks.SNOW, 0);
		this.setBlock(world, i + 13, j + 1, k + 13, Blocks.SNOW, 0);
		this.setBlock(world, i + 13, j + 1, k + 14, Blocks.SNOW, 0);
		this.setBlock(world, i + 13, j + 2, k + 2, Blocks.SNOW, 0);
		this.setBlock(world, i + 13, j + 2, k + 3, Blocks.SNOW, 0);
		this.setBlock(world, i + 13, j + 2, k + 4, Blocks.STAINED_HARDENED_CLAY, 0);
		this.setBlock(world, i + 13, j + 2, k + 5, Blocks.STAINED_HARDENED_CLAY, 0);
		this.setBlock(world, i + 13, j + 2, k + 10, Blocks.STAINED_HARDENED_CLAY, 0);
		this.setBlock(world, i + 13, j + 2, k + 11, Blocks.SNOW, 0);
		this.setBlock(world, i + 13, j + 2, k + 12, Blocks.SNOW, 0);
		this.setBlock(world, i + 13, j + 2, k + 13, Blocks.SNOW, 0);
		this.setBlock(world, i + 13, j + 3, k + 3, Blocks.HARDENED_CLAY, 0);
		this.setBlock(world, i + 13, j + 3, k + 4, Blocks.STAINED_HARDENED_CLAY, 0);
		this.setBlock(world, i + 13, j + 3, k + 5, Blocks.STAINED_HARDENED_CLAY, 0);
		this.setBlock(world, i + 13, j + 3, k + 10, Blocks.STAINED_HARDENED_CLAY, 0);
		this.setBlock(world, i + 13, j + 3, k + 11, Blocks.STAINED_HARDENED_CLAY, 0);
		this.setBlock(world, i + 13, j + 3, k + 12, Blocks.HARDENED_CLAY, 0);
		this.setBlock(world, i + 13, j + 4, k + 3, Blocks.STAINED_HARDENED_CLAY, 8);
		this.setBlock(world, i + 13, j + 4, k + 4, Blocks.STAINED_HARDENED_CLAY, 0);
		this.setBlock(world, i + 13, j + 4, k + 5, Blocks.STAINED_HARDENED_CLAY, 0);
		this.setBlock(world, i + 13, j + 4, k + 10, Blocks.STAINED_HARDENED_CLAY, 0);
		this.setBlock(world, i + 13, j + 4, k + 11, Blocks.STAINED_HARDENED_CLAY, 0);
		this.setBlock(world, i + 13, j + 4, k + 12, Blocks.STAINED_HARDENED_CLAY, 8);
		this.setBlock(world, i + 13, j + 5, k + 4, Blocks.STAINED_HARDENED_CLAY, 8);
		this.setBlock(world, i + 13, j + 5, k + 5, Blocks.STAINED_HARDENED_CLAY, 0);
		this.setBlock(world, i + 13, j + 5, k + 6, Blocks.STAINED_HARDENED_CLAY, 0);
		this.setBlock(world, i + 13, j + 5, k + 7, Blocks.STAINED_HARDENED_CLAY, 0);
		this.setBlock(world, i + 13, j + 5, k + 8, Blocks.STAINED_HARDENED_CLAY, 0);
		this.setBlock(world, i + 13, j + 5, k + 9, Blocks.STAINED_HARDENED_CLAY, 0);
		this.setBlock(world, i + 13, j + 5, k + 10, Blocks.STAINED_HARDENED_CLAY, 0);
		this.setBlock(world, i + 13, j + 5, k + 11, Blocks.STAINED_HARDENED_CLAY, 8);
		this.setBlock(world, i + 13, j + 6, k + 5, Blocks.STAINED_HARDENED_CLAY, 8);
		this.setBlock(world, i + 13, j + 6, k + 6, Blocks.STAINED_HARDENED_CLAY, 0);
		this.setBlock(world, i + 13, j + 6, k + 7, Blocks.STAINED_HARDENED_CLAY, 0);
		this.setBlock(world, i + 13, j + 6, k + 8, Blocks.STAINED_HARDENED_CLAY, 0);
		this.setBlock(world, i + 13, j + 6, k + 9, Blocks.STAINED_HARDENED_CLAY, 0);
		this.setBlock(world, i + 13, j + 6, k + 10, Blocks.STAINED_HARDENED_CLAY, 8);
		this.setBlock(world, i + 13, j + 7, k + 5, Blocks.STAINED_HARDENED_CLAY, 8);
		this.setBlock(world, i + 13, j + 7, k + 6, Blocks.STAINED_HARDENED_CLAY, 8);
		this.setBlock(world, i + 13, j + 7, k + 7, Blocks.STAINED_HARDENED_CLAY, 8);
		this.setBlock(world, i + 13, j + 7, k + 8, Blocks.STAINED_HARDENED_CLAY, 8);
		this.setBlock(world, i + 13, j + 7, k + 9, Blocks.STAINED_HARDENED_CLAY, 8);
		this.setBlock(world, i + 13, j + 7, k + 10, Blocks.STAINED_HARDENED_CLAY, 8);
		this.setBlock(world, i + 13, j + 8, k + 6, Blocks.STAINED_HARDENED_CLAY, 8);
		this.setBlock(world, i + 13, j + 8, k + 7, Blocks.STAINED_HARDENED_CLAY, 8);
		this.setBlock(world, i + 13, j + 8, k + 8, Blocks.STAINED_HARDENED_CLAY, 8);
		this.setBlock(world, i + 13, j + 8, k + 9, Blocks.STAINED_HARDENED_CLAY, 8);
		this.setBlock(world, i + 14, j + 0, k + 0, Blocks.SNOW, 0);
		this.setBlock(world, i + 14, j + 0, k + 1, Blocks.SNOW, 0);
		this.setBlock(world, i + 14, j + 0, k + 2, Blocks.SNOW, 0);
		this.setBlock(world, i + 14, j + 0, k + 3, Blocks.SNOW, 0);
		this.setBlock(world, i + 14, j + 0, k + 4, Blocks.SNOW, 0);
		this.setBlock(world, i + 14, j + 0, k + 5, Blocks.SNOW, 0);
		this.setBlock(world, i + 14, j + 0, k + 6, Blocks.SNOW, 0);
		this.setBlock(world, i + 14, j + 0, k + 7, Blocks.SNOW, 0);
		this.setBlock(world, i + 14, j + 0, k + 8, Blocks.SNOW, 0);
		this.setBlock(world, i + 14, j + 0, k + 9, Blocks.SNOW, 0);
		this.setBlock(world, i + 14, j + 0, k + 10, Blocks.SNOW, 0);
		this.setBlock(world, i + 14, j + 0, k + 11, Blocks.SNOW, 0);
		this.setBlock(world, i + 14, j + 0, k + 12, Blocks.SNOW, 0);
		this.setBlock(world, i + 14, j + 0, k + 13, Blocks.SNOW, 0);
		this.setBlock(world, i + 14, j + 0, k + 14, Blocks.SNOW, 0);
		this.setBlock(world, i + 14, j + 0, k + 15, Blocks.SNOW, 0);
		this.setBlock(world, i + 14, j + 1, k + 1, Blocks.SNOW, 0);
		this.setBlock(world, i + 14, j + 1, k + 2, Blocks.SNOW, 0);
		this.setBlock(world, i + 14, j + 1, k + 3, Blocks.SNOW, 0);
		this.setBlock(world, i + 14, j + 1, k + 4, Blocks.SNOW, 0);
		this.setBlock(world, i + 14, j + 1, k + 5, Blocks.SNOW, 0);
		this.setBlock(world, i + 14, j + 1, k + 6, Blocks.STAINED_HARDENED_CLAY, 0);
		this.setBlock(world, i + 14, j + 1, k + 7, Blocks.STAINED_HARDENED_CLAY, 0);
		this.setBlock(world, i + 14, j + 1, k + 8, Blocks.STAINED_HARDENED_CLAY, 0);
		this.setBlock(world, i + 14, j + 1, k + 9, Blocks.STAINED_HARDENED_CLAY, 0);
		this.setBlock(world, i + 14, j + 1, k + 10, Blocks.SNOW, 0);
		this.setBlock(world, i + 14, j + 1, k + 11, Blocks.SNOW, 0);
		this.setBlock(world, i + 14, j + 1, k + 12, Blocks.SNOW, 0);
		this.setBlock(world, i + 14, j + 1, k + 13, Blocks.SNOW, 0);
		this.setBlock(world, i + 14, j + 1, k + 14, Blocks.SNOW, 0);
		this.setBlock(world, i + 14, j + 2, k + 2, Blocks.SNOW, 0);
		this.setBlock(world, i + 14, j + 2, k + 3, Blocks.SNOW, 0);
		this.setBlock(world, i + 14, j + 2, k + 4, Blocks.SNOW, 0);
		this.setBlock(world, i + 14, j + 2, k + 5, Blocks.STAINED_HARDENED_CLAY, 0);
		this.setBlock(world, i + 14, j + 2, k + 6, Blocks.STAINED_HARDENED_CLAY, 0);
		this.setBlock(world, i + 14, j + 2, k + 7, Blocks.STAINED_HARDENED_CLAY, 0);
		this.setBlock(world, i + 14, j + 2, k + 8, Blocks.STAINED_HARDENED_CLAY, 0);
		this.setBlock(world, i + 14, j + 2, k + 9, Blocks.STAINED_HARDENED_CLAY, 0);
		this.setBlock(world, i + 14, j + 2, k + 10, Blocks.SNOW, 0);
		this.setBlock(world, i + 14, j + 2, k + 11, Blocks.SNOW, 0);
		this.setBlock(world, i + 14, j + 2, k + 12, Blocks.SNOW, 0);
		this.setBlock(world, i + 14, j + 2, k + 13, Blocks.SNOW, 0);
		this.setBlock(world, i + 14, j + 3, k + 3, Blocks.HARDENED_CLAY, 0);
		this.setBlock(world, i + 14, j + 3, k + 4, Blocks.STAINED_HARDENED_CLAY, 0);
		this.setBlock(world, i + 14, j + 3, k + 5, Blocks.STAINED_HARDENED_CLAY, 0);
		this.setBlock(world, i + 14, j + 3, k + 6, Blocks.STAINED_HARDENED_CLAY, 0);
		this.setBlock(world, i + 14, j + 3, k + 7, Blocks.STAINED_HARDENED_CLAY, 0);
		this.setBlock(world, i + 14, j + 3, k + 8, Blocks.STAINED_HARDENED_CLAY, 0);
		this.setBlock(world, i + 14, j + 3, k + 9, Blocks.STAINED_HARDENED_CLAY, 0);
		this.setBlock(world, i + 14, j + 3, k + 10, Blocks.STAINED_HARDENED_CLAY, 0);
		this.setBlock(world, i + 14, j + 3, k + 11, Blocks.STAINED_HARDENED_CLAY, 0);
		this.setBlock(world, i + 14, j + 3, k + 12, Blocks.HARDENED_CLAY, 0);
		this.setBlock(world, i + 14, j + 4, k + 3, Blocks.STAINED_HARDENED_CLAY, 8);
		this.setBlock(world, i + 14, j + 4, k + 4, Blocks.STAINED_HARDENED_CLAY, 0);
		this.setBlock(world, i + 14, j + 4, k + 5, Blocks.STAINED_HARDENED_CLAY, 0);
		this.setBlock(world, i + 14, j + 4, k + 6, Blocks.STAINED_HARDENED_CLAY, 0);
		this.setBlock(world, i + 14, j + 4, k + 7, Blocks.STAINED_HARDENED_CLAY, 0);
		this.setBlock(world, i + 14, j + 4, k + 8, Blocks.STAINED_HARDENED_CLAY, 0);
		this.setBlock(world, i + 14, j + 4, k + 9, Blocks.STAINED_HARDENED_CLAY, 0);
		this.setBlock(world, i + 14, j + 4, k + 10, Blocks.STAINED_HARDENED_CLAY, 0);
		this.setBlock(world, i + 14, j + 4, k + 11, Blocks.STAINED_HARDENED_CLAY, 0);
		this.setBlock(world, i + 14, j + 4, k + 12, Blocks.STAINED_HARDENED_CLAY, 8);
		this.setBlock(world, i + 14, j + 5, k + 4, Blocks.STAINED_HARDENED_CLAY, 8);
		this.setBlock(world, i + 14, j + 5, k + 5, Blocks.STAINED_HARDENED_CLAY, 8);
		this.setBlock(world, i + 14, j + 5, k + 6, Blocks.STAINED_HARDENED_CLAY, 0);
		this.setBlock(world, i + 14, j + 5, k + 7, Blocks.STAINED_HARDENED_CLAY, 0);
		this.setBlock(world, i + 14, j + 5, k + 8, Blocks.STAINED_HARDENED_CLAY, 0);
		this.setBlock(world, i + 14, j + 5, k + 9, Blocks.STAINED_HARDENED_CLAY, 0);
		this.setBlock(world, i + 14, j + 5, k + 10, Blocks.STAINED_HARDENED_CLAY, 8);
		this.setBlock(world, i + 14, j + 5, k + 11, Blocks.STAINED_HARDENED_CLAY, 8);
		this.setBlock(world, i + 14, j + 6, k + 6, Blocks.STAINED_HARDENED_CLAY, 8);
		this.setBlock(world, i + 14, j + 6, k + 7, Blocks.STAINED_HARDENED_CLAY, 8);
		this.setBlock(world, i + 14, j + 6, k + 8, Blocks.STAINED_HARDENED_CLAY, 8);
		this.setBlock(world, i + 14, j + 6, k + 9, Blocks.STAINED_HARDENED_CLAY, 8);
		this.setBlock(world, i + 15, j + 0, k + 0, Blocks.SNOW, 0);
		this.setBlock(world, i + 15, j + 0, k + 1, Blocks.SNOW, 0);
		this.setBlock(world, i + 15, j + 0, k + 2, Blocks.SNOW, 0);
		this.setBlock(world, i + 15, j + 0, k + 3, Blocks.SNOW, 0);
		this.setBlock(world, i + 15, j + 0, k + 4, Blocks.SNOW, 0);
		this.setBlock(world, i + 15, j + 0, k + 5, Blocks.SNOW, 0);
		this.setBlock(world, i + 15, j + 0, k + 6, Blocks.SNOW, 0);
		this.setBlock(world, i + 15, j + 0, k + 7, Blocks.SNOW, 0);
		this.setBlock(world, i + 15, j + 0, k + 8, Blocks.SNOW, 0);
		this.setBlock(world, i + 15, j + 0, k + 9, Blocks.SNOW, 0);
		this.setBlock(world, i + 15, j + 0, k + 10, Blocks.SNOW, 0);
		this.setBlock(world, i + 15, j + 0, k + 11, Blocks.SNOW, 0);
		this.setBlock(world, i + 15, j + 0, k + 12, Blocks.SNOW, 0);
		this.setBlock(world, i + 15, j + 0, k + 13, Blocks.SNOW, 0);
		this.setBlock(world, i + 15, j + 0, k + 14, Blocks.SNOW, 0);
		this.setBlock(world, i + 15, j + 0, k + 15, Blocks.SNOW, 0);
		this.setBlock(world, i + 15, j + 1, k + 1, Blocks.SNOW, 0);
		this.setBlock(world, i + 15, j + 1, k + 2, Blocks.SNOW, 0);
		this.setBlock(world, i + 15, j + 1, k + 3, Blocks.SNOW, 0);
		this.setBlock(world, i + 15, j + 1, k + 4, Blocks.SNOW, 0);
		this.setBlock(world, i + 15, j + 1, k + 5, Blocks.SNOW, 0);
		this.setBlock(world, i + 15, j + 1, k + 6, Blocks.SNOW, 0);
		this.setBlock(world, i + 15, j + 1, k + 7, Blocks.STAINED_HARDENED_CLAY, 0);
		this.setBlock(world, i + 15, j + 1, k + 8, Blocks.STAINED_HARDENED_CLAY, 0);
		this.setBlock(world, i + 15, j + 1, k + 9, Blocks.SNOW, 0);
		this.setBlock(world, i + 15, j + 1, k + 10, Blocks.SNOW, 0);
		this.setBlock(world, i + 15, j + 1, k + 11, Blocks.SNOW, 0);
		this.setBlock(world, i + 15, j + 1, k + 12, Blocks.SNOW, 0);
		this.setBlock(world, i + 15, j + 1, k + 13, Blocks.SNOW, 0);
		this.setBlock(world, i + 15, j + 1, k + 14, Blocks.SNOW, 0);
		this.setBlock(world, i + 15, j + 2, k + 2, Blocks.SNOW, 0);
		this.setBlock(world, i + 15, j + 2, k + 3, Blocks.SNOW, 0);
		this.setBlock(world, i + 15, j + 2, k + 4, Blocks.SNOW, 0);
		this.setBlock(world, i + 15, j + 2, k + 5, Blocks.SNOW, 0);
		this.setBlock(world, i + 15, j + 2, k + 6, Blocks.SNOW, 0);
		this.setBlock(world, i + 15, j + 2, k + 7, Blocks.STAINED_HARDENED_CLAY, 0);
		this.setBlock(world, i + 15, j + 2, k + 8, Blocks.STAINED_HARDENED_CLAY, 0);
		this.setBlock(world, i + 15, j + 2, k + 9, Blocks.SNOW, 0);
		this.setBlock(world, i + 15, j + 2, k + 10, Blocks.SNOW, 0);
		this.setBlock(world, i + 15, j + 2, k + 11, Blocks.SNOW, 0);
		this.setBlock(world, i + 15, j + 2, k + 12, Blocks.SNOW, 0);
		this.setBlock(world, i + 15, j + 2, k + 13, Blocks.SNOW, 0);
		this.setBlock(world, i + 15, j + 3, k + 3, Blocks.HARDENED_CLAY, 0);
		this.setBlock(world, i + 15, j + 3, k + 4, Blocks.STAINED_HARDENED_CLAY, 0);
		this.setBlock(world, i + 15, j + 3, k + 5, Blocks.STAINED_HARDENED_CLAY, 0);
		this.setBlock(world, i + 15, j + 3, k + 6, Blocks.STAINED_HARDENED_CLAY, 0);
		this.setBlock(world, i + 15, j + 3, k + 7, Blocks.STAINED_HARDENED_CLAY, 0);
		this.setBlock(world, i + 15, j + 3, k + 8, Blocks.STAINED_HARDENED_CLAY, 0);
		this.setBlock(world, i + 15, j + 3, k + 9, Blocks.STAINED_HARDENED_CLAY, 0);
		this.setBlock(world, i + 15, j + 3, k + 10, Blocks.STAINED_HARDENED_CLAY, 0);
		this.setBlock(world, i + 15, j + 3, k + 11, Blocks.STAINED_HARDENED_CLAY, 0);
		this.setBlock(world, i + 15, j + 3, k + 12, Blocks.HARDENED_CLAY, 0);
		this.setBlock(world, i + 15, j + 4, k + 4, Blocks.STAINED_HARDENED_CLAY, 8);
		this.setBlock(world, i + 15, j + 4, k + 5, Blocks.STAINED_HARDENED_CLAY, 0);
		this.setBlock(world, i + 15, j + 4, k + 6, Blocks.STAINED_HARDENED_CLAY, 0);
		this.setBlock(world, i + 15, j + 4, k + 7, Blocks.STAINED_HARDENED_CLAY, 0);
		this.setBlock(world, i + 15, j + 4, k + 8, Blocks.STAINED_HARDENED_CLAY, 0);
		this.setBlock(world, i + 15, j + 4, k + 9, Blocks.STAINED_HARDENED_CLAY, 0);
		this.setBlock(world, i + 15, j + 4, k + 10, Blocks.STAINED_HARDENED_CLAY, 0);
		this.setBlock(world, i + 15, j + 4, k + 11, Blocks.STAINED_HARDENED_CLAY, 8);
		this.setBlock(world, i + 15, j + 5, k + 5, Blocks.STAINED_HARDENED_CLAY, 8);
		this.setBlock(world, i + 15, j + 5, k + 6, Blocks.STAINED_HARDENED_CLAY, 8);
		this.setBlock(world, i + 15, j + 5, k + 7, Blocks.STAINED_HARDENED_CLAY, 8);
		this.setBlock(world, i + 15, j + 5, k + 8, Blocks.STAINED_HARDENED_CLAY, 8);
		this.setBlock(world, i + 15, j + 5, k + 9, Blocks.STAINED_HARDENED_CLAY, 8);
		this.setBlock(world, i + 15, j + 5, k + 10, Blocks.STAINED_HARDENED_CLAY, 8);
		this.setBlock(world, i + 16, j + 0, k + 0, Blocks.SNOW, 0);
		this.setBlock(world, i + 16, j + 0, k + 1, Blocks.SNOW, 0);
		this.setBlock(world, i + 16, j + 0, k + 2, Blocks.SNOW, 0);
		this.setBlock(world, i + 16, j + 0, k + 3, Blocks.SNOW, 0);
		this.setBlock(world, i + 16, j + 0, k + 4, Blocks.SNOW, 0);
		this.setBlock(world, i + 16, j + 0, k + 5, Blocks.SNOW, 0);
		this.setBlock(world, i + 16, j + 0, k + 6, Blocks.SNOW, 0);
		this.setBlock(world, i + 16, j + 0, k + 7, Blocks.SNOW, 0);
		this.setBlock(world, i + 16, j + 0, k + 8, Blocks.SNOW, 0);
		this.setBlock(world, i + 16, j + 0, k + 9, Blocks.SNOW, 0);
		this.setBlock(world, i + 16, j + 0, k + 10, Blocks.SNOW, 0);
		this.setBlock(world, i + 16, j + 0, k + 11, Blocks.SNOW, 0);
		this.setBlock(world, i + 16, j + 0, k + 12, Blocks.SNOW, 0);
		this.setBlock(world, i + 16, j + 0, k + 13, Blocks.SNOW, 0);
		this.setBlock(world, i + 16, j + 0, k + 14, Blocks.SNOW, 0);
		this.setBlock(world, i + 16, j + 0, k + 15, Blocks.SNOW, 0);
		this.setBlock(world, i + 16, j + 1, k + 1, Blocks.SNOW, 0);
		this.setBlock(world, i + 16, j + 1, k + 2, Blocks.SNOW, 0);
		this.setBlock(world, i + 16, j + 1, k + 3, Blocks.SNOW, 0);
		this.setBlock(world, i + 16, j + 1, k + 4, Blocks.SNOW, 0);
		this.setBlock(world, i + 16, j + 1, k + 5, Blocks.SNOW, 0);
		this.setBlock(world, i + 16, j + 1, k + 6, Blocks.SNOW, 0);
		this.setBlock(world, i + 16, j + 1, k + 7, Blocks.SNOW, 0);
		this.setBlock(world, i + 16, j + 1, k + 8, Blocks.SNOW, 0);
		this.setBlock(world, i + 16, j + 1, k + 9, Blocks.SNOW, 0);
		this.setBlock(world, i + 16, j + 1, k + 10, Blocks.SNOW, 0);
		this.setBlock(world, i + 16, j + 1, k + 11, Blocks.SNOW, 0);
		this.setBlock(world, i + 16, j + 1, k + 12, Blocks.SNOW, 0);
		this.setBlock(world, i + 16, j + 1, k + 13, Blocks.SNOW, 0);
		this.setBlock(world, i + 16, j + 1, k + 14, Blocks.SNOW, 0);
		this.setBlock(world, i + 16, j + 2, k + 2, Blocks.SNOW, 0);
		this.setBlock(world, i + 16, j + 2, k + 3, Blocks.SNOW, 0);
		this.setBlock(world, i + 16, j + 2, k + 4, Blocks.SNOW, 0);
		this.setBlock(world, i + 16, j + 2, k + 5, Blocks.SNOW, 0);
		this.setBlock(world, i + 16, j + 2, k + 6, Blocks.SNOW, 0);
		this.setBlock(world, i + 16, j + 2, k + 7, Blocks.SNOW, 0);
		this.setBlock(world, i + 16, j + 2, k + 8, Blocks.SNOW, 0);
		this.setBlock(world, i + 16, j + 2, k + 9, Blocks.SNOW, 0);
		this.setBlock(world, i + 16, j + 2, k + 10, Blocks.SNOW, 0);
		this.setBlock(world, i + 16, j + 2, k + 11, Blocks.SNOW, 0);
		this.setBlock(world, i + 16, j + 2, k + 12, Blocks.SNOW, 0);
		this.setBlock(world, i + 16, j + 2, k + 13, Blocks.SNOW, 0);
		this.setBlock(world, i + 16, j + 3, k + 4, Blocks.HARDENED_CLAY, 0);
		this.setBlock(world, i + 16, j + 3, k + 5, Blocks.STAINED_HARDENED_CLAY, 0);
		this.setBlock(world, i + 16, j + 3, k + 6, Blocks.STAINED_HARDENED_CLAY, 0);
		this.setBlock(world, i + 16, j + 3, k + 7, Blocks.STAINED_HARDENED_CLAY, 0);
		this.setBlock(world, i + 16, j + 3, k + 8, Blocks.STAINED_HARDENED_CLAY, 0);
		this.setBlock(world, i + 16, j + 3, k + 9, Blocks.STAINED_HARDENED_CLAY, 0);
		this.setBlock(world, i + 16, j + 3, k + 10, Blocks.STAINED_HARDENED_CLAY, 0);
		this.setBlock(world, i + 16, j + 3, k + 11, Blocks.HARDENED_CLAY, 0);
		this.setBlock(world, i + 16, j + 4, k + 5, Blocks.STAINED_HARDENED_CLAY, 8);
		this.setBlock(world, i + 16, j + 4, k + 6, Blocks.STAINED_HARDENED_CLAY, 8);
		this.setBlock(world, i + 16, j + 4, k + 7, Blocks.STAINED_HARDENED_CLAY, 8);
		this.setBlock(world, i + 16, j + 4, k + 8, Blocks.STAINED_HARDENED_CLAY, 8);
		this.setBlock(world, i + 16, j + 4, k + 9, Blocks.STAINED_HARDENED_CLAY, 8);
		this.setBlock(world, i + 16, j + 4, k + 10, Blocks.STAINED_HARDENED_CLAY, 8);
		this.setBlock(world, i + 17, j + 0, k + 1, Blocks.SNOW, 0);
		this.setBlock(world, i + 17, j + 0, k + 2, Blocks.SNOW, 0);
		this.setBlock(world, i + 17, j + 0, k + 3, Blocks.SNOW, 0);
		this.setBlock(world, i + 17, j + 0, k + 4, Blocks.SNOW, 0);
		this.setBlock(world, i + 17, j + 0, k + 5, Blocks.SNOW, 0);
		this.setBlock(world, i + 17, j + 0, k + 6, Blocks.SNOW, 0);
		this.setBlock(world, i + 17, j + 0, k + 7, Blocks.SNOW, 0);
		this.setBlock(world, i + 17, j + 0, k + 8, Blocks.SNOW, 0);
		this.setBlock(world, i + 17, j + 0, k + 9, Blocks.SNOW, 0);
		this.setBlock(world, i + 17, j + 0, k + 10, Blocks.SNOW, 0);
		this.setBlock(world, i + 17, j + 0, k + 11, Blocks.SNOW, 0);
		this.setBlock(world, i + 17, j + 0, k + 12, Blocks.SNOW, 0);
		this.setBlock(world, i + 17, j + 0, k + 13, Blocks.SNOW, 0);
		this.setBlock(world, i + 17, j + 0, k + 14, Blocks.SNOW, 0);
		this.setBlock(world, i + 17, j + 1, k + 2, Blocks.SNOW, 0);
		this.setBlock(world, i + 17, j + 1, k + 3, Blocks.SNOW, 0);
		this.setBlock(world, i + 17, j + 1, k + 4, Blocks.SNOW, 0);
		this.setBlock(world, i + 17, j + 1, k + 5, Blocks.SNOW, 0);
		this.setBlock(world, i + 17, j + 1, k + 6, Blocks.SNOW, 0);
		this.setBlock(world, i + 17, j + 1, k + 7, Blocks.SNOW, 0);
		this.setBlock(world, i + 17, j + 1, k + 8, Blocks.SNOW, 0);
		this.setBlock(world, i + 17, j + 1, k + 9, Blocks.SNOW, 0);
		this.setBlock(world, i + 17, j + 1, k + 10, Blocks.SNOW, 0);
		this.setBlock(world, i + 17, j + 1, k + 11, Blocks.SNOW, 0);
		this.setBlock(world, i + 17, j + 1, k + 12, Blocks.SNOW, 0);
		this.setBlock(world, i + 17, j + 1, k + 13, Blocks.SNOW, 0);
		this.setBlock(world, i + 17, j + 2, k + 3, Blocks.SNOW, 0);
		this.setBlock(world, i + 17, j + 2, k + 4, Blocks.SNOW, 0);
		this.setBlock(world, i + 17, j + 2, k + 5, Blocks.SNOW, 0);
		this.setBlock(world, i + 17, j + 2, k + 6, Blocks.SNOW, 0);
		this.setBlock(world, i + 17, j + 2, k + 7, Blocks.SNOW, 0);
		this.setBlock(world, i + 17, j + 2, k + 8, Blocks.SNOW, 0);
		this.setBlock(world, i + 17, j + 2, k + 9, Blocks.SNOW, 0);
		this.setBlock(world, i + 17, j + 2, k + 10, Blocks.SNOW, 0);
		this.setBlock(world, i + 17, j + 2, k + 11, Blocks.SNOW, 0);
		this.setBlock(world, i + 17, j + 2, k + 12, Blocks.SNOW, 0);
		this.setBlock(world, i + 17, j + 3, k + 5, Blocks.HARDENED_CLAY, 0);
		this.setBlock(world, i + 17, j + 3, k + 6, Blocks.HARDENED_CLAY, 0);
		this.setBlock(world, i + 17, j + 3, k + 7, Blocks.HARDENED_CLAY, 0);
		this.setBlock(world, i + 17, j + 3, k + 8, Blocks.HARDENED_CLAY, 0);
		this.setBlock(world, i + 17, j + 3, k + 9, Blocks.HARDENED_CLAY, 0);
		this.setBlock(world, i + 17, j + 3, k + 10, Blocks.HARDENED_CLAY, 0);
		this.setBlock(world, i + 18, j + 0, k + 2, Blocks.SNOW, 0);
		this.setBlock(world, i + 18, j + 0, k + 3, Blocks.SNOW, 0);
		this.setBlock(world, i + 18, j + 0, k + 4, Blocks.SNOW, 0);
		this.setBlock(world, i + 18, j + 0, k + 5, Blocks.SNOW, 0);
		this.setBlock(world, i + 18, j + 0, k + 6, Blocks.SNOW, 0);
		this.setBlock(world, i + 18, j + 0, k + 7, Blocks.SNOW, 0);
		this.setBlock(world, i + 18, j + 0, k + 8, Blocks.SNOW, 0);
		this.setBlock(world, i + 18, j + 0, k + 9, Blocks.SNOW, 0);
		this.setBlock(world, i + 18, j + 0, k + 10, Blocks.SNOW, 0);
		this.setBlock(world, i + 18, j + 0, k + 11, Blocks.SNOW, 0);
		this.setBlock(world, i + 18, j + 0, k + 12, Blocks.SNOW, 0);
		this.setBlock(world, i + 18, j + 0, k + 13, Blocks.SNOW, 0);
		this.setBlock(world, i + 18, j + 1, k + 3, Blocks.SNOW, 0);
		this.setBlock(world, i + 18, j + 1, k + 4, Blocks.SNOW, 0);
		this.setBlock(world, i + 18, j + 1, k + 5, Blocks.SNOW, 0);
		this.setBlock(world, i + 18, j + 1, k + 6, Blocks.SNOW, 0);
		this.setBlock(world, i + 18, j + 1, k + 7, Blocks.SNOW, 0);
		this.setBlock(world, i + 18, j + 1, k + 8, Blocks.SNOW, 0);
		this.setBlock(world, i + 18, j + 1, k + 9, Blocks.SNOW, 0);
		this.setBlock(world, i + 18, j + 1, k + 10, Blocks.SNOW, 0);
		this.setBlock(world, i + 18, j + 1, k + 11, Blocks.SNOW, 0);
		this.setBlock(world, i + 18, j + 1, k + 12, Blocks.SNOW, 0);
		this.setBlock(world, i + 18, j + 2, k + 4, Blocks.SNOW, 0);
		this.setBlock(world, i + 18, j + 2, k + 5, Blocks.SNOW, 0);
		this.setBlock(world, i + 18, j + 2, k + 6, Blocks.SNOW, 0);
		this.setBlock(world, i + 18, j + 2, k + 7, Blocks.SNOW, 0);
		this.setBlock(world, i + 18, j + 2, k + 8, Blocks.SNOW, 0);
		this.setBlock(world, i + 18, j + 2, k + 9, Blocks.SNOW, 0);
		this.setBlock(world, i + 18, j + 2, k + 10, Blocks.SNOW, 0);
		this.setBlock(world, i + 18, j + 2, k + 11, Blocks.SNOW, 0);
		this.setBlock(world, i + 19, j + 0, k + 3, Blocks.SNOW, 0);
		this.setBlock(world, i + 19, j + 0, k + 4, Blocks.SNOW, 0);
		this.setBlock(world, i + 19, j + 0, k + 5, Blocks.SNOW, 0);
		this.setBlock(world, i + 19, j + 0, k + 6, Blocks.SNOW, 0);
		this.setBlock(world, i + 19, j + 0, k + 7, Blocks.SNOW, 0);
		this.setBlock(world, i + 19, j + 0, k + 8, Blocks.SNOW, 0);
		this.setBlock(world, i + 19, j + 0, k + 9, Blocks.SNOW, 0);
		this.setBlock(world, i + 19, j + 0, k + 10, Blocks.SNOW, 0);
		this.setBlock(world, i + 19, j + 0, k + 11, Blocks.SNOW, 0);
		this.setBlock(world, i + 19, j + 0, k + 12, Blocks.SNOW, 0);
		this.setBlock(world, i + 19, j + 1, k + 4, Blocks.SNOW, 0);
		this.setBlock(world, i + 19, j + 1, k + 5, Blocks.SNOW, 0);
		this.setBlock(world, i + 19, j + 1, k + 6, Blocks.SNOW, 0);
		this.setBlock(world, i + 19, j + 1, k + 7, Blocks.SNOW, 0);
		this.setBlock(world, i + 19, j + 1, k + 8, Blocks.SNOW, 0);
		this.setBlock(world, i + 19, j + 1, k + 9, Blocks.SNOW, 0);
		this.setBlock(world, i + 19, j + 1, k + 10, Blocks.SNOW, 0);
		this.setBlock(world, i + 19, j + 1, k + 11, Blocks.SNOW, 0);
		this.setBlock(world, i + 20, j + 0, k + 4, Blocks.SNOW, 0);
		this.setBlock(world, i + 20, j + 0, k + 5, Blocks.SNOW, 0);
		this.setBlock(world, i + 20, j + 0, k + 6, Blocks.SNOW, 0);
		this.setBlock(world, i + 20, j + 0, k + 7, Blocks.SNOW, 0);
		this.setBlock(world, i + 20, j + 0, k + 8, Blocks.SNOW, 0);
		this.setBlock(world, i + 20, j + 0, k + 9, Blocks.SNOW, 0);
		this.setBlock(world, i + 20, j + 0, k + 10, Blocks.SNOW, 0);
		this.setBlock(world, i + 20, j + 0, k + 11, Blocks.SNOW, 0);
/*		world.setBlockMetadataWithNotify(i + 7, j + 3, k + 6, 3, 2);
		world.setBlockMetadataWithNotify(i + 7, j + 3, k + 9, 4, 2);
		world.setBlockMetadataWithNotify(i + 8, j + 3, k + 5, 1, 2);
		world.setBlockMetadataWithNotify(i + 8, j + 3, k + 10, 1, 2);
		world.setBlockMetadataWithNotify(i + 12, j + 3, k + 5, 2, 2);
		world.setBlockMetadataWithNotify(i + 12, j + 3, k + 10, 2, 2);
		world.setBlockMetadataWithNotify(i + 13, j + 3, k + 6, 3, 2);
		world.setBlockMetadataWithNotify(i + 13, j + 3, k + 9, 4, 2);*/

		return true;
	}
}