package com.zalthrion.zylroth.world.mapstructures;

import java.util.Random;

import net.minecraft.block.Block;
import net.minecraft.init.Blocks;
import net.minecraft.util.math.BlockPos;
import net.minecraft.world.World;
import net.minecraft.world.gen.feature.WorldGenerator;

public class IceHouse extends WorldGenerator {
	@Override public boolean generate(World world, Random rand, BlockPos pos) {
		this.generate(world, rand, pos.getX(), pos.getY(), pos.getZ());
		return true;
	}
	
	@Deprecated private void setBlock(World world, int i, int j, int k, Block block, int meta) {
		world.setBlockState(new BlockPos(i, j, k), block.getStateFromMeta(meta));
	}
	
	@Deprecated public boolean generate(World world, Random rand, int i, int j, int k) {
		this.setBlock(world, i + 0, j + 0, k + 0, Blocks.AIR, 0);
		this.setBlock(world, i + 0, j + 0, k + 1, Blocks.AIR, 0);
		this.setBlock(world, i + 0, j + 0, k + 2, Blocks.COBBLESTONE, 0);
		this.setBlock(world, i + 0, j + 0, k + 3, Blocks.STONE_STAIRS, 0);
		this.setBlock(world, i + 0, j + 0, k + 4, Blocks.COBBLESTONE, 0);
		this.setBlock(world, i + 0, j + 0, k + 5, Blocks.AIR, 0);
		this.setBlock(world, i + 0, j + 0, k + 6, Blocks.AIR, 0);
		this.setBlock(world, i + 0, j + 1, k + 0, Blocks.AIR, 0);
		this.setBlock(world, i + 0, j + 1, k + 1, Blocks.AIR, 0);
		this.setBlock(world, i + 0, j + 1, k + 2, Blocks.AIR, 0);
		this.setBlock(world, i + 0, j + 1, k + 3, Blocks.AIR, 0);
		this.setBlock(world, i + 0, j + 1, k + 4, Blocks.AIR, 0);
		this.setBlock(world, i + 0, j + 1, k + 5, Blocks.AIR, 0);
		this.setBlock(world, i + 0, j + 1, k + 6, Blocks.AIR, 0);
		this.setBlock(world, i + 0, j + 2, k + 0, Blocks.AIR, 0);
		this.setBlock(world, i + 0, j + 2, k + 1, Blocks.AIR, 0);
		this.setBlock(world, i + 0, j + 2, k + 2, Blocks.AIR, 0);
		this.setBlock(world, i + 0, j + 2, k + 3, Blocks.AIR, 0);
		this.setBlock(world, i + 0, j + 2, k + 4, Blocks.AIR, 0);
		this.setBlock(world, i + 0, j + 2, k + 5, Blocks.AIR, 0);
		this.setBlock(world, i + 0, j + 2, k + 6, Blocks.AIR, 0);
		this.setBlock(world, i + 0, j + 3, k + 0, Blocks.AIR, 0);
		this.setBlock(world, i + 0, j + 3, k + 1, Blocks.AIR, 0);
		this.setBlock(world, i + 0, j + 3, k + 2, Blocks.AIR, 0);
		this.setBlock(world, i + 0, j + 3, k + 3, Blocks.AIR, 0);
		this.setBlock(world, i + 0, j + 3, k + 4, Blocks.AIR, 0);
		this.setBlock(world, i + 0, j + 3, k + 5, Blocks.AIR, 0);
		this.setBlock(world, i + 0, j + 3, k + 6, Blocks.AIR, 0);
		this.setBlock(world, i + 0, j + 4, k + 0, Blocks.AIR, 0);
		this.setBlock(world, i + 0, j + 4, k + 1, Blocks.AIR, 0);
		this.setBlock(world, i + 0, j + 4, k + 2, Blocks.AIR, 0);
		this.setBlock(world, i + 0, j + 4, k + 3, Blocks.AIR, 0);
		this.setBlock(world, i + 0, j + 4, k + 4, Blocks.AIR, 0);
		this.setBlock(world, i + 0, j + 4, k + 5, Blocks.AIR, 0);
		this.setBlock(world, i + 0, j + 4, k + 6, Blocks.AIR, 0);
		this.setBlock(world, i + 0, j + 5, k + 0, Blocks.AIR, 0);
		this.setBlock(world, i + 0, j + 5, k + 1, Blocks.AIR, 0);
		this.setBlock(world, i + 0, j + 5, k + 2, Blocks.AIR, 0);
		this.setBlock(world, i + 0, j + 5, k + 3, Blocks.AIR, 0);
		this.setBlock(world, i + 0, j + 5, k + 4, Blocks.AIR, 0);
		this.setBlock(world, i + 0, j + 5, k + 5, Blocks.AIR, 0);
		this.setBlock(world, i + 0, j + 5, k + 6, Blocks.AIR, 0);
		this.setBlock(world, i + 1, j + 0, k + 0, Blocks.COBBLESTONE, 0);
		this.setBlock(world, i + 1, j + 0, k + 1, Blocks.COBBLESTONE, 0);
		this.setBlock(world, i + 1, j + 0, k + 2, Blocks.COBBLESTONE, 0);
		this.setBlock(world, i + 1, j + 0, k + 3, Blocks.COBBLESTONE, 0);
		this.setBlock(world, i + 1, j + 0, k + 4, Blocks.COBBLESTONE, 0);
		this.setBlock(world, i + 1, j + 0, k + 5, Blocks.COBBLESTONE, 0);
		this.setBlock(world, i + 1, j + 0, k + 6, Blocks.COBBLESTONE, 0);
		this.setBlock(world, i + 1, j + 1, k + 0, Blocks.ICE, 0);
		this.setBlock(world, i + 1, j + 1, k + 1, Blocks.SNOW, 0);
		this.setBlock(world, i + 1, j + 1, k + 2, Blocks.SNOW, 0);
		this.setBlock(world, i + 1, j + 1, k + 4, Blocks.SNOW, 0);
		this.setBlock(world, i + 1, j + 1, k + 5, Blocks.SNOW, 0);
		this.setBlock(world, i + 1, j + 1, k + 6, Blocks.ICE, 0);
		this.setBlock(world, i + 1, j + 2, k + 0, Blocks.ICE, 0);
		this.setBlock(world, i + 1, j + 2, k + 1, Blocks.SNOW, 0);
		this.setBlock(world, i + 1, j + 2, k + 2, Blocks.SNOW, 0);
		this.setBlock(world, i + 1, j + 2, k + 4, Blocks.SNOW, 0);
		this.setBlock(world, i + 1, j + 2, k + 5, Blocks.SNOW, 0);
		this.setBlock(world, i + 1, j + 2, k + 6, Blocks.ICE, 0);
		this.setBlock(world, i + 1, j + 3, k + 0, Blocks.ICE, 0);
		this.setBlock(world, i + 1, j + 3, k + 1, Blocks.SNOW, 0);
		this.setBlock(world, i + 1, j + 3, k + 2, Blocks.SNOW, 0);
		this.setBlock(world, i + 1, j + 3, k + 3, Blocks.SNOW, 0);
		this.setBlock(world, i + 1, j + 3, k + 4, Blocks.SNOW, 0);
		this.setBlock(world, i + 1, j + 3, k + 5, Blocks.SNOW, 0);
		this.setBlock(world, i + 1, j + 3, k + 6, Blocks.ICE, 0);
		this.setBlock(world, i + 1, j + 4, k + 0, Blocks.AIR, 0);
		this.setBlock(world, i + 1, j + 4, k + 1, Blocks.ICE, 0);
		this.setBlock(world, i + 1, j + 4, k + 2, Blocks.ICE, 0);
		this.setBlock(world, i + 1, j + 4, k + 3, Blocks.ICE, 0);
		this.setBlock(world, i + 1, j + 4, k + 4, Blocks.ICE, 0);
		this.setBlock(world, i + 1, j + 4, k + 5, Blocks.ICE, 0);
		this.setBlock(world, i + 1, j + 4, k + 6, Blocks.AIR, 0);
		this.setBlock(world, i + 1, j + 5, k + 0, Blocks.AIR, 0);
		this.setBlock(world, i + 1, j + 5, k + 1, Blocks.AIR, 0);
		this.setBlock(world, i + 1, j + 5, k + 2, Blocks.AIR, 0);
		this.setBlock(world, i + 1, j + 5, k + 3, Blocks.AIR, 0);
		this.setBlock(world, i + 1, j + 5, k + 4, Blocks.AIR, 0);
		this.setBlock(world, i + 1, j + 5, k + 5, Blocks.AIR, 0);
		this.setBlock(world, i + 1, j + 5, k + 6, Blocks.AIR, 0);
		this.setBlock(world, i + 2, j + 0, k + 0, Blocks.COBBLESTONE, 0);
		this.setBlock(world, i + 2, j + 0, k + 1, Blocks.COBBLESTONE, 0);
		this.setBlock(world, i + 2, j + 0, k + 2, Blocks.COBBLESTONE, 0);
		this.setBlock(world, i + 2, j + 0, k + 3, Blocks.COBBLESTONE, 0);
		this.setBlock(world, i + 2, j + 0, k + 4, Blocks.COBBLESTONE, 0);
		this.setBlock(world, i + 2, j + 0, k + 5, Blocks.COBBLESTONE, 0);
		this.setBlock(world, i + 2, j + 0, k + 6, Blocks.COBBLESTONE, 0);
		this.setBlock(world, i + 2, j + 1, k + 0, Blocks.SNOW, 0);
		this.setBlock(world, i + 2, j + 1, k + 1, Blocks.CRAFTING_TABLE, 0);
		this.setBlock(world, i + 2, j + 1, k + 2, Blocks.AIR, 0);
		this.setBlock(world, i + 2, j + 1, k + 3, Blocks.AIR, 0);
		this.setBlock(world, i + 2, j + 1, k + 4, Blocks.AIR, 0);
		this.setBlock(world, i + 2, j + 1, k + 5, Blocks.AIR, 0);
		this.setBlock(world, i + 2, j + 1, k + 6, Blocks.SNOW, 0);
		this.setBlock(world, i + 2, j + 2, k + 0, Blocks.SNOW, 0);
		this.setBlock(world, i + 2, j + 2, k + 1, Blocks.AIR, 0);
		this.setBlock(world, i + 2, j + 2, k + 2, Blocks.AIR, 0);
		this.setBlock(world, i + 2, j + 2, k + 3, Blocks.AIR, 0);
		this.setBlock(world, i + 2, j + 2, k + 4, Blocks.AIR, 0);
		this.setBlock(world, i + 2, j + 2, k + 5, Blocks.AIR, 0);
		this.setBlock(world, i + 2, j + 2, k + 6, Blocks.SNOW, 0);
		this.setBlock(world, i + 2, j + 3, k + 0, Blocks.SNOW, 0);
		this.setBlock(world, i + 2, j + 3, k + 1, Blocks.AIR, 0);
		this.setBlock(world, i + 2, j + 3, k + 2, Blocks.AIR, 0);
		this.setBlock(world, i + 2, j + 3, k + 3, Blocks.AIR, 0);
		this.setBlock(world, i + 2, j + 3, k + 4, Blocks.AIR, 0);
		this.setBlock(world, i + 2, j + 3, k + 5, Blocks.AIR, 0);
		this.setBlock(world, i + 2, j + 3, k + 6, Blocks.SNOW, 0);
		this.setBlock(world, i + 2, j + 4, k + 0, Blocks.ICE, 0);
		this.setBlock(world, i + 2, j + 4, k + 1, Blocks.SNOW, 0);
		this.setBlock(world, i + 2, j + 4, k + 2, Blocks.SNOW, 0);
		this.setBlock(world, i + 2, j + 4, k + 3, Blocks.SNOW, 0);
		this.setBlock(world, i + 2, j + 4, k + 4, Blocks.SNOW, 0);
		this.setBlock(world, i + 2, j + 4, k + 5, Blocks.SNOW, 0);
		this.setBlock(world, i + 2, j + 4, k + 6, Blocks.ICE, 0);
		this.setBlock(world, i + 2, j + 5, k + 0, Blocks.AIR, 0);
		this.setBlock(world, i + 2, j + 5, k + 1, Blocks.AIR, 0);
		this.setBlock(world, i + 2, j + 5, k + 2, Blocks.AIR, 0);
		this.setBlock(world, i + 2, j + 5, k + 3, Blocks.AIR, 0);
		this.setBlock(world, i + 2, j + 5, k + 4, Blocks.AIR, 0);
		this.setBlock(world, i + 2, j + 5, k + 5, Blocks.AIR, 0);
		this.setBlock(world, i + 2, j + 5, k + 6, Blocks.AIR, 0);
		this.setBlock(world, i + 3, j + 0, k + 0, Blocks.COBBLESTONE, 0);
		this.setBlock(world, i + 3, j + 0, k + 1, Blocks.COBBLESTONE, 0);
		this.setBlock(world, i + 3, j + 0, k + 2, Blocks.COBBLESTONE, 0);
		this.setBlock(world, i + 3, j + 0, k + 3, Blocks.COBBLESTONE, 0);
		this.setBlock(world, i + 3, j + 0, k + 4, Blocks.COBBLESTONE, 0);
		this.setBlock(world, i + 3, j + 0, k + 5, Blocks.COBBLESTONE, 0);
		this.setBlock(world, i + 3, j + 0, k + 6, Blocks.COBBLESTONE, 0);
		this.setBlock(world, i + 3, j + 1, k + 0, Blocks.SNOW, 0);
		this.setBlock(world, i + 3, j + 1, k + 1, Blocks.AIR, 0);
		this.setBlock(world, i + 3, j + 1, k + 2, Blocks.AIR, 0);
		this.setBlock(world, i + 3, j + 1, k + 3, Blocks.AIR, 0);
		this.setBlock(world, i + 3, j + 1, k + 4, Blocks.AIR, 0);
		this.setBlock(world, i + 3, j + 1, k + 5, Blocks.AIR, 0);
		this.setBlock(world, i + 3, j + 1, k + 6, Blocks.SNOW, 0);
		this.setBlock(world, i + 3, j + 2, k + 0, Blocks.GLASS_PANE, 0);
		this.setBlock(world, i + 3, j + 2, k + 1, Blocks.AIR, 0);
		this.setBlock(world, i + 3, j + 2, k + 2, Blocks.AIR, 0);
		this.setBlock(world, i + 3, j + 2, k + 3, Blocks.AIR, 0);
		this.setBlock(world, i + 3, j + 2, k + 4, Blocks.AIR, 0);
		this.setBlock(world, i + 3, j + 2, k + 5, Blocks.AIR, 0);
		this.setBlock(world, i + 3, j + 2, k + 6, Blocks.GLASS_PANE, 0);
		this.setBlock(world, i + 3, j + 3, k + 0, Blocks.SNOW, 0);
		this.setBlock(world, i + 3, j + 3, k + 1, Blocks.AIR, 0);
		this.setBlock(world, i + 3, j + 3, k + 2, Blocks.AIR, 0);
		this.setBlock(world, i + 3, j + 3, k + 3, Blocks.AIR, 0);
		this.setBlock(world, i + 3, j + 3, k + 4, Blocks.AIR, 0);
		this.setBlock(world, i + 3, j + 3, k + 5, Blocks.AIR, 0);
		this.setBlock(world, i + 3, j + 3, k + 6, Blocks.SNOW, 0);
		this.setBlock(world, i + 3, j + 4, k + 0, Blocks.ICE, 0);
		this.setBlock(world, i + 3, j + 4, k + 1, Blocks.SNOW, 0);
		this.setBlock(world, i + 3, j + 4, k + 2, Blocks.AIR, 0);
		this.setBlock(world, i + 3, j + 4, k + 3, Blocks.AIR, 0);
		this.setBlock(world, i + 3, j + 4, k + 4, Blocks.AIR, 0);
		this.setBlock(world, i + 3, j + 4, k + 5, Blocks.SNOW, 0);
		this.setBlock(world, i + 3, j + 4, k + 6, Blocks.ICE, 0);
		this.setBlock(world, i + 3, j + 5, k + 0, Blocks.AIR, 0);
		this.setBlock(world, i + 3, j + 5, k + 1, Blocks.AIR, 0);
		this.setBlock(world, i + 3, j + 5, k + 2, Blocks.SNOW, 0);
		this.setBlock(world, i + 3, j + 5, k + 3, Blocks.SNOW, 0);
		this.setBlock(world, i + 3, j + 5, k + 4, Blocks.SNOW, 0);
		this.setBlock(world, i + 3, j + 5, k + 5, Blocks.AIR, 0);
		this.setBlock(world, i + 3, j + 5, k + 6, Blocks.AIR, 0);
		this.setBlock(world, i + 4, j + 0, k + 0, Blocks.COBBLESTONE, 0);
		this.setBlock(world, i + 4, j + 0, k + 1, Blocks.COBBLESTONE, 0);
		this.setBlock(world, i + 4, j + 0, k + 2, Blocks.COBBLESTONE, 0);
		this.setBlock(world, i + 4, j + 0, k + 3, Blocks.COBBLESTONE, 0);
		this.setBlock(world, i + 4, j + 0, k + 4, Blocks.COBBLESTONE, 0);
		this.setBlock(world, i + 4, j + 0, k + 5, Blocks.COBBLESTONE, 0);
		this.setBlock(world, i + 4, j + 0, k + 6, Blocks.COBBLESTONE, 0);
		this.setBlock(world, i + 4, j + 1, k + 0, Blocks.SNOW, 0);
		this.setBlock(world, i + 4, j + 1, k + 1, Blocks.AIR, 0);
		this.setBlock(world, i + 4, j + 1, k + 2, Blocks.AIR, 0);
		this.setBlock(world, i + 4, j + 1, k + 3, Blocks.AIR, 0);
		this.setBlock(world, i + 4, j + 1, k + 4, Blocks.AIR, 0);
		this.setBlock(world, i + 4, j + 1, k + 5, Blocks.AIR, 0);
		this.setBlock(world, i + 4, j + 1, k + 6, Blocks.SNOW, 0);
		this.setBlock(world, i + 4, j + 2, k + 0, Blocks.GLASS_PANE, 0);
		this.setBlock(world, i + 4, j + 2, k + 1, Blocks.AIR, 0);
		this.setBlock(world, i + 4, j + 2, k + 2, Blocks.AIR, 0);
		this.setBlock(world, i + 4, j + 2, k + 3, Blocks.AIR, 0);
		this.setBlock(world, i + 4, j + 2, k + 4, Blocks.AIR, 0);
		this.setBlock(world, i + 4, j + 2, k + 5, Blocks.AIR, 0);
		this.setBlock(world, i + 4, j + 2, k + 6, Blocks.GLASS_PANE, 0);
		this.setBlock(world, i + 4, j + 3, k + 0, Blocks.SNOW, 0);
		this.setBlock(world, i + 4, j + 3, k + 1, Blocks.AIR, 0);
		this.setBlock(world, i + 4, j + 3, k + 2, Blocks.AIR, 0);
		this.setBlock(world, i + 4, j + 3, k + 3, Blocks.AIR, 0);
		this.setBlock(world, i + 4, j + 3, k + 4, Blocks.AIR, 0);
		this.setBlock(world, i + 4, j + 3, k + 5, Blocks.AIR, 0);
		this.setBlock(world, i + 4, j + 3, k + 6, Blocks.SNOW, 0);
		this.setBlock(world, i + 4, j + 4, k + 0, Blocks.ICE, 0);
		this.setBlock(world, i + 4, j + 4, k + 1, Blocks.SNOW, 0);
		this.setBlock(world, i + 4, j + 4, k + 2, Blocks.AIR, 0);
		this.setBlock(world, i + 4, j + 4, k + 3, Blocks.AIR, 0);
		this.setBlock(world, i + 4, j + 4, k + 4, Blocks.AIR, 0);
		this.setBlock(world, i + 4, j + 4, k + 5, Blocks.SNOW, 0);
		this.setBlock(world, i + 4, j + 4, k + 6, Blocks.ICE, 0);
		this.setBlock(world, i + 4, j + 5, k + 0, Blocks.AIR, 0);
		this.setBlock(world, i + 4, j + 5, k + 1, Blocks.AIR, 0);
		this.setBlock(world, i + 4, j + 5, k + 2, Blocks.SNOW, 0);
		this.setBlock(world, i + 4, j + 5, k + 3, Blocks.SNOW, 0);
		this.setBlock(world, i + 4, j + 5, k + 4, Blocks.SNOW, 0);
		this.setBlock(world, i + 4, j + 5, k + 5, Blocks.AIR, 0);
		this.setBlock(world, i + 4, j + 5, k + 6, Blocks.AIR, 0);
		this.setBlock(world, i + 5, j + 0, k + 0, Blocks.COBBLESTONE, 0);
		this.setBlock(world, i + 5, j + 0, k + 1, Blocks.COBBLESTONE, 0);
		this.setBlock(world, i + 5, j + 0, k + 2, Blocks.COBBLESTONE, 0);
		this.setBlock(world, i + 5, j + 0, k + 3, Blocks.COBBLESTONE, 0);
		this.setBlock(world, i + 5, j + 0, k + 4, Blocks.COBBLESTONE, 0);
		this.setBlock(world, i + 5, j + 0, k + 5, Blocks.COBBLESTONE, 0);
		this.setBlock(world, i + 5, j + 0, k + 6, Blocks.COBBLESTONE, 0);
		this.setBlock(world, i + 5, j + 1, k + 0, Blocks.SNOW, 0);
		this.setBlock(world, i + 5, j + 1, k + 1, Blocks.CHEST, 3);
		this.setBlock(world, i + 5, j + 1, k + 2, Blocks.AIR, 0);
		this.setBlock(world, i + 5, j + 1, k + 3, Blocks.AIR, 0);
		this.setBlock(world, i + 5, j + 1, k + 4, Blocks.AIR, 0);
		this.setBlock(world, i + 5, j + 1, k + 5, Blocks.BED, 3);
		this.setBlock(world, i + 5, j + 1, k + 6, Blocks.SNOW, 0);
		this.setBlock(world, i + 5, j + 2, k + 0, Blocks.GLASS_PANE, 0);
		this.setBlock(world, i + 5, j + 2, k + 1, Blocks.AIR, 0);
		this.setBlock(world, i + 5, j + 2, k + 2, Blocks.AIR, 0);
		this.setBlock(world, i + 5, j + 2, k + 3, Blocks.AIR, 0);
		this.setBlock(world, i + 5, j + 2, k + 4, Blocks.AIR, 0);
		this.setBlock(world, i + 5, j + 2, k + 5, Blocks.AIR, 0);
		this.setBlock(world, i + 5, j + 2, k + 6, Blocks.GLASS_PANE, 0);
		this.setBlock(world, i + 5, j + 3, k + 0, Blocks.SNOW, 0);
		this.setBlock(world, i + 5, j + 3, k + 1, Blocks.AIR, 0);
		this.setBlock(world, i + 5, j + 3, k + 2, Blocks.AIR, 0);
		this.setBlock(world, i + 5, j + 3, k + 3, Blocks.AIR, 0);
		this.setBlock(world, i + 5, j + 3, k + 4, Blocks.AIR, 0);
		this.setBlock(world, i + 5, j + 3, k + 5, Blocks.AIR, 0);
		this.setBlock(world, i + 5, j + 3, k + 6, Blocks.SNOW, 0);
		this.setBlock(world, i + 5, j + 4, k + 0, Blocks.ICE, 0);
		this.setBlock(world, i + 5, j + 4, k + 1, Blocks.SNOW, 0);
		this.setBlock(world, i + 5, j + 4, k + 2, Blocks.AIR, 0);
		this.setBlock(world, i + 5, j + 4, k + 3, Blocks.AIR, 0);
		this.setBlock(world, i + 5, j + 4, k + 4, Blocks.AIR, 0);
		this.setBlock(world, i + 5, j + 4, k + 5, Blocks.SNOW, 0);
		this.setBlock(world, i + 5, j + 4, k + 6, Blocks.ICE, 0);
		this.setBlock(world, i + 5, j + 5, k + 0, Blocks.AIR, 0);
		this.setBlock(world, i + 5, j + 5, k + 1, Blocks.AIR, 0);
		this.setBlock(world, i + 5, j + 5, k + 2, Blocks.SNOW, 0);
		this.setBlock(world, i + 5, j + 5, k + 3, Blocks.SNOW, 0);
		this.setBlock(world, i + 5, j + 5, k + 4, Blocks.SNOW, 0);
		this.setBlock(world, i + 5, j + 5, k + 5, Blocks.AIR, 0);
		this.setBlock(world, i + 5, j + 5, k + 6, Blocks.AIR, 0);
		this.setBlock(world, i + 6, j + 0, k + 0, Blocks.COBBLESTONE, 0);
		this.setBlock(world, i + 6, j + 0, k + 1, Blocks.COBBLESTONE, 0);
		this.setBlock(world, i + 6, j + 0, k + 2, Blocks.COBBLESTONE, 0);
		this.setBlock(world, i + 6, j + 0, k + 3, Blocks.COBBLESTONE, 0);
		this.setBlock(world, i + 6, j + 0, k + 4, Blocks.COBBLESTONE, 0);
		this.setBlock(world, i + 6, j + 0, k + 5, Blocks.COBBLESTONE, 0);
		this.setBlock(world, i + 6, j + 0, k + 6, Blocks.COBBLESTONE, 0);
		this.setBlock(world, i + 6, j + 1, k + 0, Blocks.SNOW, 0);
		this.setBlock(world, i + 6, j + 1, k + 1, Blocks.CHEST, 3);
		this.setBlock(world, i + 6, j + 1, k + 2, Blocks.AIR, 0);
		this.setBlock(world, i + 6, j + 1, k + 3, Blocks.AIR, 0);
		this.setBlock(world, i + 6, j + 1, k + 4, Blocks.AIR, 0);
		this.setBlock(world, i + 6, j + 1, k + 5, Blocks.BED, 11);
		this.setBlock(world, i + 6, j + 1, k + 6, Blocks.SNOW, 0);
		this.setBlock(world, i + 6, j + 2, k + 0, Blocks.SNOW, 0);
		this.setBlock(world, i + 6, j + 2, k + 1, Blocks.AIR, 0);
		this.setBlock(world, i + 6, j + 2, k + 2, Blocks.AIR, 0);
		this.setBlock(world, i + 6, j + 2, k + 3, Blocks.AIR, 0);
		this.setBlock(world, i + 6, j + 2, k + 4, Blocks.AIR, 0);
		this.setBlock(world, i + 6, j + 2, k + 5, Blocks.AIR, 0);
		this.setBlock(world, i + 6, j + 2, k + 6, Blocks.SNOW, 0);
		this.setBlock(world, i + 6, j + 3, k + 0, Blocks.SNOW, 0);
		this.setBlock(world, i + 6, j + 3, k + 1, Blocks.AIR, 0);
		this.setBlock(world, i + 6, j + 3, k + 2, Blocks.AIR, 0);
		this.setBlock(world, i + 6, j + 3, k + 3, Blocks.AIR, 0);
		this.setBlock(world, i + 6, j + 3, k + 4, Blocks.AIR, 0);
		this.setBlock(world, i + 6, j + 3, k + 5, Blocks.AIR, 0);
		this.setBlock(world, i + 6, j + 3, k + 6, Blocks.SNOW, 0);
		this.setBlock(world, i + 6, j + 4, k + 0, Blocks.ICE, 0);
		this.setBlock(world, i + 6, j + 4, k + 1, Blocks.SNOW, 0);
		this.setBlock(world, i + 6, j + 4, k + 2, Blocks.SNOW, 0);
		this.setBlock(world, i + 6, j + 4, k + 3, Blocks.SNOW, 0);
		this.setBlock(world, i + 6, j + 4, k + 4, Blocks.SNOW, 0);
		this.setBlock(world, i + 6, j + 4, k + 5, Blocks.SNOW, 0);
		this.setBlock(world, i + 6, j + 4, k + 6, Blocks.ICE, 0);
		this.setBlock(world, i + 6, j + 5, k + 0, Blocks.AIR, 0);
		this.setBlock(world, i + 6, j + 5, k + 1, Blocks.AIR, 0);
		this.setBlock(world, i + 6, j + 5, k + 2, Blocks.AIR, 0);
		this.setBlock(world, i + 6, j + 5, k + 3, Blocks.AIR, 0);
		this.setBlock(world, i + 6, j + 5, k + 4, Blocks.AIR, 0);
		this.setBlock(world, i + 6, j + 5, k + 5, Blocks.AIR, 0);
		this.setBlock(world, i + 6, j + 5, k + 6, Blocks.AIR, 0);
		this.setBlock(world, i + 7, j + 0, k + 0, Blocks.COBBLESTONE, 0);
		this.setBlock(world, i + 7, j + 0, k + 1, Blocks.COBBLESTONE, 0);
		this.setBlock(world, i + 7, j + 0, k + 2, Blocks.COBBLESTONE, 0);
		this.setBlock(world, i + 7, j + 0, k + 3, Blocks.COBBLESTONE, 0);
		this.setBlock(world, i + 7, j + 0, k + 4, Blocks.COBBLESTONE, 0);
		this.setBlock(world, i + 7, j + 0, k + 5, Blocks.COBBLESTONE, 0);
		this.setBlock(world, i + 7, j + 0, k + 6, Blocks.COBBLESTONE, 0);
		this.setBlock(world, i + 7, j + 1, k + 0, Blocks.ICE, 0);
		this.setBlock(world, i + 7, j + 1, k + 1, Blocks.SNOW, 0);
		this.setBlock(world, i + 7, j + 1, k + 2, Blocks.SNOW, 0);
		this.setBlock(world, i + 7, j + 1, k + 3, Blocks.SNOW, 0);
		this.setBlock(world, i + 7, j + 1, k + 4, Blocks.SNOW, 0);
		this.setBlock(world, i + 7, j + 1, k + 5, Blocks.SNOW, 0);
		this.setBlock(world, i + 7, j + 1, k + 6, Blocks.ICE, 0);
		this.setBlock(world, i + 7, j + 2, k + 0, Blocks.ICE, 0);
		this.setBlock(world, i + 7, j + 2, k + 1, Blocks.SNOW, 0);
		this.setBlock(world, i + 7, j + 2, k + 2, Blocks.GLASS_PANE, 0);
		this.setBlock(world, i + 7, j + 2, k + 3, Blocks.GLASS_PANE, 0);
		this.setBlock(world, i + 7, j + 2, k + 4, Blocks.GLASS_PANE, 0);
		this.setBlock(world, i + 7, j + 2, k + 5, Blocks.SNOW, 0);
		this.setBlock(world, i + 7, j + 2, k + 6, Blocks.ICE, 0);
		this.setBlock(world, i + 7, j + 3, k + 0, Blocks.ICE, 0);
		this.setBlock(world, i + 7, j + 3, k + 1, Blocks.SNOW, 0);
		this.setBlock(world, i + 7, j + 3, k + 2, Blocks.SNOW, 0);
		this.setBlock(world, i + 7, j + 3, k + 3, Blocks.SNOW, 0);
		this.setBlock(world, i + 7, j + 3, k + 4, Blocks.SNOW, 0);
		this.setBlock(world, i + 7, j + 3, k + 5, Blocks.SNOW, 0);
		this.setBlock(world, i + 7, j + 3, k + 6, Blocks.ICE, 0);
		this.setBlock(world, i + 7, j + 4, k + 0, Blocks.AIR, 0);
		this.setBlock(world, i + 7, j + 4, k + 1, Blocks.ICE, 0);
		this.setBlock(world, i + 7, j + 4, k + 2, Blocks.ICE, 0);
		this.setBlock(world, i + 7, j + 4, k + 3, Blocks.ICE, 0);
		this.setBlock(world, i + 7, j + 4, k + 4, Blocks.ICE, 0);
		this.setBlock(world, i + 7, j + 4, k + 5, Blocks.ICE, 0);
		this.setBlock(world, i + 7, j + 4, k + 6, Blocks.AIR, 0);
		this.setBlock(world, i + 7, j + 5, k + 0, Blocks.AIR, 0);
		this.setBlock(world, i + 7, j + 5, k + 1, Blocks.AIR, 0);
		this.setBlock(world, i + 7, j + 5, k + 2, Blocks.AIR, 0);
		this.setBlock(world, i + 7, j + 5, k + 3, Blocks.AIR, 0);
		this.setBlock(world, i + 7, j + 5, k + 4, Blocks.AIR, 0);
		this.setBlock(world, i + 7, j + 5, k + 5, Blocks.AIR, 0);
		this.setBlock(world, i + 7, j + 5, k + 6, Blocks.AIR, 0);
/*		world.setBlockMetadataWithNotify(i + 1, j + 1, k + 3, 2, 2);
		world.setBlockMetadataWithNotify(i + 1, j + 2, k + 3, 8, 2);
*/
		return true;
	}
}