package com.zalthrion.zylroth.world.mapstructures;

import java.util.Random;

import net.minecraft.block.Block;
import net.minecraft.init.Blocks;
import net.minecraft.util.math.BlockPos;
import net.minecraft.world.World;
import net.minecraft.world.gen.feature.WorldGenerator;

public class TreasureWell extends WorldGenerator {
	// PRE-COMMENTED OUT public static final WeightedRandomChestContent[] generalLoot = new WeightedRandomChestContent[] {new WeightedRandomChestContent(ModItems.endiriteIngot, 0, 1, 3, 2), new WeightedRandomChestContent(ModItems.tenebraeIngot, 0, 1, 4, 15), new WeightedRandomChestContent(ModTools.repulsorCannon, 0, 1, 1, 4), new WeightedRandomChestContent(Items.diamond, 0, 1, 5, 8), new WeightedRandomChestContent(Items.bread, 0, 1, 8, 45), new WeightedRandomChestContent(Items.blaze_rod, 0, 1, 2, 2), new WeightedRandomChestContent(Items.compass, 0, 1, 1, 5), new WeightedRandomChestContent(Items.redstone, 0, 1, 8, 25), new WeightedRandomChestContent(Items.bone, 0, 1, 7, 50), new WeightedRandomChestContent(Items.blaze_powder, 0, 1, 5, 8), new WeightedRandomChestContent(Items.emerald, 0, 1, 8, 5), new WeightedRandomChestContent(ModItems.celestialCore, 0, 1, 1, 5), new WeightedRandomChestContent(ModItems.autumnTalisman, 0, 1, 1, 1), new WeightedRandomChestContent(ModItems.inferniumIngot, 0, 1, 4, 8), new WeightedRandomChestContent(Items.pumpkin_pie, 0, 1, 5, 15), new WeightedRandomChestContent(Items.iron_ingot, 0, 1, 5, 20), new WeightedRandomChestContent(Items.gold_ingot, 0, 1, 3, 12), new WeightedRandomChestContent(Items.melon_seeds, 0, 2, 4, 10), new WeightedRandomChestContent(Items.pumpkin_seeds, 0, 2, 4, 10), new WeightedRandomChestContent(Items.saddle, 0, 1, 1, 3), new WeightedRandomChestContent(Items.iron_horse_armor, 0, 1, 1, 3)};
	// MAKE THIS A LOOTTABLE public static final WeightedRandomChestContent[] wellLoot = new WeightedRandomChestContent[] {new WeightedRandomChestContent(ModItems.endiriteIngot, 0, 1, 3, 2), new WeightedRandomChestContent(ModItems.tenebraeIngot, 0, 1, 4, 15), new WeightedRandomChestContent(Items.diamond, 0, 1, 5, 8), new WeightedRandomChestContent(Items.bread, 0, 1, 8, 45), new WeightedRandomChestContent(Items.blaze_rod, 0, 1, 2, 2), new WeightedRandomChestContent(Items.compass, 0, 1, 1, 5), new WeightedRandomChestContent(Items.redstone, 0, 1, 8, 25), new WeightedRandomChestContent(Items.bone, 0, 1, 7, 50), new WeightedRandomChestContent(Items.blaze_powder, 0, 1, 5, 8), new WeightedRandomChestContent(Items.emerald, 0, 1, 8, 5), new WeightedRandomChestContent(ModItems.autumnTalisman, 0, 1, 1, 1), new WeightedRandomChestContent(ModItems.inferniumIngot, 0, 1, 4, 8), new WeightedRandomChestContent(Items.pumpkin_pie, 0, 1, 5, 15), new WeightedRandomChestContent(Items.iron_ingot, 0, 1, 5, 20), new WeightedRandomChestContent(Items.gold_ingot, 0, 1, 3, 12), new WeightedRandomChestContent(Items.melon_seeds, 0, 2, 4, 10), new WeightedRandomChestContent(Items.pumpkin_seeds, 0, 2, 4, 10), new WeightedRandomChestContent(Items.saddle, 0, 1, 1, 3), new WeightedRandomChestContent(Items.iron_horse_armor, 0, 1, 1, 3)};
	
	@Override public boolean generate(World world, Random rand, BlockPos pos) {
		this.generate(world, rand, pos.getX(), pos.getY(), pos.getZ());
		return true;
	}
	
	@Deprecated private void setBlock(World world, int i, int j, int k, Block block, int meta) {
		world.setBlockState(new BlockPos(i, j, k), block.getStateFromMeta(meta));
	}
	
	@Deprecated public boolean generate(World world, Random rand, int i, int j, int k) {
		this.setBlock(world, i + 0, j + 0, k + 0, Blocks.AIR, 0);
		this.setBlock(world, i + 0, j + 0, k + 1, Blocks.AIR, 0);
		this.setBlock(world, i + 0, j + 0, k + 2, Blocks.AIR, 0);
		this.setBlock(world, i + 0, j + 0, k + 3, Blocks.AIR, 0);
		this.setBlock(world, i + 0, j + 0, k + 4, Blocks.AIR, 0);
		this.setBlock(world, i + 0, j + 0, k + 5, Blocks.AIR, 0);
		this.setBlock(world, i + 0, j + 0, k + 6, Blocks.AIR, 0);
		this.setBlock(world, i + 0, j + 0, k + 7, Blocks.AIR, 0);
		this.setBlock(world, i + 0, j + 0, k + 8, Blocks.AIR, 0);
		this.setBlock(world, i + 0, j + 1, k + 0, Blocks.AIR, 0);
		this.setBlock(world, i + 0, j + 1, k + 1, Blocks.AIR, 0);
		this.setBlock(world, i + 0, j + 1, k + 2, Blocks.AIR, 0);
		this.setBlock(world, i + 0, j + 1, k + 3, Blocks.AIR, 0);
		this.setBlock(world, i + 0, j + 1, k + 4, Blocks.AIR, 0);
		this.setBlock(world, i + 0, j + 1, k + 5, Blocks.AIR, 0);
		this.setBlock(world, i + 0, j + 1, k + 6, Blocks.AIR, 0);
		this.setBlock(world, i + 0, j + 1, k + 7, Blocks.AIR, 0);
		this.setBlock(world, i + 0, j + 1, k + 8, Blocks.AIR, 0);
		this.setBlock(world, i + 0, j + 2, k + 0, Blocks.AIR, 0);
		this.setBlock(world, i + 0, j + 2, k + 1, Blocks.AIR, 0);
		this.setBlock(world, i + 0, j + 2, k + 2, Blocks.AIR, 0);
		this.setBlock(world, i + 0, j + 2, k + 3, Blocks.AIR, 0);
		this.setBlock(world, i + 0, j + 2, k + 4, Blocks.AIR, 0);
		this.setBlock(world, i + 0, j + 2, k + 5, Blocks.AIR, 0);
		this.setBlock(world, i + 0, j + 2, k + 6, Blocks.AIR, 0);
		this.setBlock(world, i + 0, j + 2, k + 7, Blocks.AIR, 0);
		this.setBlock(world, i + 0, j + 2, k + 8, Blocks.AIR, 0);
		this.setBlock(world, i + 0, j + 3, k + 0, Blocks.AIR, 0);
		this.setBlock(world, i + 0, j + 3, k + 1, Blocks.SAND, 0);
		this.setBlock(world, i + 0, j + 3, k + 2, Blocks.SAND, 0);
		this.setBlock(world, i + 0, j + 3, k + 3, Blocks.SAND, 0);
		this.setBlock(world, i + 0, j + 3, k + 4, Blocks.SAND, 0);
		this.setBlock(world, i + 0, j + 3, k + 5, Blocks.SAND, 0);
		this.setBlock(world, i + 0, j + 3, k + 6, Blocks.SAND, 0);
		this.setBlock(world, i + 0, j + 3, k + 7, Blocks.SAND, 0);
		this.setBlock(world, i + 0, j + 4, k + 1, Blocks.SAND, 0);
		this.setBlock(world, i + 0, j + 4, k + 2, Blocks.SAND, 0);
		this.setBlock(world, i + 0, j + 4, k + 3, Blocks.SAND, 0);
		this.setBlock(world, i + 0, j + 4, k + 4, Blocks.SAND, 0);
		this.setBlock(world, i + 0, j + 4, k + 5, Blocks.SAND, 0);
		this.setBlock(world, i + 0, j + 4, k + 6, Blocks.SAND, 0);
		this.setBlock(world, i + 0, j + 4, k + 7, Blocks.SAND, 0);
		this.setBlock(world, i + 0, j + 3, k + 8, Blocks.AIR, 0);
		this.setBlock(world, i + 0, j + 4, k + 0, Blocks.AIR, 0);
		this.setBlock(world, i + 0, j + 4, k + 1, Blocks.AIR, 0);
		this.setBlock(world, i + 0, j + 4, k + 2, Blocks.AIR, 0);
		this.setBlock(world, i + 0, j + 4, k + 3, Blocks.AIR, 0);
		this.setBlock(world, i + 0, j + 4, k + 4, Blocks.AIR, 0);
		this.setBlock(world, i + 0, j + 4, k + 5, Blocks.AIR, 0);
		this.setBlock(world, i + 0, j + 4, k + 6, Blocks.AIR, 0);
		this.setBlock(world, i + 0, j + 4, k + 7, Blocks.AIR, 0);
		this.setBlock(world, i + 0, j + 4, k + 8, Blocks.AIR, 0);
		this.setBlock(world, i + 0, j + 5, k + 0, Blocks.AIR, 0);
		this.setBlock(world, i + 0, j + 5, k + 1, Blocks.AIR, 0);
		this.setBlock(world, i + 0, j + 5, k + 2, Blocks.AIR, 0);
		this.setBlock(world, i + 0, j + 5, k + 3, Blocks.AIR, 0);
		this.setBlock(world, i + 0, j + 5, k + 4, Blocks.AIR, 0);
		this.setBlock(world, i + 0, j + 5, k + 5, Blocks.AIR, 0);
		this.setBlock(world, i + 0, j + 5, k + 6, Blocks.AIR, 0);
		this.setBlock(world, i + 0, j + 5, k + 7, Blocks.AIR, 0);
		this.setBlock(world, i + 0, j + 5, k + 8, Blocks.AIR, 0);
		this.setBlock(world, i + 0, j + 6, k + 0, Blocks.AIR, 0);
		this.setBlock(world, i + 0, j + 6, k + 1, Blocks.AIR, 0);
		this.setBlock(world, i + 0, j + 6, k + 2, Blocks.AIR, 0);
		this.setBlock(world, i + 0, j + 6, k + 3, Blocks.AIR, 0);
		this.setBlock(world, i + 0, j + 6, k + 4, Blocks.AIR, 0);
		this.setBlock(world, i + 0, j + 6, k + 5, Blocks.AIR, 0);
		this.setBlock(world, i + 0, j + 6, k + 6, Blocks.AIR, 0);
		this.setBlock(world, i + 0, j + 6, k + 7, Blocks.AIR, 0);
		this.setBlock(world, i + 0, j + 6, k + 8, Blocks.AIR, 0);
		this.setBlock(world, i + 0, j + 7, k + 0, Blocks.AIR, 0);
		this.setBlock(world, i + 0, j + 7, k + 1, Blocks.AIR, 0);
		this.setBlock(world, i + 0, j + 7, k + 2, Blocks.AIR, 0);
		this.setBlock(world, i + 0, j + 7, k + 3, Blocks.AIR, 0);
		this.setBlock(world, i + 0, j + 7, k + 4, Blocks.AIR, 0);
		this.setBlock(world, i + 0, j + 7, k + 5, Blocks.AIR, 0);
		this.setBlock(world, i + 0, j + 7, k + 6, Blocks.AIR, 0);
		this.setBlock(world, i + 0, j + 7, k + 7, Blocks.AIR, 0);
		this.setBlock(world, i + 0, j + 7, k + 8, Blocks.AIR, 0);
		this.setBlock(world, i + 0, j + 8, k + 0, Blocks.AIR, 0);
		this.setBlock(world, i + 0, j + 8, k + 1, Blocks.AIR, 0);
		this.setBlock(world, i + 0, j + 8, k + 2, Blocks.AIR, 0);
		this.setBlock(world, i + 0, j + 8, k + 3, Blocks.AIR, 0);
		this.setBlock(world, i + 0, j + 8, k + 4, Blocks.AIR, 0);
		this.setBlock(world, i + 0, j + 8, k + 5, Blocks.AIR, 0);
		this.setBlock(world, i + 0, j + 8, k + 6, Blocks.AIR, 0);
		this.setBlock(world, i + 0, j + 8, k + 7, Blocks.AIR, 0);
		this.setBlock(world, i + 0, j + 8, k + 8, Blocks.AIR, 0);
		this.setBlock(world, i + 0, j + 9, k + 0, Blocks.AIR, 0);
		this.setBlock(world, i + 0, j + 9, k + 1, Blocks.AIR, 0);
		this.setBlock(world, i + 0, j + 9, k + 2, Blocks.AIR, 0);
		this.setBlock(world, i + 0, j + 9, k + 3, Blocks.AIR, 0);
		this.setBlock(world, i + 0, j + 9, k + 4, Blocks.AIR, 0);
		this.setBlock(world, i + 0, j + 9, k + 5, Blocks.AIR, 0);
		this.setBlock(world, i + 0, j + 9, k + 6, Blocks.AIR, 0);
		this.setBlock(world, i + 0, j + 9, k + 7, Blocks.AIR, 0);
		this.setBlock(world, i + 0, j + 9, k + 8, Blocks.AIR, 0);
		this.setBlock(world, i + 1, j + 0, k + 0, Blocks.AIR, 0);
		this.setBlock(world, i + 1, j + 0, k + 1, Blocks.SANDSTONE, 0);
		this.setBlock(world, i + 1, j + 0, k + 2, Blocks.SANDSTONE, 0);
		this.setBlock(world, i + 1, j + 0, k + 3, Blocks.SANDSTONE, 0);
		this.setBlock(world, i + 1, j + 0, k + 4, Blocks.SANDSTONE, 0);
		this.setBlock(world, i + 1, j + 0, k + 5, Blocks.SANDSTONE, 0);
		this.setBlock(world, i + 1, j + 0, k + 6, Blocks.SANDSTONE, 0);
		this.setBlock(world, i + 1, j + 0, k + 7, Blocks.SANDSTONE, 0);
		this.setBlock(world, i + 1, j + 0, k + 8, Blocks.AIR, 0);
		this.setBlock(world, i + 1, j + 1, k + 0, Blocks.AIR, 0);
		this.setBlock(world, i + 1, j + 1, k + 1, Blocks.SANDSTONE, 0);
		this.setBlock(world, i + 1, j + 1, k + 2, Blocks.SANDSTONE, 0);
		this.setBlock(world, i + 1, j + 1, k + 3, Blocks.SANDSTONE, 0);
		this.setBlock(world, i + 1, j + 1, k + 4, Blocks.SANDSTONE, 0);
		this.setBlock(world, i + 1, j + 1, k + 5, Blocks.SANDSTONE, 0);
		this.setBlock(world, i + 1, j + 1, k + 6, Blocks.SANDSTONE, 0);
		this.setBlock(world, i + 1, j + 1, k + 7, Blocks.SANDSTONE, 0);
		this.setBlock(world, i + 1, j + 1, k + 8, Blocks.AIR, 0);
		this.setBlock(world, i + 1, j + 2, k + 0, Blocks.AIR, 0);
		this.setBlock(world, i + 1, j + 2, k + 1, Blocks.SANDSTONE, 0);
		this.setBlock(world, i + 1, j + 2, k + 2, Blocks.SANDSTONE, 0);
		this.setBlock(world, i + 1, j + 2, k + 3, Blocks.SANDSTONE, 0);
		this.setBlock(world, i + 1, j + 2, k + 4, Blocks.SANDSTONE, 0);
		this.setBlock(world, i + 1, j + 2, k + 5, Blocks.SANDSTONE, 0);
		this.setBlock(world, i + 1, j + 2, k + 6, Blocks.SANDSTONE, 0);
		this.setBlock(world, i + 1, j + 2, k + 7, Blocks.SANDSTONE, 0);
		this.setBlock(world, i + 1, j + 2, k + 8, Blocks.AIR, 0);
		this.setBlock(world, i + 1, j + 3, k + 0, Blocks.SAND, 0);
		this.setBlock(world, i + 1, j + 4, k + 0, Blocks.SAND, 0);
		this.setBlock(world, i + 1, j + 3, k + 1, Blocks.SANDSTONE, 0);
		this.setBlock(world, i + 1, j + 3, k + 2, Blocks.SANDSTONE, 0);
		this.setBlock(world, i + 1, j + 3, k + 3, Blocks.SANDSTONE, 0);
		this.setBlock(world, i + 1, j + 3, k + 4, Blocks.SANDSTONE, 0);
		this.setBlock(world, i + 1, j + 3, k + 5, Blocks.SANDSTONE, 0);
		this.setBlock(world, i + 1, j + 3, k + 6, Blocks.SANDSTONE, 0);
		this.setBlock(world, i + 1, j + 3, k + 7, Blocks.SANDSTONE, 0);
		this.setBlock(world, i + 1, j + 3, k + 8, Blocks.SAND, 0);
		this.setBlock(world, i + 1, j + 4, k + 8, Blocks.SAND, 0);
		this.setBlock(world, i + 1, j + 4, k + 0, Blocks.AIR, 0);
		this.setBlock(world, i + 1, j + 4, k + 1, Blocks.SANDSTONE, 0);
		this.setBlock(world, i + 1, j + 4, k + 2, Blocks.AIR, 0);
		this.setBlock(world, i + 1, j + 4, k + 3, Blocks.AIR, 0);
		this.setBlock(world, i + 1, j + 4, k + 4, Blocks.AIR, 0);
		this.setBlock(world, i + 1, j + 4, k + 5, Blocks.AIR, 0);
		this.setBlock(world, i + 1, j + 4, k + 6, Blocks.AIR, 0);
		this.setBlock(world, i + 1, j + 4, k + 7, Blocks.SANDSTONE, 0);
		this.setBlock(world, i + 1, j + 4, k + 8, Blocks.AIR, 0);
		this.setBlock(world, i + 1, j + 5, k + 0, Blocks.AIR, 0);
		this.setBlock(world, i + 1, j + 5, k + 1, Blocks.SANDSTONE, 0);
		this.setBlock(world, i + 1, j + 5, k + 2, Blocks.AIR, 0);
		this.setBlock(world, i + 1, j + 5, k + 3, Blocks.AIR, 0);
		this.setBlock(world, i + 1, j + 5, k + 4, Blocks.AIR, 0);
		this.setBlock(world, i + 1, j + 5, k + 5, Blocks.AIR, 0);
		this.setBlock(world, i + 1, j + 5, k + 6, Blocks.AIR, 0);
		this.setBlock(world, i + 1, j + 5, k + 7, Blocks.SANDSTONE, 0);
		this.setBlock(world, i + 1, j + 5, k + 8, Blocks.AIR, 0);
		this.setBlock(world, i + 1, j + 6, k + 0, Blocks.AIR, 0);
		this.setBlock(world, i + 1, j + 6, k + 1, Blocks.SANDSTONE, 0);
		this.setBlock(world, i + 1, j + 6, k + 2, Blocks.AIR, 0);
		this.setBlock(world, i + 1, j + 6, k + 3, Blocks.AIR, 0);
		this.setBlock(world, i + 1, j + 6, k + 4, Blocks.AIR, 0);
		this.setBlock(world, i + 1, j + 6, k + 5, Blocks.AIR, 0);
		this.setBlock(world, i + 1, j + 6, k + 6, Blocks.AIR, 0);
		this.setBlock(world, i + 1, j + 6, k + 7, Blocks.SANDSTONE, 0);
		this.setBlock(world, i + 1, j + 6, k + 8, Blocks.AIR, 0);
		this.setBlock(world, i + 1, j + 7, k + 0, Blocks.AIR, 0);
		this.setBlock(world, i + 1, j + 7, k + 1, Blocks.STONE_SLAB, 1);
		this.setBlock(world, i + 1, j + 7, k + 2, Blocks.SANDSTONE, 0);
		this.setBlock(world, i + 1, j + 7, k + 3, Blocks.SANDSTONE, 0);
		this.setBlock(world, i + 1, j + 7, k + 4, Blocks.STONE_SLAB, 9);
		this.setBlock(world, i + 1, j + 7, k + 5, Blocks.SANDSTONE, 0);
		this.setBlock(world, i + 1, j + 7, k + 6, Blocks.SANDSTONE, 0);
		this.setBlock(world, i + 1, j + 7, k + 7, Blocks.STONE_SLAB, 1);
		this.setBlock(world, i + 1, j + 7, k + 8, Blocks.AIR, 0);
		this.setBlock(world, i + 1, j + 8, k + 0, Blocks.AIR, 0);
		this.setBlock(world, i + 1, j + 8, k + 1, Blocks.AIR, 0);
		this.setBlock(world, i + 1, j + 8, k + 2, Blocks.AIR, 0);
		this.setBlock(world, i + 1, j + 8, k + 3, Blocks.AIR, 0);
		this.setBlock(world, i + 1, j + 8, k + 4, Blocks.AIR, 0);
		this.setBlock(world, i + 1, j + 8, k + 5, Blocks.AIR, 0);
		this.setBlock(world, i + 1, j + 8, k + 6, Blocks.AIR, 0);
		this.setBlock(world, i + 1, j + 8, k + 7, Blocks.AIR, 0);
		this.setBlock(world, i + 1, j + 8, k + 8, Blocks.AIR, 0);
		this.setBlock(world, i + 1, j + 9, k + 0, Blocks.AIR, 0);
		this.setBlock(world, i + 1, j + 9, k + 1, Blocks.AIR, 0);
		this.setBlock(world, i + 1, j + 9, k + 2, Blocks.AIR, 0);
		this.setBlock(world, i + 1, j + 9, k + 3, Blocks.AIR, 0);
		this.setBlock(world, i + 1, j + 9, k + 4, Blocks.AIR, 0);
		this.setBlock(world, i + 1, j + 9, k + 5, Blocks.AIR, 0);
		this.setBlock(world, i + 1, j + 9, k + 6, Blocks.AIR, 0);
		this.setBlock(world, i + 1, j + 9, k + 7, Blocks.AIR, 0);
		this.setBlock(world, i + 1, j + 9, k + 8, Blocks.AIR, 0);
		this.setBlock(world, i + 2, j + 0, k + 0, Blocks.AIR, 0);
		this.setBlock(world, i + 2, j + 0, k + 1, Blocks.SANDSTONE, 0);
		this.setBlock(world, i + 2, j + 0, k + 2, Blocks.SANDSTONE, 0);
		this.setBlock(world, i + 2, j + 0, k + 3, Blocks.SANDSTONE, 0);
		this.setBlock(world, i + 2, j + 0, k + 4, Blocks.SANDSTONE, 0);
		this.setBlock(world, i + 2, j + 0, k + 5, Blocks.SANDSTONE, 0);
		this.setBlock(world, i + 2, j + 0, k + 6, Blocks.SANDSTONE, 0);
		this.setBlock(world, i + 2, j + 0, k + 7, Blocks.SANDSTONE, 0);
		this.setBlock(world, i + 2, j + 0, k + 8, Blocks.AIR, 0);
		this.setBlock(world, i + 2, j + 1, k + 0, Blocks.AIR, 0);
		this.setBlock(world, i + 2, j + 1, k + 1, Blocks.SANDSTONE, 0);
		this.setBlock(world, i + 2, j + 1, k + 2, Blocks.SANDSTONE, 0);
		this.setBlock(world, i + 2, j + 1, k + 3, Blocks.SANDSTONE, 0);
		this.setBlock(world, i + 2, j + 1, k + 4, Blocks.SANDSTONE, 0);
		this.setBlock(world, i + 2, j + 1, k + 5, Blocks.SANDSTONE, 0);
		this.setBlock(world, i + 2, j + 1, k + 6, Blocks.SANDSTONE, 0);
		this.setBlock(world, i + 2, j + 1, k + 7, Blocks.SANDSTONE, 0);
		this.setBlock(world, i + 2, j + 1, k + 8, Blocks.AIR, 0);
		this.setBlock(world, i + 2, j + 2, k + 0, Blocks.AIR, 0);
		this.setBlock(world, i + 2, j + 2, k + 1, Blocks.SANDSTONE, 0);
		this.setBlock(world, i + 2, j + 2, k + 2, Blocks.SANDSTONE, 0);
		this.setBlock(world, i + 2, j + 2, k + 3, Blocks.SANDSTONE, 0);
		this.setBlock(world, i + 2, j + 2, k + 4, Blocks.SANDSTONE, 0);
		this.setBlock(world, i + 2, j + 2, k + 5, Blocks.SANDSTONE, 0);
		this.setBlock(world, i + 2, j + 2, k + 6, Blocks.SANDSTONE, 0);
		this.setBlock(world, i + 2, j + 2, k + 7, Blocks.SANDSTONE, 0);
		this.setBlock(world, i + 2, j + 2, k + 8, Blocks.AIR, 0);
		this.setBlock(world, i + 2, j + 3, k + 0, Blocks.SAND, 0);
		this.setBlock(world, i + 2, j + 4, k + 0, Blocks.SAND, 0);
		this.setBlock(world, i + 2, j + 3, k + 1, Blocks.SANDSTONE, 0);
		this.setBlock(world, i + 2, j + 3, k + 2, Blocks.SANDSTONE, 0);
		this.setBlock(world, i + 2, j + 3, k + 3, Blocks.SANDSTONE, 0);
		this.setBlock(world, i + 2, j + 3, k + 4, Blocks.SANDSTONE, 0);
		this.setBlock(world, i + 2, j + 3, k + 5, Blocks.SANDSTONE, 0);
		this.setBlock(world, i + 2, j + 3, k + 6, Blocks.SANDSTONE, 0);
		this.setBlock(world, i + 2, j + 3, k + 7, Blocks.SANDSTONE, 0);
		this.setBlock(world, i + 2, j + 3, k + 8, Blocks.SAND, 0);
		this.setBlock(world, i + 2, j + 4, k + 8, Blocks.SAND, 0);
		this.setBlock(world, i + 2, j + 4, k + 0, Blocks.AIR, 0);
		this.setBlock(world, i + 2, j + 4, k + 1, Blocks.AIR, 0);
		this.setBlock(world, i + 2, j + 4, k + 2, Blocks.AIR, 0);
		this.setBlock(world, i + 2, j + 4, k + 3, Blocks.SANDSTONE_STAIRS, 0);
		this.setBlock(world, i + 2, j + 4, k + 4, Blocks.SANDSTONE_STAIRS, 0);
		this.setBlock(world, i + 2, j + 4, k + 5, Blocks.SANDSTONE_STAIRS, 0);
		this.setBlock(world, i + 2, j + 4, k + 6, Blocks.AIR, 0);
		this.setBlock(world, i + 2, j + 4, k + 7, Blocks.AIR, 0);
		this.setBlock(world, i + 2, j + 4, k + 8, Blocks.AIR, 0);
		this.setBlock(world, i + 2, j + 5, k + 0, Blocks.AIR, 0);
		this.setBlock(world, i + 2, j + 5, k + 1, Blocks.AIR, 0);
		this.setBlock(world, i + 2, j + 5, k + 2, Blocks.AIR, 0);
		this.setBlock(world, i + 2, j + 5, k + 3, Blocks.AIR, 0);
		this.setBlock(world, i + 2, j + 5, k + 4, Blocks.AIR, 0);
		this.setBlock(world, i + 2, j + 5, k + 5, Blocks.AIR, 0);
		this.setBlock(world, i + 2, j + 5, k + 6, Blocks.AIR, 0);
		this.setBlock(world, i + 2, j + 5, k + 7, Blocks.AIR, 0);
		this.setBlock(world, i + 2, j + 5, k + 8, Blocks.AIR, 0);
		this.setBlock(world, i + 2, j + 6, k + 0, Blocks.AIR, 0);
		this.setBlock(world, i + 2, j + 6, k + 1, Blocks.STONE_SLAB, 9);
		this.setBlock(world, i + 2, j + 6, k + 2, Blocks.AIR, 0);
		this.setBlock(world, i + 2, j + 6, k + 3, Blocks.AIR, 0);
		this.setBlock(world, i + 2, j + 6, k + 4, Blocks.AIR, 0);
		this.setBlock(world, i + 2, j + 6, k + 5, Blocks.AIR, 0);
		this.setBlock(world, i + 2, j + 6, k + 6, Blocks.AIR, 0);
		this.setBlock(world, i + 2, j + 6, k + 7, Blocks.STONE_SLAB, 9);
		this.setBlock(world, i + 2, j + 6, k + 8, Blocks.AIR, 0);
		this.setBlock(world, i + 2, j + 7, k + 0, Blocks.AIR, 0);
		this.setBlock(world, i + 2, j + 7, k + 1, Blocks.SANDSTONE, 0);
		this.setBlock(world, i + 2, j + 7, k + 2, Blocks.SANDSTONE, 0);
		this.setBlock(world, i + 2, j + 7, k + 3, Blocks.STONE_SLAB, 9);
		this.setBlock(world, i + 2, j + 7, k + 4, Blocks.AIR, 0);
		this.setBlock(world, i + 2, j + 7, k + 5, Blocks.STONE_SLAB, 9);
		this.setBlock(world, i + 2, j + 7, k + 6, Blocks.SANDSTONE, 0);
		this.setBlock(world, i + 2, j + 7, k + 7, Blocks.SANDSTONE, 0);
		this.setBlock(world, i + 2, j + 7, k + 8, Blocks.AIR, 0);
		this.setBlock(world, i + 2, j + 8, k + 0, Blocks.AIR, 0);
		this.setBlock(world, i + 2, j + 8, k + 1, Blocks.AIR, 0);
		this.setBlock(world, i + 2, j + 8, k + 2, Blocks.STONE_SLAB, 1);
		this.setBlock(world, i + 2, j + 8, k + 3, Blocks.SANDSTONE, 0);
		this.setBlock(world, i + 2, j + 8, k + 4, Blocks.SANDSTONE, 0);
		this.setBlock(world, i + 2, j + 8, k + 5, Blocks.SANDSTONE, 0);
		this.setBlock(world, i + 2, j + 8, k + 6, Blocks.STONE_SLAB, 1);
		this.setBlock(world, i + 2, j + 8, k + 7, Blocks.AIR, 0);
		this.setBlock(world, i + 2, j + 8, k + 8, Blocks.AIR, 0);
		this.setBlock(world, i + 2, j + 9, k + 0, Blocks.AIR, 0);
		this.setBlock(world, i + 2, j + 9, k + 1, Blocks.AIR, 0);
		this.setBlock(world, i + 2, j + 9, k + 2, Blocks.AIR, 0);
		this.setBlock(world, i + 2, j + 9, k + 3, Blocks.AIR, 0);
		this.setBlock(world, i + 2, j + 9, k + 4, Blocks.AIR, 0);
		this.setBlock(world, i + 2, j + 9, k + 5, Blocks.AIR, 0);
		this.setBlock(world, i + 2, j + 9, k + 6, Blocks.AIR, 0);
		this.setBlock(world, i + 2, j + 9, k + 7, Blocks.AIR, 0);
		this.setBlock(world, i + 2, j + 9, k + 8, Blocks.AIR, 0);
		this.setBlock(world, i + 3, j + 0, k + 0, Blocks.AIR, 0);
		this.setBlock(world, i + 3, j + 0, k + 1, Blocks.SANDSTONE, 0);
		this.setBlock(world, i + 3, j + 0, k + 2, Blocks.SANDSTONE, 0);
		this.setBlock(world, i + 3, j + 0, k + 3, Blocks.SANDSTONE, 0);
		this.setBlock(world, i + 3, j + 0, k + 4, Blocks.SANDSTONE, 0);
		this.setBlock(world, i + 3, j + 0, k + 5, Blocks.SANDSTONE, 0);
		this.setBlock(world, i + 3, j + 0, k + 6, Blocks.SANDSTONE, 0);
		this.setBlock(world, i + 3, j + 0, k + 7, Blocks.SANDSTONE, 0);
		this.setBlock(world, i + 3, j + 0, k + 8, Blocks.AIR, 0);
		this.setBlock(world, i + 3, j + 1, k + 0, Blocks.AIR, 0);
		this.setBlock(world, i + 3, j + 1, k + 1, Blocks.SANDSTONE, 0);
		this.setBlock(world, i + 3, j + 1, k + 2, Blocks.SANDSTONE, 0);
		this.setBlock(world, i + 3, j + 1, k + 3, Blocks.SANDSTONE, 0);
		this.setBlock(world, i + 3, j + 1, k + 4, Blocks.SANDSTONE, 0);
		this.setBlock(world, i + 3, j + 1, k + 5, Blocks.SANDSTONE, 0);
		this.setBlock(world, i + 3, j + 1, k + 6, Blocks.SANDSTONE, 0);
		this.setBlock(world, i + 3, j + 1, k + 7, Blocks.SANDSTONE, 0);
		this.setBlock(world, i + 3, j + 1, k + 8, Blocks.AIR, 0);
		this.setBlock(world, i + 3, j + 2, k + 0, Blocks.AIR, 0);
		this.setBlock(world, i + 3, j + 2, k + 1, Blocks.SANDSTONE, 0);
		this.setBlock(world, i + 3, j + 2, k + 2, Blocks.SANDSTONE, 0);
		this.setBlock(world, i + 3, j + 2, k + 6, Blocks.SANDSTONE, 0);
		this.setBlock(world, i + 3, j + 2, k + 7, Blocks.SANDSTONE, 0);
		this.setBlock(world, i + 3, j + 2, k + 8, Blocks.AIR, 0);
		this.setBlock(world, i + 3, j + 3, k + 0, Blocks.SAND, 0);
		this.setBlock(world, i + 3, j + 4, k + 0, Blocks.SAND, 0);
		this.setBlock(world, i + 3, j + 3, k + 1, Blocks.SANDSTONE, 0);
		this.setBlock(world, i + 3, j + 3, k + 2, Blocks.SANDSTONE, 0);
		this.setBlock(world, i + 3, j + 3, k + 6, Blocks.SANDSTONE, 0);
		this.setBlock(world, i + 3, j + 3, k + 7, Blocks.SANDSTONE, 0);
		this.setBlock(world, i + 3, j + 3, k + 8, Blocks.SAND, 0);
		this.setBlock(world, i + 3, j + 4, k + 8, Blocks.SAND, 0);
		this.setBlock(world, i + 3, j + 4, k + 0, Blocks.AIR, 0);
		this.setBlock(world, i + 3, j + 4, k + 1, Blocks.AIR, 0);
		this.setBlock(world, i + 3, j + 4, k + 2, Blocks.SANDSTONE_STAIRS, 2);
		this.setBlock(world, i + 3, j + 4, k + 6, Blocks.SANDSTONE_STAIRS, 3);
		this.setBlock(world, i + 3, j + 4, k + 7, Blocks.AIR, 0);
		this.setBlock(world, i + 3, j + 4, k + 8, Blocks.AIR, 0);
		this.setBlock(world, i + 3, j + 5, k + 0, Blocks.AIR, 0);
		this.setBlock(world, i + 3, j + 5, k + 1, Blocks.AIR, 0);
		this.setBlock(world, i + 3, j + 5, k + 2, Blocks.AIR, 0);
		this.setBlock(world, i + 3, j + 5, k + 3, Blocks.AIR, 0);
		this.setBlock(world, i + 3, j + 5, k + 4, Blocks.AIR, 0);
		this.setBlock(world, i + 3, j + 5, k + 5, Blocks.AIR, 0);
		this.setBlock(world, i + 3, j + 5, k + 6, Blocks.AIR, 0);
		this.setBlock(world, i + 3, j + 5, k + 7, Blocks.AIR, 0);
		this.setBlock(world, i + 3, j + 5, k + 8, Blocks.AIR, 0);
		this.setBlock(world, i + 3, j + 6, k + 0, Blocks.AIR, 0);
		this.setBlock(world, i + 3, j + 6, k + 1, Blocks.AIR, 0);
		this.setBlock(world, i + 3, j + 6, k + 2, Blocks.AIR, 0);
		this.setBlock(world, i + 3, j + 6, k + 3, Blocks.AIR, 0);
		this.setBlock(world, i + 3, j + 6, k + 4, Blocks.AIR, 0);
		this.setBlock(world, i + 3, j + 6, k + 5, Blocks.AIR, 0);
		this.setBlock(world, i + 3, j + 6, k + 6, Blocks.AIR, 0);
		this.setBlock(world, i + 3, j + 6, k + 7, Blocks.AIR, 0);
		this.setBlock(world, i + 3, j + 6, k + 8, Blocks.AIR, 0);
		this.setBlock(world, i + 3, j + 7, k + 0, Blocks.AIR, 0);
		this.setBlock(world, i + 3, j + 7, k + 1, Blocks.SANDSTONE, 0);
		this.setBlock(world, i + 3, j + 7, k + 2, Blocks.STONE_SLAB, 9);
		this.setBlock(world, i + 3, j + 7, k + 3, Blocks.AIR, 0);
		this.setBlock(world, i + 3, j + 7, k + 4, Blocks.AIR, 0);
		this.setBlock(world, i + 3, j + 7, k + 5, Blocks.AIR, 0);
		this.setBlock(world, i + 3, j + 7, k + 6, Blocks.STONE_SLAB, 9);
		this.setBlock(world, i + 3, j + 7, k + 7, Blocks.SANDSTONE, 0);
		this.setBlock(world, i + 3, j + 7, k + 8, Blocks.AIR, 0);
		this.setBlock(world, i + 3, j + 8, k + 0, Blocks.AIR, 0);
		this.setBlock(world, i + 3, j + 8, k + 1, Blocks.AIR, 0);
		this.setBlock(world, i + 3, j + 8, k + 2, Blocks.SANDSTONE, 0);
		this.setBlock(world, i + 3, j + 8, k + 3, Blocks.STONE_SLAB, 1);
		this.setBlock(world, i + 3, j + 8, k + 4, Blocks.STONE_SLAB, 9);
		this.setBlock(world, i + 3, j + 8, k + 5, Blocks.STONE_SLAB, 1);
		this.setBlock(world, i + 3, j + 8, k + 6, Blocks.SANDSTONE, 0);
		this.setBlock(world, i + 3, j + 8, k + 7, Blocks.AIR, 0);
		this.setBlock(world, i + 3, j + 8, k + 8, Blocks.AIR, 0);
		this.setBlock(world, i + 3, j + 9, k + 0, Blocks.AIR, 0);
		this.setBlock(world, i + 3, j + 9, k + 1, Blocks.AIR, 0);
		this.setBlock(world, i + 3, j + 9, k + 2, Blocks.AIR, 0);
		this.setBlock(world, i + 3, j + 9, k + 3, Blocks.AIR, 0);
		this.setBlock(world, i + 3, j + 9, k + 4, Blocks.AIR, 0);
		this.setBlock(world, i + 3, j + 9, k + 5, Blocks.AIR, 0);
		this.setBlock(world, i + 3, j + 9, k + 6, Blocks.AIR, 0);
		this.setBlock(world, i + 3, j + 9, k + 7, Blocks.AIR, 0);
		this.setBlock(world, i + 3, j + 9, k + 8, Blocks.AIR, 0);
		this.setBlock(world, i + 4, j + 0, k + 0, Blocks.AIR, 0);
		this.setBlock(world, i + 4, j + 0, k + 1, Blocks.SANDSTONE, 0);
		this.setBlock(world, i + 4, j + 0, k + 2, Blocks.SANDSTONE, 0);
		this.setBlock(world, i + 4, j + 0, k + 3, Blocks.SANDSTONE, 0);
		this.setBlock(world, i + 4, j + 0, k + 4, Blocks.SANDSTONE, 0);
		this.setBlock(world, i + 4, j + 0, k + 5, Blocks.SANDSTONE, 0);
		this.setBlock(world, i + 4, j + 0, k + 6, Blocks.SANDSTONE, 0);
		this.setBlock(world, i + 4, j + 0, k + 7, Blocks.SANDSTONE, 0);
		this.setBlock(world, i + 4, j + 0, k + 8, Blocks.AIR, 0);
		this.setBlock(world, i + 4, j + 1, k + 0, Blocks.AIR, 0);
		this.setBlock(world, i + 4, j + 1, k + 1, Blocks.SANDSTONE, 0);
		this.setBlock(world, i + 4, j + 1, k + 2, Blocks.SANDSTONE, 0);
		this.setBlock(world, i + 4, j + 1, k + 3, Blocks.SANDSTONE, 0);
		this.setBlock(world, i + 4, j + 1, k + 4, Blocks.CHEST, 3);
		
/*		TileEntityChest entityChest = (TileEntityChest) world.getTileEntity(i + 4, j + 1, k + 4);
		
		if (entityChest instanceof IInventory) {
			if (entityChest != null) {
				// TODO THIS WeightedRandomChestContent.generateChestContents(rand, wellLoot, entityChest, 8);
			}
		}*/
		
		this.setBlock(world, i + 4, j + 1, k + 5, Blocks.SANDSTONE, 0);
		this.setBlock(world, i + 4, j + 1, k + 6, Blocks.SANDSTONE, 0);
		this.setBlock(world, i + 4, j + 1, k + 7, Blocks.SANDSTONE, 0);
		this.setBlock(world, i + 4, j + 1, k + 8, Blocks.AIR, 0);
		this.setBlock(world, i + 4, j + 2, k + 0, Blocks.AIR, 0);
		this.setBlock(world, i + 4, j + 2, k + 1, Blocks.SANDSTONE, 0);
		this.setBlock(world, i + 4, j + 2, k + 2, Blocks.SANDSTONE, 0);
		this.setBlock(world, i + 4, j + 2, k + 6, Blocks.SANDSTONE, 0);
		this.setBlock(world, i + 4, j + 2, k + 7, Blocks.SANDSTONE, 0);
		this.setBlock(world, i + 4, j + 2, k + 8, Blocks.AIR, 0);
		this.setBlock(world, i + 4, j + 3, k + 0, Blocks.SAND, 0);
		this.setBlock(world, i + 4, j + 3, k + 1, Blocks.SANDSTONE, 0);
		this.setBlock(world, i + 4, j + 3, k + 2, Blocks.SANDSTONE, 0);
		this.setBlock(world, i + 4, j + 3, k + 6, Blocks.SANDSTONE, 0);
		this.setBlock(world, i + 4, j + 3, k + 7, Blocks.SANDSTONE, 0);
		this.setBlock(world, i + 4, j + 3, k + 8, Blocks.SAND, 0);
		this.setBlock(world, i + 4, j + 4, k + 8, Blocks.SAND, 0);
		this.setBlock(world, i + 4, j + 4, k + 0, Blocks.AIR, 0);
		this.setBlock(world, i + 4, j + 4, k + 1, Blocks.AIR, 0);
		this.setBlock(world, i + 4, j + 4, k + 2, Blocks.SANDSTONE_STAIRS, 2);
		this.setBlock(world, i + 4, j + 4, k + 6, Blocks.SANDSTONE_STAIRS, 3);
		this.setBlock(world, i + 4, j + 4, k + 7, Blocks.AIR, 0);
		this.setBlock(world, i + 4, j + 4, k + 8, Blocks.AIR, 0);
		this.setBlock(world, i + 4, j + 5, k + 0, Blocks.AIR, 0);
		this.setBlock(world, i + 4, j + 5, k + 1, Blocks.AIR, 0);
		this.setBlock(world, i + 4, j + 5, k + 2, Blocks.AIR, 0);
		this.setBlock(world, i + 4, j + 5, k + 3, Blocks.AIR, 0);
		this.setBlock(world, i + 4, j + 5, k + 4, Blocks.AIR, 0);
		this.setBlock(world, i + 4, j + 5, k + 5, Blocks.AIR, 0);
		this.setBlock(world, i + 4, j + 5, k + 6, Blocks.AIR, 0);
		this.setBlock(world, i + 4, j + 5, k + 7, Blocks.AIR, 0);
		this.setBlock(world, i + 4, j + 5, k + 8, Blocks.AIR, 0);
		this.setBlock(world, i + 4, j + 6, k + 0, Blocks.AIR, 0);
		this.setBlock(world, i + 4, j + 6, k + 1, Blocks.AIR, 0);
		this.setBlock(world, i + 4, j + 6, k + 2, Blocks.AIR, 0);
		this.setBlock(world, i + 4, j + 6, k + 3, Blocks.AIR, 0);
		this.setBlock(world, i + 4, j + 6, k + 4, Blocks.AIR, 0);
		this.setBlock(world, i + 4, j + 6, k + 5, Blocks.AIR, 0);
		this.setBlock(world, i + 4, j + 6, k + 6, Blocks.AIR, 0);
		this.setBlock(world, i + 4, j + 6, k + 7, Blocks.AIR, 0);
		this.setBlock(world, i + 4, j + 6, k + 8, Blocks.AIR, 0);
		this.setBlock(world, i + 4, j + 7, k + 0, Blocks.AIR, 0);
		this.setBlock(world, i + 4, j + 7, k + 1, Blocks.STONE_SLAB, 9);
		this.setBlock(world, i + 4, j + 7, k + 2, Blocks.AIR, 0);
		this.setBlock(world, i + 4, j + 7, k + 3, Blocks.AIR, 0);
		this.setBlock(world, i + 4, j + 7, k + 4, Blocks.AIR, 0);
		this.setBlock(world, i + 4, j + 7, k + 5, Blocks.AIR, 0);
		this.setBlock(world, i + 4, j + 7, k + 6, Blocks.AIR, 0);
		this.setBlock(world, i + 4, j + 7, k + 7, Blocks.STONE_SLAB, 9);
		this.setBlock(world, i + 4, j + 7, k + 8, Blocks.AIR, 0);
		this.setBlock(world, i + 4, j + 8, k + 0, Blocks.AIR, 0);
		this.setBlock(world, i + 4, j + 8, k + 1, Blocks.AIR, 0);
		this.setBlock(world, i + 4, j + 8, k + 2, Blocks.SANDSTONE, 0);
		this.setBlock(world, i + 4, j + 8, k + 3, Blocks.STONE_SLAB, 9);
		this.setBlock(world, i + 4, j + 8, k + 4, Blocks.GLOWSTONE, 0);
		this.setBlock(world, i + 4, j + 8, k + 5, Blocks.STONE_SLAB, 9);
		this.setBlock(world, i + 4, j + 8, k + 6, Blocks.SANDSTONE, 0);
		this.setBlock(world, i + 4, j + 8, k + 7, Blocks.AIR, 0);
		this.setBlock(world, i + 4, j + 8, k + 8, Blocks.AIR, 0);
		this.setBlock(world, i + 4, j + 9, k + 0, Blocks.AIR, 0);
		this.setBlock(world, i + 4, j + 9, k + 1, Blocks.AIR, 0);
		this.setBlock(world, i + 4, j + 9, k + 2, Blocks.AIR, 0);
		this.setBlock(world, i + 4, j + 9, k + 3, Blocks.AIR, 0);
		this.setBlock(world, i + 4, j + 9, k + 4, Blocks.AIR, 0);
		this.setBlock(world, i + 4, j + 9, k + 5, Blocks.AIR, 0);
		this.setBlock(world, i + 4, j + 9, k + 6, Blocks.AIR, 0);
		this.setBlock(world, i + 4, j + 9, k + 7, Blocks.AIR, 0);
		this.setBlock(world, i + 4, j + 9, k + 8, Blocks.AIR, 0);
		this.setBlock(world, i + 5, j + 0, k + 0, Blocks.AIR, 0);
		this.setBlock(world, i + 5, j + 0, k + 1, Blocks.SANDSTONE, 0);
		this.setBlock(world, i + 5, j + 0, k + 2, Blocks.SANDSTONE, 0);
		this.setBlock(world, i + 5, j + 0, k + 3, Blocks.SANDSTONE, 0);
		this.setBlock(world, i + 5, j + 0, k + 4, Blocks.SANDSTONE, 0);
		this.setBlock(world, i + 5, j + 0, k + 5, Blocks.SANDSTONE, 0);
		this.setBlock(world, i + 5, j + 0, k + 6, Blocks.SANDSTONE, 0);
		this.setBlock(world, i + 5, j + 0, k + 7, Blocks.SANDSTONE, 0);
		this.setBlock(world, i + 5, j + 0, k + 8, Blocks.AIR, 0);
		this.setBlock(world, i + 5, j + 1, k + 0, Blocks.AIR, 0);
		this.setBlock(world, i + 5, j + 1, k + 1, Blocks.SANDSTONE, 0);
		this.setBlock(world, i + 5, j + 1, k + 2, Blocks.SANDSTONE, 0);
		this.setBlock(world, i + 5, j + 1, k + 3, Blocks.SANDSTONE, 0);
		this.setBlock(world, i + 5, j + 1, k + 4, Blocks.SANDSTONE, 0);
		this.setBlock(world, i + 5, j + 1, k + 5, Blocks.SANDSTONE, 0);
		this.setBlock(world, i + 5, j + 1, k + 6, Blocks.SANDSTONE, 0);
		this.setBlock(world, i + 5, j + 1, k + 7, Blocks.SANDSTONE, 0);
		this.setBlock(world, i + 5, j + 1, k + 8, Blocks.AIR, 0);
		this.setBlock(world, i + 5, j + 2, k + 0, Blocks.AIR, 0);
		this.setBlock(world, i + 5, j + 2, k + 1, Blocks.SANDSTONE, 0);
		this.setBlock(world, i + 5, j + 2, k + 2, Blocks.SANDSTONE, 0);
		this.setBlock(world, i + 5, j + 2, k + 6, Blocks.SANDSTONE, 0);
		this.setBlock(world, i + 5, j + 2, k + 7, Blocks.SANDSTONE, 0);
		this.setBlock(world, i + 5, j + 2, k + 8, Blocks.AIR, 0);
		this.setBlock(world, i + 5, j + 3, k + 0, Blocks.SAND, 0);
		this.setBlock(world, i + 5, j + 4, k + 0, Blocks.SAND, 0);
		this.setBlock(world, i + 5, j + 3, k + 1, Blocks.SANDSTONE, 0);
		this.setBlock(world, i + 5, j + 3, k + 2, Blocks.SANDSTONE, 0);
		this.setBlock(world, i + 5, j + 3, k + 6, Blocks.SANDSTONE, 0);
		this.setBlock(world, i + 5, j + 3, k + 7, Blocks.SANDSTONE, 0);
		this.setBlock(world, i + 5, j + 3, k + 8, Blocks.SAND, 0);
		this.setBlock(world, i + 5, j + 4, k + 8, Blocks.SAND, 0);
		this.setBlock(world, i + 5, j + 4, k + 0, Blocks.AIR, 0);
		this.setBlock(world, i + 5, j + 4, k + 1, Blocks.AIR, 0);
		this.setBlock(world, i + 5, j + 4, k + 2, Blocks.SANDSTONE_STAIRS, 2);
		this.setBlock(world, i + 5, j + 4, k + 6, Blocks.SANDSTONE_STAIRS, 3);
		this.setBlock(world, i + 5, j + 4, k + 7, Blocks.AIR, 0);
		this.setBlock(world, i + 5, j + 4, k + 8, Blocks.AIR, 0);
		this.setBlock(world, i + 5, j + 5, k + 0, Blocks.AIR, 0);
		this.setBlock(world, i + 5, j + 5, k + 1, Blocks.AIR, 0);
		this.setBlock(world, i + 5, j + 5, k + 2, Blocks.AIR, 0);
		this.setBlock(world, i + 5, j + 5, k + 3, Blocks.AIR, 0);
		this.setBlock(world, i + 5, j + 5, k + 4, Blocks.AIR, 0);
		this.setBlock(world, i + 5, j + 5, k + 5, Blocks.AIR, 0);
		this.setBlock(world, i + 5, j + 5, k + 6, Blocks.AIR, 0);
		this.setBlock(world, i + 5, j + 5, k + 7, Blocks.AIR, 0);
		this.setBlock(world, i + 5, j + 5, k + 8, Blocks.AIR, 0);
		this.setBlock(world, i + 5, j + 6, k + 0, Blocks.AIR, 0);
		this.setBlock(world, i + 5, j + 6, k + 1, Blocks.AIR, 0);
		this.setBlock(world, i + 5, j + 6, k + 2, Blocks.AIR, 0);
		this.setBlock(world, i + 5, j + 6, k + 3, Blocks.AIR, 0);
		this.setBlock(world, i + 5, j + 6, k + 4, Blocks.AIR, 0);
		this.setBlock(world, i + 5, j + 6, k + 5, Blocks.AIR, 0);
		this.setBlock(world, i + 5, j + 6, k + 6, Blocks.AIR, 0);
		this.setBlock(world, i + 5, j + 6, k + 7, Blocks.AIR, 0);
		this.setBlock(world, i + 5, j + 6, k + 8, Blocks.AIR, 0);
		this.setBlock(world, i + 5, j + 7, k + 0, Blocks.AIR, 0);
		this.setBlock(world, i + 5, j + 7, k + 1, Blocks.SANDSTONE, 0);
		this.setBlock(world, i + 5, j + 7, k + 2, Blocks.STONE_SLAB, 9);
		this.setBlock(world, i + 5, j + 7, k + 3, Blocks.AIR, 0);
		this.setBlock(world, i + 5, j + 7, k + 4, Blocks.AIR, 0);
		this.setBlock(world, i + 5, j + 7, k + 5, Blocks.AIR, 0);
		this.setBlock(world, i + 5, j + 7, k + 6, Blocks.STONE_SLAB, 9);
		this.setBlock(world, i + 5, j + 7, k + 7, Blocks.SANDSTONE, 0);
		this.setBlock(world, i + 5, j + 7, k + 8, Blocks.AIR, 0);
		this.setBlock(world, i + 5, j + 8, k + 0, Blocks.AIR, 0);
		this.setBlock(world, i + 5, j + 8, k + 1, Blocks.AIR, 0);
		this.setBlock(world, i + 5, j + 8, k + 2, Blocks.SANDSTONE, 0);
		this.setBlock(world, i + 5, j + 8, k + 3, Blocks.STONE_SLAB, 1);
		this.setBlock(world, i + 5, j + 8, k + 4, Blocks.STONE_SLAB, 9);
		this.setBlock(world, i + 5, j + 8, k + 5, Blocks.STONE_SLAB, 1);
		this.setBlock(world, i + 5, j + 8, k + 6, Blocks.SANDSTONE, 0);
		this.setBlock(world, i + 5, j + 8, k + 7, Blocks.AIR, 0);
		this.setBlock(world, i + 5, j + 8, k + 8, Blocks.AIR, 0);
		this.setBlock(world, i + 5, j + 9, k + 0, Blocks.AIR, 0);
		this.setBlock(world, i + 5, j + 9, k + 1, Blocks.AIR, 0);
		this.setBlock(world, i + 5, j + 9, k + 2, Blocks.AIR, 0);
		this.setBlock(world, i + 5, j + 9, k + 3, Blocks.AIR, 0);
		this.setBlock(world, i + 5, j + 9, k + 4, Blocks.AIR, 0);
		this.setBlock(world, i + 5, j + 9, k + 5, Blocks.AIR, 0);
		this.setBlock(world, i + 5, j + 9, k + 6, Blocks.AIR, 0);
		this.setBlock(world, i + 5, j + 9, k + 7, Blocks.AIR, 0);
		this.setBlock(world, i + 5, j + 9, k + 8, Blocks.AIR, 0);
		this.setBlock(world, i + 6, j + 0, k + 0, Blocks.AIR, 0);
		this.setBlock(world, i + 6, j + 0, k + 1, Blocks.SANDSTONE, 0);
		this.setBlock(world, i + 6, j + 0, k + 2, Blocks.SANDSTONE, 0);
		this.setBlock(world, i + 6, j + 0, k + 3, Blocks.SANDSTONE, 0);
		this.setBlock(world, i + 6, j + 0, k + 4, Blocks.SANDSTONE, 0);
		this.setBlock(world, i + 6, j + 0, k + 5, Blocks.SANDSTONE, 0);
		this.setBlock(world, i + 6, j + 0, k + 6, Blocks.SANDSTONE, 0);
		this.setBlock(world, i + 6, j + 0, k + 7, Blocks.SANDSTONE, 0);
		this.setBlock(world, i + 6, j + 0, k + 8, Blocks.AIR, 0);
		this.setBlock(world, i + 6, j + 1, k + 0, Blocks.AIR, 0);
		this.setBlock(world, i + 6, j + 1, k + 1, Blocks.SANDSTONE, 0);
		this.setBlock(world, i + 6, j + 1, k + 2, Blocks.SANDSTONE, 0);
		this.setBlock(world, i + 6, j + 1, k + 3, Blocks.SANDSTONE, 0);
		this.setBlock(world, i + 6, j + 1, k + 4, Blocks.SANDSTONE, 0);
		this.setBlock(world, i + 6, j + 1, k + 5, Blocks.SANDSTONE, 0);
		this.setBlock(world, i + 6, j + 1, k + 6, Blocks.SANDSTONE, 0);
		this.setBlock(world, i + 6, j + 1, k + 7, Blocks.SANDSTONE, 0);
		this.setBlock(world, i + 6, j + 1, k + 8, Blocks.AIR, 0);
		this.setBlock(world, i + 6, j + 2, k + 0, Blocks.AIR, 0);
		this.setBlock(world, i + 6, j + 2, k + 1, Blocks.SANDSTONE, 0);
		this.setBlock(world, i + 6, j + 2, k + 2, Blocks.SANDSTONE, 0);
		this.setBlock(world, i + 6, j + 2, k + 3, Blocks.SANDSTONE, 0);
		this.setBlock(world, i + 6, j + 2, k + 4, Blocks.SANDSTONE, 0);
		this.setBlock(world, i + 6, j + 2, k + 5, Blocks.SANDSTONE, 0);
		this.setBlock(world, i + 6, j + 2, k + 6, Blocks.SANDSTONE, 0);
		this.setBlock(world, i + 6, j + 2, k + 7, Blocks.SANDSTONE, 0);
		this.setBlock(world, i + 6, j + 2, k + 8, Blocks.AIR, 0);
		this.setBlock(world, i + 6, j + 3, k + 0, Blocks.SAND, 0);
		this.setBlock(world, i + 6, j + 4, k + 0, Blocks.SAND, 0);
		this.setBlock(world, i + 6, j + 3, k + 1, Blocks.SANDSTONE, 0);
		this.setBlock(world, i + 6, j + 3, k + 2, Blocks.SANDSTONE, 0);
		this.setBlock(world, i + 6, j + 3, k + 3, Blocks.SANDSTONE, 0);
		this.setBlock(world, i + 6, j + 3, k + 4, Blocks.SANDSTONE, 0);
		this.setBlock(world, i + 6, j + 3, k + 5, Blocks.SANDSTONE, 0);
		this.setBlock(world, i + 6, j + 3, k + 6, Blocks.SANDSTONE, 0);
		this.setBlock(world, i + 6, j + 3, k + 7, Blocks.SANDSTONE, 0);
		this.setBlock(world, i + 6, j + 3, k + 8, Blocks.SAND, 0);
		this.setBlock(world, i + 6, j + 4, k + 8, Blocks.SAND, 0);
		this.setBlock(world, i + 6, j + 4, k + 0, Blocks.AIR, 0);
		this.setBlock(world, i + 6, j + 4, k + 1, Blocks.AIR, 0);
		this.setBlock(world, i + 6, j + 4, k + 2, Blocks.AIR, 0);
		this.setBlock(world, i + 6, j + 4, k + 3, Blocks.SANDSTONE_STAIRS, 1);
		this.setBlock(world, i + 6, j + 4, k + 4, Blocks.SANDSTONE_STAIRS, 1);
		this.setBlock(world, i + 6, j + 4, k + 5, Blocks.SANDSTONE_STAIRS, 1);
		this.setBlock(world, i + 6, j + 4, k + 6, Blocks.AIR, 0);
		this.setBlock(world, i + 6, j + 4, k + 7, Blocks.AIR, 0);
		this.setBlock(world, i + 6, j + 4, k + 8, Blocks.AIR, 0);
		this.setBlock(world, i + 6, j + 5, k + 0, Blocks.AIR, 0);
		this.setBlock(world, i + 6, j + 5, k + 1, Blocks.AIR, 0);
		this.setBlock(world, i + 6, j + 5, k + 2, Blocks.AIR, 0);
		this.setBlock(world, i + 6, j + 5, k + 3, Blocks.AIR, 0);
		this.setBlock(world, i + 6, j + 5, k + 4, Blocks.AIR, 0);
		this.setBlock(world, i + 6, j + 5, k + 5, Blocks.AIR, 0);
		this.setBlock(world, i + 6, j + 5, k + 6, Blocks.AIR, 0);
		this.setBlock(world, i + 6, j + 5, k + 7, Blocks.AIR, 0);
		this.setBlock(world, i + 6, j + 5, k + 8, Blocks.AIR, 0);
		this.setBlock(world, i + 6, j + 6, k + 0, Blocks.AIR, 0);
		this.setBlock(world, i + 6, j + 6, k + 1, Blocks.STONE_SLAB, 9);
		this.setBlock(world, i + 6, j + 6, k + 2, Blocks.AIR, 0);
		this.setBlock(world, i + 6, j + 6, k + 3, Blocks.AIR, 0);
		this.setBlock(world, i + 6, j + 6, k + 4, Blocks.AIR, 0);
		this.setBlock(world, i + 6, j + 6, k + 5, Blocks.AIR, 0);
		this.setBlock(world, i + 6, j + 6, k + 6, Blocks.AIR, 0);
		this.setBlock(world, i + 6, j + 6, k + 7, Blocks.STONE_SLAB, 9);
		this.setBlock(world, i + 6, j + 6, k + 8, Blocks.AIR, 0);
		this.setBlock(world, i + 6, j + 7, k + 0, Blocks.AIR, 0);
		this.setBlock(world, i + 6, j + 7, k + 1, Blocks.SANDSTONE, 0);
		this.setBlock(world, i + 6, j + 7, k + 2, Blocks.SANDSTONE, 0);
		this.setBlock(world, i + 6, j + 7, k + 3, Blocks.STONE_SLAB, 9);
		this.setBlock(world, i + 6, j + 7, k + 4, Blocks.AIR, 0);
		this.setBlock(world, i + 6, j + 7, k + 5, Blocks.STONE_SLAB, 9);
		this.setBlock(world, i + 6, j + 7, k + 6, Blocks.SANDSTONE, 0);
		this.setBlock(world, i + 6, j + 7, k + 7, Blocks.SANDSTONE, 0);
		this.setBlock(world, i + 6, j + 7, k + 8, Blocks.AIR, 0);
		this.setBlock(world, i + 6, j + 8, k + 0, Blocks.AIR, 0);
		this.setBlock(world, i + 6, j + 8, k + 1, Blocks.AIR, 0);
		this.setBlock(world, i + 6, j + 8, k + 2, Blocks.STONE_SLAB, 1);
		this.setBlock(world, i + 6, j + 8, k + 3, Blocks.SANDSTONE, 0);
		this.setBlock(world, i + 6, j + 8, k + 4, Blocks.SANDSTONE, 0);
		this.setBlock(world, i + 6, j + 8, k + 5, Blocks.SANDSTONE, 0);
		this.setBlock(world, i + 6, j + 8, k + 6, Blocks.STONE_SLAB, 1);
		this.setBlock(world, i + 6, j + 8, k + 7, Blocks.AIR, 0);
		this.setBlock(world, i + 6, j + 8, k + 8, Blocks.AIR, 0);
		this.setBlock(world, i + 6, j + 9, k + 0, Blocks.AIR, 0);
		this.setBlock(world, i + 6, j + 9, k + 1, Blocks.AIR, 0);
		this.setBlock(world, i + 6, j + 9, k + 2, Blocks.AIR, 0);
		this.setBlock(world, i + 6, j + 9, k + 3, Blocks.AIR, 0);
		this.setBlock(world, i + 6, j + 9, k + 4, Blocks.AIR, 0);
		this.setBlock(world, i + 6, j + 9, k + 5, Blocks.AIR, 0);
		this.setBlock(world, i + 6, j + 9, k + 6, Blocks.AIR, 0);
		this.setBlock(world, i + 6, j + 9, k + 7, Blocks.AIR, 0);
		this.setBlock(world, i + 6, j + 9, k + 8, Blocks.AIR, 0);
		this.setBlock(world, i + 7, j + 0, k + 0, Blocks.AIR, 0);
		this.setBlock(world, i + 7, j + 0, k + 1, Blocks.SANDSTONE, 0);
		this.setBlock(world, i + 7, j + 0, k + 2, Blocks.SANDSTONE, 0);
		this.setBlock(world, i + 7, j + 0, k + 3, Blocks.SANDSTONE, 0);
		this.setBlock(world, i + 7, j + 0, k + 4, Blocks.SANDSTONE, 0);
		this.setBlock(world, i + 7, j + 0, k + 5, Blocks.SANDSTONE, 0);
		this.setBlock(world, i + 7, j + 0, k + 6, Blocks.SANDSTONE, 0);
		this.setBlock(world, i + 7, j + 0, k + 7, Blocks.SANDSTONE, 0);
		this.setBlock(world, i + 7, j + 0, k + 8, Blocks.AIR, 0);
		this.setBlock(world, i + 7, j + 1, k + 0, Blocks.AIR, 0);
		this.setBlock(world, i + 7, j + 1, k + 1, Blocks.SANDSTONE, 0);
		this.setBlock(world, i + 7, j + 1, k + 2, Blocks.SANDSTONE, 0);
		this.setBlock(world, i + 7, j + 1, k + 3, Blocks.SANDSTONE, 0);
		this.setBlock(world, i + 7, j + 1, k + 4, Blocks.SANDSTONE, 0);
		this.setBlock(world, i + 7, j + 1, k + 5, Blocks.SANDSTONE, 0);
		this.setBlock(world, i + 7, j + 1, k + 6, Blocks.SANDSTONE, 0);
		this.setBlock(world, i + 7, j + 1, k + 7, Blocks.SANDSTONE, 0);
		this.setBlock(world, i + 7, j + 1, k + 8, Blocks.AIR, 0);
		this.setBlock(world, i + 7, j + 2, k + 0, Blocks.AIR, 0);
		this.setBlock(world, i + 7, j + 2, k + 1, Blocks.SANDSTONE, 0);
		this.setBlock(world, i + 7, j + 2, k + 2, Blocks.SANDSTONE, 0);
		this.setBlock(world, i + 7, j + 2, k + 3, Blocks.SANDSTONE, 0);
		this.setBlock(world, i + 7, j + 2, k + 4, Blocks.SANDSTONE, 0);
		this.setBlock(world, i + 7, j + 2, k + 5, Blocks.SANDSTONE, 0);
		this.setBlock(world, i + 7, j + 2, k + 6, Blocks.SANDSTONE, 0);
		this.setBlock(world, i + 7, j + 2, k + 7, Blocks.SANDSTONE, 0);
		this.setBlock(world, i + 7, j + 2, k + 8, Blocks.AIR, 0);
		this.setBlock(world, i + 7, j + 3, k + 0, Blocks.SAND, 0);
		this.setBlock(world, i + 7, j + 4, k + 0, Blocks.SAND, 0);
		this.setBlock(world, i + 7, j + 3, k + 1, Blocks.SANDSTONE, 0);
		this.setBlock(world, i + 7, j + 3, k + 2, Blocks.SANDSTONE, 0);
		this.setBlock(world, i + 7, j + 3, k + 3, Blocks.SANDSTONE, 0);
		this.setBlock(world, i + 7, j + 3, k + 4, Blocks.SANDSTONE, 0);
		this.setBlock(world, i + 7, j + 3, k + 5, Blocks.SANDSTONE, 0);
		this.setBlock(world, i + 7, j + 3, k + 6, Blocks.SANDSTONE, 0);
		this.setBlock(world, i + 7, j + 3, k + 7, Blocks.SANDSTONE, 0);
		this.setBlock(world, i + 7, j + 3, k + 8, Blocks.SAND, 0);
		this.setBlock(world, i + 7, j + 4, k + 8, Blocks.SAND, 0);
		this.setBlock(world, i + 7, j + 4, k + 0, Blocks.AIR, 0);
		this.setBlock(world, i + 7, j + 4, k + 1, Blocks.SANDSTONE, 0);
		this.setBlock(world, i + 7, j + 4, k + 2, Blocks.AIR, 0);
		this.setBlock(world, i + 7, j + 4, k + 3, Blocks.AIR, 0);
		this.setBlock(world, i + 7, j + 4, k + 4, Blocks.AIR, 0);
		this.setBlock(world, i + 7, j + 4, k + 5, Blocks.AIR, 0);
		this.setBlock(world, i + 7, j + 4, k + 6, Blocks.AIR, 0);
		this.setBlock(world, i + 7, j + 4, k + 7, Blocks.SANDSTONE, 0);
		this.setBlock(world, i + 7, j + 4, k + 8, Blocks.AIR, 0);
		this.setBlock(world, i + 7, j + 5, k + 0, Blocks.AIR, 0);
		this.setBlock(world, i + 7, j + 5, k + 1, Blocks.SANDSTONE, 0);
		this.setBlock(world, i + 7, j + 5, k + 2, Blocks.AIR, 0);
		this.setBlock(world, i + 7, j + 5, k + 3, Blocks.AIR, 0);
		this.setBlock(world, i + 7, j + 5, k + 4, Blocks.AIR, 0);
		this.setBlock(world, i + 7, j + 5, k + 5, Blocks.AIR, 0);
		this.setBlock(world, i + 7, j + 5, k + 6, Blocks.AIR, 0);
		this.setBlock(world, i + 7, j + 5, k + 7, Blocks.SANDSTONE, 0);
		this.setBlock(world, i + 7, j + 5, k + 8, Blocks.AIR, 0);
		this.setBlock(world, i + 7, j + 6, k + 0, Blocks.AIR, 0);
		this.setBlock(world, i + 7, j + 6, k + 1, Blocks.SANDSTONE, 0);
		this.setBlock(world, i + 7, j + 6, k + 2, Blocks.STONE_SLAB, 9);
		this.setBlock(world, i + 7, j + 6, k + 3, Blocks.AIR, 0);
		this.setBlock(world, i + 7, j + 6, k + 4, Blocks.AIR, 0);
		this.setBlock(world, i + 7, j + 6, k + 5, Blocks.AIR, 0);
		this.setBlock(world, i + 7, j + 6, k + 6, Blocks.STONE_SLAB, 9);
		this.setBlock(world, i + 7, j + 6, k + 7, Blocks.SANDSTONE, 0);
		this.setBlock(world, i + 7, j + 6, k + 8, Blocks.AIR, 0);
		this.setBlock(world, i + 7, j + 7, k + 0, Blocks.AIR, 0);
		this.setBlock(world, i + 7, j + 7, k + 1, Blocks.STONE_SLAB, 1);
		this.setBlock(world, i + 7, j + 7, k + 2, Blocks.SANDSTONE, 0);
		this.setBlock(world, i + 7, j + 7, k + 3, Blocks.SANDSTONE, 0);
		this.setBlock(world, i + 7, j + 7, k + 4, Blocks.STONE_SLAB, 9);
		this.setBlock(world, i + 7, j + 7, k + 5, Blocks.SANDSTONE, 0);
		this.setBlock(world, i + 7, j + 7, k + 6, Blocks.SANDSTONE, 0);
		this.setBlock(world, i + 7, j + 7, k + 7, Blocks.STONE_SLAB, 1);
		this.setBlock(world, i + 7, j + 7, k + 8, Blocks.AIR, 0);
		this.setBlock(world, i + 7, j + 8, k + 0, Blocks.AIR, 0);
		this.setBlock(world, i + 7, j + 8, k + 1, Blocks.AIR, 0);
		this.setBlock(world, i + 7, j + 8, k + 2, Blocks.AIR, 0);
		this.setBlock(world, i + 7, j + 8, k + 3, Blocks.AIR, 0);
		this.setBlock(world, i + 7, j + 8, k + 4, Blocks.AIR, 0);
		this.setBlock(world, i + 7, j + 8, k + 5, Blocks.AIR, 0);
		this.setBlock(world, i + 7, j + 8, k + 6, Blocks.AIR, 0);
		this.setBlock(world, i + 7, j + 8, k + 7, Blocks.AIR, 0);
		this.setBlock(world, i + 7, j + 8, k + 8, Blocks.AIR, 0);
		this.setBlock(world, i + 7, j + 9, k + 0, Blocks.AIR, 0);
		this.setBlock(world, i + 7, j + 9, k + 1, Blocks.AIR, 0);
		this.setBlock(world, i + 7, j + 9, k + 2, Blocks.AIR, 0);
		this.setBlock(world, i + 7, j + 9, k + 3, Blocks.AIR, 0);
		this.setBlock(world, i + 7, j + 9, k + 4, Blocks.AIR, 0);
		this.setBlock(world, i + 7, j + 9, k + 5, Blocks.AIR, 0);
		this.setBlock(world, i + 7, j + 9, k + 6, Blocks.AIR, 0);
		this.setBlock(world, i + 7, j + 9, k + 7, Blocks.AIR, 0);
		this.setBlock(world, i + 7, j + 9, k + 8, Blocks.AIR, 0);
		this.setBlock(world, i + 8, j + 0, k + 0, Blocks.AIR, 0);
		this.setBlock(world, i + 8, j + 0, k + 1, Blocks.AIR, 0);
		this.setBlock(world, i + 8, j + 0, k + 2, Blocks.AIR, 0);
		this.setBlock(world, i + 8, j + 0, k + 3, Blocks.AIR, 0);
		this.setBlock(world, i + 8, j + 0, k + 4, Blocks.AIR, 0);
		this.setBlock(world, i + 8, j + 0, k + 5, Blocks.AIR, 0);
		this.setBlock(world, i + 8, j + 0, k + 6, Blocks.AIR, 0);
		this.setBlock(world, i + 8, j + 0, k + 7, Blocks.AIR, 0);
		this.setBlock(world, i + 8, j + 0, k + 8, Blocks.AIR, 0);
		this.setBlock(world, i + 8, j + 1, k + 0, Blocks.AIR, 0);
		this.setBlock(world, i + 8, j + 1, k + 1, Blocks.AIR, 0);
		this.setBlock(world, i + 8, j + 1, k + 2, Blocks.AIR, 0);
		this.setBlock(world, i + 8, j + 1, k + 3, Blocks.AIR, 0);
		this.setBlock(world, i + 8, j + 1, k + 4, Blocks.AIR, 0);
		this.setBlock(world, i + 8, j + 1, k + 5, Blocks.AIR, 0);
		this.setBlock(world, i + 8, j + 1, k + 6, Blocks.AIR, 0);
		this.setBlock(world, i + 8, j + 1, k + 7, Blocks.AIR, 0);
		this.setBlock(world, i + 8, j + 1, k + 8, Blocks.AIR, 0);
		this.setBlock(world, i + 8, j + 2, k + 0, Blocks.AIR, 0);
		this.setBlock(world, i + 8, j + 2, k + 1, Blocks.AIR, 0);
		this.setBlock(world, i + 8, j + 2, k + 2, Blocks.AIR, 0);
		this.setBlock(world, i + 8, j + 2, k + 3, Blocks.AIR, 0);
		this.setBlock(world, i + 8, j + 2, k + 4, Blocks.AIR, 0);
		this.setBlock(world, i + 8, j + 2, k + 5, Blocks.AIR, 0);
		this.setBlock(world, i + 8, j + 2, k + 6, Blocks.AIR, 0);
		this.setBlock(world, i + 8, j + 2, k + 7, Blocks.AIR, 0);
		this.setBlock(world, i + 8, j + 2, k + 8, Blocks.AIR, 0);
		this.setBlock(world, i + 8, j + 3, k + 0, Blocks.AIR, 0);
		this.setBlock(world, i + 8, j + 3, k + 1, Blocks.SAND, 0);
		this.setBlock(world, i + 8, j + 3, k + 2, Blocks.SAND, 0);
		this.setBlock(world, i + 8, j + 3, k + 3, Blocks.SAND, 0);
		this.setBlock(world, i + 8, j + 3, k + 4, Blocks.SAND, 0);
		this.setBlock(world, i + 8, j + 3, k + 5, Blocks.SAND, 0);
		this.setBlock(world, i + 8, j + 3, k + 6, Blocks.SAND, 0);
		this.setBlock(world, i + 8, j + 3, k + 7, Blocks.SAND, 0);
		this.setBlock(world, i + 8, j + 4, k + 1, Blocks.SAND, 0);
		this.setBlock(world, i + 8, j + 4, k + 2, Blocks.SAND, 0);
		this.setBlock(world, i + 8, j + 4, k + 3, Blocks.SAND, 0);
		this.setBlock(world, i + 8, j + 4, k + 4, Blocks.SAND, 0);
		this.setBlock(world, i + 8, j + 4, k + 5, Blocks.SAND, 0);
		this.setBlock(world, i + 8, j + 4, k + 6, Blocks.SAND, 0);
		this.setBlock(world, i + 8, j + 4, k + 7, Blocks.SAND, 0);
		this.setBlock(world, i + 8, j + 3, k + 8, Blocks.AIR, 0);
		this.setBlock(world, i + 8, j + 4, k + 0, Blocks.AIR, 0);
		this.setBlock(world, i + 8, j + 4, k + 1, Blocks.AIR, 0);
		this.setBlock(world, i + 8, j + 4, k + 2, Blocks.AIR, 0);
		this.setBlock(world, i + 8, j + 4, k + 3, Blocks.AIR, 0);
		this.setBlock(world, i + 8, j + 4, k + 4, Blocks.AIR, 0);
		this.setBlock(world, i + 8, j + 4, k + 5, Blocks.AIR, 0);
		this.setBlock(world, i + 8, j + 4, k + 6, Blocks.AIR, 0);
		this.setBlock(world, i + 8, j + 4, k + 7, Blocks.AIR, 0);
		this.setBlock(world, i + 8, j + 4, k + 8, Blocks.AIR, 0);
		this.setBlock(world, i + 8, j + 5, k + 0, Blocks.AIR, 0);
		this.setBlock(world, i + 8, j + 5, k + 1, Blocks.AIR, 0);
		this.setBlock(world, i + 8, j + 5, k + 2, Blocks.AIR, 0);
		this.setBlock(world, i + 8, j + 5, k + 3, Blocks.AIR, 0);
		this.setBlock(world, i + 8, j + 5, k + 4, Blocks.AIR, 0);
		this.setBlock(world, i + 8, j + 5, k + 5, Blocks.AIR, 0);
		this.setBlock(world, i + 8, j + 5, k + 6, Blocks.AIR, 0);
		this.setBlock(world, i + 8, j + 5, k + 7, Blocks.AIR, 0);
		this.setBlock(world, i + 8, j + 5, k + 8, Blocks.AIR, 0);
		this.setBlock(world, i + 8, j + 6, k + 0, Blocks.AIR, 0);
		this.setBlock(world, i + 8, j + 6, k + 1, Blocks.AIR, 0);
		this.setBlock(world, i + 8, j + 6, k + 2, Blocks.AIR, 0);
		this.setBlock(world, i + 8, j + 6, k + 3, Blocks.AIR, 0);
		this.setBlock(world, i + 8, j + 6, k + 4, Blocks.AIR, 0);
		this.setBlock(world, i + 8, j + 6, k + 5, Blocks.AIR, 0);
		this.setBlock(world, i + 8, j + 6, k + 6, Blocks.AIR, 0);
		this.setBlock(world, i + 8, j + 6, k + 7, Blocks.AIR, 0);
		this.setBlock(world, i + 8, j + 6, k + 8, Blocks.AIR, 0);
		this.setBlock(world, i + 8, j + 7, k + 0, Blocks.AIR, 0);
		this.setBlock(world, i + 8, j + 7, k + 1, Blocks.AIR, 0);
		this.setBlock(world, i + 8, j + 7, k + 2, Blocks.AIR, 0);
		this.setBlock(world, i + 8, j + 7, k + 3, Blocks.AIR, 0);
		this.setBlock(world, i + 8, j + 7, k + 4, Blocks.AIR, 0);
		this.setBlock(world, i + 8, j + 7, k + 5, Blocks.AIR, 0);
		this.setBlock(world, i + 8, j + 7, k + 6, Blocks.AIR, 0);
		this.setBlock(world, i + 8, j + 7, k + 7, Blocks.AIR, 0);
		this.setBlock(world, i + 8, j + 7, k + 8, Blocks.AIR, 0);
		this.setBlock(world, i + 8, j + 8, k + 0, Blocks.AIR, 0);
		this.setBlock(world, i + 8, j + 8, k + 1, Blocks.AIR, 0);
		this.setBlock(world, i + 8, j + 8, k + 2, Blocks.AIR, 0);
		this.setBlock(world, i + 8, j + 8, k + 3, Blocks.AIR, 0);
		this.setBlock(world, i + 8, j + 8, k + 4, Blocks.AIR, 0);
		this.setBlock(world, i + 8, j + 8, k + 5, Blocks.AIR, 0);
		this.setBlock(world, i + 8, j + 8, k + 6, Blocks.AIR, 0);
		this.setBlock(world, i + 8, j + 8, k + 7, Blocks.AIR, 0);
		this.setBlock(world, i + 8, j + 8, k + 8, Blocks.AIR, 0);
		this.setBlock(world, i + 8, j + 9, k + 0, Blocks.AIR, 0);
		this.setBlock(world, i + 8, j + 9, k + 1, Blocks.AIR, 0);
		this.setBlock(world, i + 8, j + 9, k + 2, Blocks.AIR, 0);
		this.setBlock(world, i + 8, j + 9, k + 3, Blocks.AIR, 0);
		this.setBlock(world, i + 8, j + 9, k + 4, Blocks.AIR, 0);
		this.setBlock(world, i + 8, j + 9, k + 5, Blocks.AIR, 0);
		this.setBlock(world, i + 8, j + 9, k + 6, Blocks.AIR, 0);
		this.setBlock(world, i + 8, j + 9, k + 7, Blocks.AIR, 0);
		this.setBlock(world, i + 8, j + 9, k + 8, Blocks.AIR, 0);
		this.setBlock(world, i + 3, j + 2, k + 3, Blocks.WATER, 0);
		this.setBlock(world, i + 3, j + 2, k + 4, Blocks.WATER, 0);
		this.setBlock(world, i + 3, j + 2, k + 5, Blocks.WATER, 0);
		this.setBlock(world, i + 3, j + 3, k + 3, Blocks.WATER, 0);
		this.setBlock(world, i + 3, j + 3, k + 4, Blocks.WATER, 0);
		this.setBlock(world, i + 3, j + 3, k + 5, Blocks.WATER, 0);
		this.setBlock(world, i + 3, j + 4, k + 3, Blocks.WATER, 0);
		this.setBlock(world, i + 3, j + 4, k + 4, Blocks.WATER, 0);
		this.setBlock(world, i + 3, j + 4, k + 5, Blocks.WATER, 0);
		this.setBlock(world, i + 4, j + 2, k + 3, Blocks.WATER, 0);
		this.setBlock(world, i + 4, j + 2, k + 4, Blocks.WATER, 0);
		this.setBlock(world, i + 4, j + 2, k + 5, Blocks.WATER, 0);
		this.setBlock(world, i + 4, j + 3, k + 3, Blocks.WATER, 0);
		this.setBlock(world, i + 4, j + 3, k + 4, Blocks.WATER, 0);
		this.setBlock(world, i + 4, j + 3, k + 5, Blocks.WATER, 0);
		this.setBlock(world, i + 4, j + 4, k + 3, Blocks.WATER, 0);
		this.setBlock(world, i + 4, j + 4, k + 4, Blocks.WATER, 0);
		this.setBlock(world, i + 4, j + 4, k + 5, Blocks.WATER, 0);
		this.setBlock(world, i + 5, j + 2, k + 3, Blocks.WATER, 0);
		this.setBlock(world, i + 5, j + 2, k + 4, Blocks.WATER, 0);
		this.setBlock(world, i + 5, j + 2, k + 5, Blocks.WATER, 0);
		this.setBlock(world, i + 5, j + 3, k + 3, Blocks.WATER, 0);
		this.setBlock(world, i + 5, j + 3, k + 4, Blocks.WATER, 0);
		this.setBlock(world, i + 5, j + 3, k + 5, Blocks.WATER, 0);
		this.setBlock(world, i + 5, j + 4, k + 3, Blocks.WATER, 0);
		this.setBlock(world, i + 5, j + 4, k + 4, Blocks.WATER, 0);
		this.setBlock(world, i + 5, j + 4, k + 5, Blocks.WATER, 0);
		
		return true;
	}
}