/*
*** MADE BY MRPONYCAPTAIN'S .SCHEMATIC TO .JAVA CONVERTING TOOL v2.0 ***
*/

package com.zalthrion.zylroth.world.gen.structures;

import java.util.Random;

import cpw.mods.fml.common.IWorldGenerator;
import net.minecraft.block.Block;
import net.minecraft.init.Blocks;
import net.minecraft.world.World;
import net.minecraft.world.chunk.IChunkProvider;
import net.minecraft.world.gen.feature.WorldGenerator;

public class BenzennHut extends WorldGenerator implements IWorldGenerator {
	protected Block[] getValidSpawnBlocks() {
		return new Block[] {Blocks.snow};
	}
	
	public boolean locationIsValidSpawn(World world, int i, int j, int k) {
		int distanceToAir = 0;
		Block check = world.getBlock(i, j, k);
		
		while (check != Blocks.air) {
			if (distanceToAir > 0) { return false; }
			
			distanceToAir ++;
			check = world.getBlock(i, j + distanceToAir, k);
		}
		
		j += distanceToAir - 1;
		
		Block block = world.getBlock(i, j, k);
		Block blockAbove = world.getBlock(i, j + 1, k);
		Block blockBelow = world.getBlock(i, j - 1, k);
		
		for (Block x : getValidSpawnBlocks()) {
			if (blockAbove != Blocks.air) { return false; }
			if (block == x) {
				return true;
			} else if (block == Blocks.snow && blockBelow == x) { return true; }
		}
		
		return false;
	}
	
	public BenzennHut() {}
	
	@Override
	public void generate(Random random, int chunkX, int chunkZ, World world, IChunkProvider chunkGenerator, IChunkProvider chunkProvider) {}
	
	public void setBlock(World world, int x, int y, int z, Block block, int metadata) {
		Block b1 = world.getBlock(x, y, z);
		
		if (b1.isAir(world, x, y, z) || b1.isLeaves(world, x, y, z)) {
			world.setBlock(x, y, z, block, metadata, 2);
		}
	}
	
	@Override
	public boolean generate(World world, Random rand, int i, int j, int k) {
		//check that each corner is one of the valid spawn blocks
		if(!locationIsValidSpawn(world, i, j, k) || !locationIsValidSpawn(world, i + 20, j, k) || !locationIsValidSpawn(world, i + 20, j, k + 15) || !locationIsValidSpawn(world, i, j, k + 15))
		{
			return false;
		}

		k = k - 10;
		i = i - 10;

		this.setBlock(world, i + 0, j + 0, k + 5, Blocks.snow, 0);
		this.setBlock(world, i + 0, j + 0, k + 6, Blocks.snow, 0);
		this.setBlock(world, i + 0, j + 0, k + 7, Blocks.snow, 0);
		this.setBlock(world, i + 0, j + 0, k + 8, Blocks.snow, 0);
		this.setBlock(world, i + 0, j + 0, k + 9, Blocks.snow, 0);
		this.setBlock(world, i + 0, j + 0, k + 10, Blocks.snow, 0);
		this.setBlock(world, i + 1, j + 0, k + 4, Blocks.snow, 0);
		this.setBlock(world, i + 1, j + 0, k + 5, Blocks.snow, 0);
		this.setBlock(world, i + 1, j + 0, k + 6, Blocks.snow, 0);
		this.setBlock(world, i + 1, j + 0, k + 7, Blocks.snow, 0);
		this.setBlock(world, i + 1, j + 0, k + 8, Blocks.snow, 0);
		this.setBlock(world, i + 1, j + 0, k + 9, Blocks.snow, 0);
		this.setBlock(world, i + 1, j + 0, k + 10, Blocks.snow, 0);
		this.setBlock(world, i + 1, j + 0, k + 11, Blocks.snow, 0);
		this.setBlock(world, i + 1, j + 1, k + 5, Blocks.snow, 0);
		this.setBlock(world, i + 1, j + 1, k + 6, Blocks.snow, 0);
		this.setBlock(world, i + 1, j + 1, k + 7, Blocks.snow, 0);
		this.setBlock(world, i + 1, j + 1, k + 8, Blocks.snow, 0);
		this.setBlock(world, i + 1, j + 1, k + 9, Blocks.snow, 0);
		this.setBlock(world, i + 1, j + 1, k + 10, Blocks.snow, 0);
		this.setBlock(world, i + 2, j + 0, k + 3, Blocks.snow, 0);
		this.setBlock(world, i + 2, j + 0, k + 4, Blocks.snow, 0);
		this.setBlock(world, i + 2, j + 0, k + 5, Blocks.snow, 0);
		this.setBlock(world, i + 2, j + 0, k + 6, Blocks.snow, 0);
		this.setBlock(world, i + 2, j + 0, k + 7, Blocks.snow, 0);
		this.setBlock(world, i + 2, j + 0, k + 8, Blocks.snow, 0);
		this.setBlock(world, i + 2, j + 0, k + 9, Blocks.snow, 0);
		this.setBlock(world, i + 2, j + 0, k + 10, Blocks.snow, 0);
		this.setBlock(world, i + 2, j + 0, k + 11, Blocks.snow, 0);
		this.setBlock(world, i + 2, j + 0, k + 12, Blocks.snow, 0);
		this.setBlock(world, i + 2, j + 1, k + 4, Blocks.snow, 0);
		this.setBlock(world, i + 2, j + 1, k + 5, Blocks.snow, 0);
		this.setBlock(world, i + 2, j + 1, k + 6, Blocks.snow, 0);
		this.setBlock(world, i + 2, j + 1, k + 7, Blocks.snow, 0);
		this.setBlock(world, i + 2, j + 1, k + 8, Blocks.snow, 0);
		this.setBlock(world, i + 2, j + 1, k + 9, Blocks.snow, 0);
		this.setBlock(world, i + 2, j + 1, k + 10, Blocks.snow, 0);
		this.setBlock(world, i + 2, j + 1, k + 11, Blocks.snow, 0);
		this.setBlock(world, i + 2, j + 2, k + 5, Blocks.snow, 0);
		this.setBlock(world, i + 2, j + 2, k + 6, Blocks.snow, 0);
		this.setBlock(world, i + 2, j + 2, k + 7, Blocks.snow, 0);
		this.setBlock(world, i + 2, j + 2, k + 8, Blocks.snow, 0);
		this.setBlock(world, i + 2, j + 2, k + 9, Blocks.snow, 0);
		this.setBlock(world, i + 2, j + 2, k + 10, Blocks.snow, 0);
		this.setBlock(world, i + 3, j + 0, k + 2, Blocks.snow, 0);
		this.setBlock(world, i + 3, j + 0, k + 3, Blocks.snow, 0);
		this.setBlock(world, i + 3, j + 0, k + 4, Blocks.snow, 0);
		this.setBlock(world, i + 3, j + 0, k + 5, Blocks.snow, 0);
		this.setBlock(world, i + 3, j + 0, k + 6, Blocks.snow, 0);
		this.setBlock(world, i + 3, j + 0, k + 7, Blocks.snow, 0);
		this.setBlock(world, i + 3, j + 0, k + 8, Blocks.snow, 0);
		this.setBlock(world, i + 3, j + 0, k + 9, Blocks.snow, 0);
		this.setBlock(world, i + 3, j + 0, k + 10, Blocks.snow, 0);
		this.setBlock(world, i + 3, j + 0, k + 11, Blocks.snow, 0);
		this.setBlock(world, i + 3, j + 0, k + 12, Blocks.snow, 0);
		this.setBlock(world, i + 3, j + 0, k + 13, Blocks.snow, 0);
		this.setBlock(world, i + 3, j + 1, k + 3, Blocks.snow, 0);
		this.setBlock(world, i + 3, j + 1, k + 4, Blocks.snow, 0);
		this.setBlock(world, i + 3, j + 1, k + 5, Blocks.snow, 0);
		this.setBlock(world, i + 3, j + 1, k + 6, Blocks.snow, 0);
		this.setBlock(world, i + 3, j + 1, k + 7, Blocks.snow, 0);
		this.setBlock(world, i + 3, j + 1, k + 8, Blocks.snow, 0);
		this.setBlock(world, i + 3, j + 1, k + 9, Blocks.snow, 0);
		this.setBlock(world, i + 3, j + 1, k + 10, Blocks.snow, 0);
		this.setBlock(world, i + 3, j + 1, k + 11, Blocks.snow, 0);
		this.setBlock(world, i + 3, j + 1, k + 12, Blocks.snow, 0);
		this.setBlock(world, i + 3, j + 2, k + 4, Blocks.snow, 0);
		this.setBlock(world, i + 3, j + 2, k + 5, Blocks.snow, 0);
		this.setBlock(world, i + 3, j + 2, k + 6, Blocks.snow, 0);
		this.setBlock(world, i + 3, j + 2, k + 7, Blocks.snow, 0);
		this.setBlock(world, i + 3, j + 2, k + 8, Blocks.snow, 0);
		this.setBlock(world, i + 3, j + 2, k + 9, Blocks.snow, 0);
		this.setBlock(world, i + 3, j + 2, k + 10, Blocks.snow, 0);
		this.setBlock(world, i + 3, j + 2, k + 11, Blocks.snow, 0);
		this.setBlock(world, i + 4, j + 0, k + 1, Blocks.snow, 0);
		this.setBlock(world, i + 4, j + 0, k + 2, Blocks.snow, 0);
		this.setBlock(world, i + 4, j + 0, k + 3, Blocks.snow, 0);
		this.setBlock(world, i + 4, j + 0, k + 4, Blocks.snow, 0);
		this.setBlock(world, i + 4, j + 0, k + 5, Blocks.snow, 0);
		this.setBlock(world, i + 4, j + 0, k + 6, Blocks.snow, 0);
		this.setBlock(world, i + 4, j + 0, k + 7, Blocks.snow, 0);
		this.setBlock(world, i + 4, j + 0, k + 8, Blocks.snow, 0);
		this.setBlock(world, i + 4, j + 0, k + 9, Blocks.snow, 0);
		this.setBlock(world, i + 4, j + 0, k + 10, Blocks.snow, 0);
		this.setBlock(world, i + 4, j + 0, k + 11, Blocks.snow, 0);
		this.setBlock(world, i + 4, j + 0, k + 12, Blocks.snow, 0);
		this.setBlock(world, i + 4, j + 0, k + 13, Blocks.snow, 0);
		this.setBlock(world, i + 4, j + 0, k + 14, Blocks.snow, 0);
		this.setBlock(world, i + 4, j + 1, k + 2, Blocks.snow, 0);
		this.setBlock(world, i + 4, j + 1, k + 3, Blocks.snow, 0);
		this.setBlock(world, i + 4, j + 1, k + 4, Blocks.snow, 0);
		this.setBlock(world, i + 4, j + 1, k + 5, Blocks.snow, 0);
		this.setBlock(world, i + 4, j + 1, k + 6, Blocks.snow, 0);
		this.setBlock(world, i + 4, j + 1, k + 7, Blocks.snow, 0);
		this.setBlock(world, i + 4, j + 1, k + 8, Blocks.snow, 0);
		this.setBlock(world, i + 4, j + 1, k + 9, Blocks.snow, 0);
		this.setBlock(world, i + 4, j + 1, k + 10, Blocks.snow, 0);
		this.setBlock(world, i + 4, j + 1, k + 11, Blocks.snow, 0);
		this.setBlock(world, i + 4, j + 1, k + 12, Blocks.snow, 0);
		this.setBlock(world, i + 4, j + 1, k + 13, Blocks.snow, 0);
		this.setBlock(world, i + 4, j + 2, k + 3, Blocks.snow, 0);
		this.setBlock(world, i + 4, j + 2, k + 4, Blocks.snow, 0);
		this.setBlock(world, i + 4, j + 2, k + 5, Blocks.snow, 0);
		this.setBlock(world, i + 4, j + 2, k + 6, Blocks.snow, 0);
		this.setBlock(world, i + 4, j + 2, k + 7, Blocks.snow, 0);
		this.setBlock(world, i + 4, j + 2, k + 8, Blocks.snow, 0);
		this.setBlock(world, i + 4, j + 2, k + 9, Blocks.snow, 0);
		this.setBlock(world, i + 4, j + 2, k + 10, Blocks.snow, 0);
		this.setBlock(world, i + 4, j + 2, k + 11, Blocks.snow, 0);
		this.setBlock(world, i + 4, j + 2, k + 12, Blocks.snow, 0);
		this.setBlock(world, i + 4, j + 3, k + 6, Blocks.stained_hardened_clay, 0);
		this.setBlock(world, i + 4, j + 3, k + 9, Blocks.stained_hardened_clay, 0);
		this.setBlock(world, i + 5, j + 0, k + 0, Blocks.snow, 0);
		this.setBlock(world, i + 5, j + 0, k + 1, Blocks.snow, 0);
		this.setBlock(world, i + 5, j + 0, k + 2, Blocks.snow, 0);
		this.setBlock(world, i + 5, j + 0, k + 3, Blocks.snow, 0);
		this.setBlock(world, i + 5, j + 0, k + 4, Blocks.snow, 0);
		this.setBlock(world, i + 5, j + 0, k + 5, Blocks.snow, 0);
		this.setBlock(world, i + 5, j + 0, k + 6, Blocks.snow, 0);
		this.setBlock(world, i + 5, j + 0, k + 7, Blocks.snow, 0);
		this.setBlock(world, i + 5, j + 0, k + 8, Blocks.snow, 0);
		this.setBlock(world, i + 5, j + 0, k + 9, Blocks.snow, 0);
		this.setBlock(world, i + 5, j + 0, k + 10, Blocks.snow, 0);
		this.setBlock(world, i + 5, j + 0, k + 11, Blocks.snow, 0);
		this.setBlock(world, i + 5, j + 0, k + 12, Blocks.snow, 0);
		this.setBlock(world, i + 5, j + 0, k + 13, Blocks.snow, 0);
		this.setBlock(world, i + 5, j + 0, k + 14, Blocks.snow, 0);
		this.setBlock(world, i + 5, j + 0, k + 15, Blocks.snow, 0);
		this.setBlock(world, i + 5, j + 1, k + 1, Blocks.snow, 0);
		this.setBlock(world, i + 5, j + 1, k + 2, Blocks.snow, 0);
		this.setBlock(world, i + 5, j + 1, k + 3, Blocks.snow, 0);
		this.setBlock(world, i + 5, j + 1, k + 4, Blocks.snow, 0);
		this.setBlock(world, i + 5, j + 1, k + 5, Blocks.snow, 0);
		this.setBlock(world, i + 5, j + 1, k + 6, Blocks.stained_hardened_clay, 0);
		this.setBlock(world, i + 5, j + 1, k + 7, Blocks.stained_hardened_clay, 0);
		this.setBlock(world, i + 5, j + 1, k + 8, Blocks.stained_hardened_clay, 0);
		this.setBlock(world, i + 5, j + 1, k + 9, Blocks.stained_hardened_clay, 0);
		this.setBlock(world, i + 5, j + 1, k + 10, Blocks.snow, 0);
		this.setBlock(world, i + 5, j + 1, k + 11, Blocks.snow, 0);
		this.setBlock(world, i + 5, j + 1, k + 12, Blocks.snow, 0);
		this.setBlock(world, i + 5, j + 1, k + 13, Blocks.snow, 0);
		this.setBlock(world, i + 5, j + 1, k + 14, Blocks.snow, 0);
		this.setBlock(world, i + 5, j + 2, k + 2, Blocks.snow, 0);
		this.setBlock(world, i + 5, j + 2, k + 3, Blocks.snow, 0);
		this.setBlock(world, i + 5, j + 2, k + 4, Blocks.snow, 0);
		this.setBlock(world, i + 5, j + 2, k + 5, Blocks.snow, 0);
		this.setBlock(world, i + 5, j + 2, k + 6, Blocks.stained_hardened_clay, 0);
		this.setBlock(world, i + 5, j + 2, k + 7, Blocks.stained_hardened_clay, 0);
		this.setBlock(world, i + 5, j + 2, k + 8, Blocks.stained_hardened_clay, 0);
		this.setBlock(world, i + 5, j + 2, k + 9, Blocks.stained_hardened_clay, 0);
		this.setBlock(world, i + 5, j + 2, k + 10, Blocks.snow, 0);
		this.setBlock(world, i + 5, j + 2, k + 11, Blocks.snow, 0);
		this.setBlock(world, i + 5, j + 2, k + 12, Blocks.snow, 0);
		this.setBlock(world, i + 5, j + 2, k + 13, Blocks.snow, 0);
		this.setBlock(world, i + 5, j + 3, k + 4, Blocks.hardened_clay, 0);
		this.setBlock(world, i + 5, j + 3, k + 5, Blocks.hardened_clay, 0);
		this.setBlock(world, i + 5, j + 3, k + 6, Blocks.stained_hardened_clay, 0);
		this.setBlock(world, i + 5, j + 3, k + 9, Blocks.stained_hardened_clay, 0);
		this.setBlock(world, i + 5, j + 3, k + 10, Blocks.hardened_clay, 0);
		this.setBlock(world, i + 5, j + 3, k + 11, Blocks.hardened_clay, 0);
		this.setBlock(world, i + 5, j + 4, k + 5, Blocks.stained_hardened_clay, 8);
		this.setBlock(world, i + 5, j + 4, k + 6, Blocks.stained_hardened_clay, 0);
		this.setBlock(world, i + 5, j + 4, k + 9, Blocks.stained_hardened_clay, 0);
		this.setBlock(world, i + 5, j + 4, k + 10, Blocks.stained_hardened_clay, 8);
		this.setBlock(world, i + 5, j + 5, k + 6, Blocks.stained_hardened_clay, 0);
		this.setBlock(world, i + 5, j + 5, k + 9, Blocks.stained_hardened_clay, 0);
		this.setBlock(world, i + 5, j + 6, k + 7, Blocks.stained_hardened_clay, 0);
		this.setBlock(world, i + 5, j + 6, k + 8, Blocks.stained_hardened_clay, 0);
		this.setBlock(world, i + 6, j + 0, k + 0, Blocks.snow, 0);
		this.setBlock(world, i + 6, j + 0, k + 1, Blocks.snow, 0);
		this.setBlock(world, i + 6, j + 0, k + 2, Blocks.snow, 0);
		this.setBlock(world, i + 6, j + 0, k + 3, Blocks.snow, 0);
		this.setBlock(world, i + 6, j + 0, k + 4, Blocks.snow, 0);
		this.setBlock(world, i + 6, j + 0, k + 5, Blocks.snow, 0);
		this.setBlock(world, i + 6, j + 0, k + 6, Blocks.snow, 0);
		this.setBlock(world, i + 6, j + 0, k + 7, Blocks.snow, 0);
		this.setBlock(world, i + 6, j + 0, k + 8, Blocks.snow, 0);
		this.setBlock(world, i + 6, j + 0, k + 9, Blocks.snow, 0);
		this.setBlock(world, i + 6, j + 0, k + 10, Blocks.snow, 0);
		this.setBlock(world, i + 6, j + 0, k + 11, Blocks.snow, 0);
		this.setBlock(world, i + 6, j + 0, k + 12, Blocks.snow, 0);
		this.setBlock(world, i + 6, j + 0, k + 13, Blocks.snow, 0);
		this.setBlock(world, i + 6, j + 0, k + 14, Blocks.snow, 0);
		this.setBlock(world, i + 6, j + 0, k + 15, Blocks.snow, 0);
		this.setBlock(world, i + 6, j + 1, k + 1, Blocks.snow, 0);
		this.setBlock(world, i + 6, j + 1, k + 2, Blocks.snow, 0);
		this.setBlock(world, i + 6, j + 1, k + 3, Blocks.snow, 0);
		this.setBlock(world, i + 6, j + 1, k + 4, Blocks.snow, 0);
		this.setBlock(world, i + 6, j + 1, k + 5, Blocks.stained_hardened_clay, 0);
		this.setBlock(world, i + 6, j + 1, k + 6, Blocks.stained_hardened_clay, 0);
		this.setBlock(world, i + 6, j + 1, k + 7, Blocks.stained_hardened_clay, 0);
		this.setBlock(world, i + 6, j + 1, k + 8, Blocks.stained_hardened_clay, 0);
		this.setBlock(world, i + 6, j + 1, k + 9, Blocks.stained_hardened_clay, 0);
		this.setBlock(world, i + 6, j + 1, k + 10, Blocks.stained_hardened_clay, 0);
		this.setBlock(world, i + 6, j + 1, k + 11, Blocks.snow, 0);
		this.setBlock(world, i + 6, j + 1, k + 12, Blocks.snow, 0);
		this.setBlock(world, i + 6, j + 1, k + 13, Blocks.snow, 0);
		this.setBlock(world, i + 6, j + 1, k + 14, Blocks.snow, 0);
		this.setBlock(world, i + 6, j + 2, k + 2, Blocks.snow, 0);
		this.setBlock(world, i + 6, j + 2, k + 3, Blocks.snow, 0);
		this.setBlock(world, i + 6, j + 2, k + 4, Blocks.snow, 0);
		this.setBlock(world, i + 6, j + 2, k + 5, Blocks.stained_hardened_clay, 0);
		this.setBlock(world, i + 6, j + 2, k + 6, Blocks.stained_hardened_clay, 0);
		this.setBlock(world, i + 6, j + 2, k + 9, Blocks.stained_hardened_clay, 0);
		this.setBlock(world, i + 6, j + 2, k + 10, Blocks.stained_hardened_clay, 0);
		this.setBlock(world, i + 6, j + 2, k + 11, Blocks.snow, 0);
		this.setBlock(world, i + 6, j + 2, k + 12, Blocks.snow, 0);
		this.setBlock(world, i + 6, j + 2, k + 13, Blocks.snow, 0);
		this.setBlock(world, i + 6, j + 3, k + 3, Blocks.hardened_clay, 0);
		this.setBlock(world, i + 6, j + 3, k + 4, Blocks.hardened_clay, 0);
		this.setBlock(world, i + 6, j + 3, k + 5, Blocks.stained_hardened_clay, 0);
		this.setBlock(world, i + 6, j + 3, k + 6, Blocks.stained_hardened_clay, 0);
		this.setBlock(world, i + 6, j + 3, k + 9, Blocks.stained_hardened_clay, 0);
		this.setBlock(world, i + 6, j + 3, k + 10, Blocks.stained_hardened_clay, 0);
		this.setBlock(world, i + 6, j + 3, k + 11, Blocks.hardened_clay, 0);
		this.setBlock(world, i + 6, j + 3, k + 12, Blocks.hardened_clay, 0);
		this.setBlock(world, i + 6, j + 4, k + 4, Blocks.stained_hardened_clay, 8);
		this.setBlock(world, i + 6, j + 4, k + 5, Blocks.stained_hardened_clay, 0);
		this.setBlock(world, i + 6, j + 4, k + 6, Blocks.stained_hardened_clay, 0);
		this.setBlock(world, i + 6, j + 4, k + 9, Blocks.stained_hardened_clay, 0);
		this.setBlock(world, i + 6, j + 4, k + 10, Blocks.stained_hardened_clay, 0);
		this.setBlock(world, i + 6, j + 4, k + 11, Blocks.stained_hardened_clay, 8);
		this.setBlock(world, i + 6, j + 5, k + 5, Blocks.stained_hardened_clay, 8);
		this.setBlock(world, i + 6, j + 5, k + 6, Blocks.stained_hardened_clay, 0);
		this.setBlock(world, i + 6, j + 5, k + 7, Blocks.stained_hardened_clay, 0);
		this.setBlock(world, i + 6, j + 5, k + 8, Blocks.stained_hardened_clay, 0);
		this.setBlock(world, i + 6, j + 5, k + 9, Blocks.stained_hardened_clay, 0);
		this.setBlock(world, i + 6, j + 5, k + 10, Blocks.stained_hardened_clay, 8);
		this.setBlock(world, i + 6, j + 6, k + 5, Blocks.stained_hardened_clay, 8);
		this.setBlock(world, i + 6, j + 6, k + 6, Blocks.stained_hardened_clay, 0);
		this.setBlock(world, i + 6, j + 6, k + 7, Blocks.stained_hardened_clay, 0);
		this.setBlock(world, i + 6, j + 6, k + 8, Blocks.stained_hardened_clay, 0);
		this.setBlock(world, i + 6, j + 6, k + 9, Blocks.stained_hardened_clay, 0);
		this.setBlock(world, i + 6, j + 6, k + 10, Blocks.stained_hardened_clay, 8);
		this.setBlock(world, i + 6, j + 7, k + 6, Blocks.stained_hardened_clay, 15);
		this.setBlock(world, i + 6, j + 7, k + 7, Blocks.stained_hardened_clay, 0);
		this.setBlock(world, i + 6, j + 7, k + 8, Blocks.stained_hardened_clay, 0);
		this.setBlock(world, i + 6, j + 7, k + 9, Blocks.stained_hardened_clay, 15);
		this.setBlock(world, i + 6, j + 8, k + 7, Blocks.stained_hardened_clay, 8);
		this.setBlock(world, i + 6, j + 8, k + 8, Blocks.stained_hardened_clay, 8);
		this.setBlock(world, i + 7, j + 0, k + 0, Blocks.snow, 0);
		this.setBlock(world, i + 7, j + 0, k + 1, Blocks.snow, 0);
		this.setBlock(world, i + 7, j + 0, k + 2, Blocks.snow, 0);
		this.setBlock(world, i + 7, j + 0, k + 3, Blocks.snow, 0);
		this.setBlock(world, i + 7, j + 0, k + 4, Blocks.snow, 0);
		this.setBlock(world, i + 7, j + 0, k + 5, Blocks.snow, 0);
		this.setBlock(world, i + 7, j + 0, k + 6, Blocks.snow, 0);
		this.setBlock(world, i + 7, j + 0, k + 7, Blocks.snow, 0);
		this.setBlock(world, i + 7, j + 0, k + 8, Blocks.snow, 0);
		this.setBlock(world, i + 7, j + 0, k + 9, Blocks.snow, 0);
		this.setBlock(world, i + 7, j + 0, k + 10, Blocks.snow, 0);
		this.setBlock(world, i + 7, j + 0, k + 11, Blocks.snow, 0);
		this.setBlock(world, i + 7, j + 0, k + 12, Blocks.snow, 0);
		this.setBlock(world, i + 7, j + 0, k + 13, Blocks.snow, 0);
		this.setBlock(world, i + 7, j + 0, k + 14, Blocks.snow, 0);
		this.setBlock(world, i + 7, j + 0, k + 15, Blocks.snow, 0);
		this.setBlock(world, i + 7, j + 1, k + 1, Blocks.snow, 0);
		this.setBlock(world, i + 7, j + 1, k + 2, Blocks.snow, 0);
		this.setBlock(world, i + 7, j + 1, k + 3, Blocks.snow, 0);
		this.setBlock(world, i + 7, j + 1, k + 4, Blocks.stained_hardened_clay, 0);
		this.setBlock(world, i + 7, j + 1, k + 5, Blocks.stained_hardened_clay, 0);
		this.setBlock(world, i + 7, j + 1, k + 6, Blocks.stained_hardened_clay, 0);
		this.setBlock(world, i + 7, j + 1, k + 7, Blocks.stained_hardened_clay, 0);
		this.setBlock(world, i + 7, j + 1, k + 8, Blocks.stained_hardened_clay, 0);
		this.setBlock(world, i + 7, j + 1, k + 9, Blocks.stained_hardened_clay, 0);
		this.setBlock(world, i + 7, j + 1, k + 10, Blocks.stained_hardened_clay, 0);
		this.setBlock(world, i + 7, j + 1, k + 11, Blocks.stained_hardened_clay, 0);
		this.setBlock(world, i + 7, j + 1, k + 12, Blocks.snow, 0);
		this.setBlock(world, i + 7, j + 1, k + 13, Blocks.snow, 0);
		this.setBlock(world, i + 7, j + 1, k + 14, Blocks.snow, 0);
		this.setBlock(world, i + 7, j + 2, k + 2, Blocks.snow, 0);
		this.setBlock(world, i + 7, j + 2, k + 3, Blocks.snow, 0);
		this.setBlock(world, i + 7, j + 2, k + 4, Blocks.stained_hardened_clay, 0);
		this.setBlock(world, i + 7, j + 2, k + 5, Blocks.stained_hardened_clay, 0);
		this.setBlock(world, i + 7, j + 2, k + 10, Blocks.stained_hardened_clay, 0);
		this.setBlock(world, i + 7, j + 2, k + 11, Blocks.stained_hardened_clay, 0);
		this.setBlock(world, i + 7, j + 2, k + 12, Blocks.snow, 0);
		this.setBlock(world, i + 7, j + 2, k + 13, Blocks.snow, 0);
		this.setBlock(world, i + 7, j + 3, k + 3, Blocks.hardened_clay, 0);
		this.setBlock(world, i + 7, j + 3, k + 4, Blocks.stained_hardened_clay, 0);
		this.setBlock(world, i + 7, j + 3, k + 5, Blocks.stained_hardened_clay, 0);
		this.setBlock(world, i + 7, j + 3, k + 10, Blocks.stained_hardened_clay, 0);
		this.setBlock(world, i + 7, j + 3, k + 11, Blocks.stained_hardened_clay, 0);
		this.setBlock(world, i + 7, j + 3, k + 12, Blocks.hardened_clay, 0);
		this.setBlock(world, i + 7, j + 4, k + 3, Blocks.stained_hardened_clay, 8);
		this.setBlock(world, i + 7, j + 4, k + 4, Blocks.stained_hardened_clay, 0);
		this.setBlock(world, i + 7, j + 4, k + 5, Blocks.stained_hardened_clay, 0);
		this.setBlock(world, i + 7, j + 4, k + 10, Blocks.stained_hardened_clay, 0);
		this.setBlock(world, i + 7, j + 4, k + 11, Blocks.stained_hardened_clay, 0);
		this.setBlock(world, i + 7, j + 4, k + 12, Blocks.stained_hardened_clay, 8);
		this.setBlock(world, i + 7, j + 5, k + 4, Blocks.stained_hardened_clay, 8);
		this.setBlock(world, i + 7, j + 5, k + 5, Blocks.stained_hardened_clay, 0);
		this.setBlock(world, i + 7, j + 5, k + 6, Blocks.stained_hardened_clay, 0);
		this.setBlock(world, i + 7, j + 5, k + 9, Blocks.stained_hardened_clay, 0);
		this.setBlock(world, i + 7, j + 5, k + 10, Blocks.stained_hardened_clay, 0);
		this.setBlock(world, i + 7, j + 5, k + 11, Blocks.stained_hardened_clay, 8);
		this.setBlock(world, i + 7, j + 6, k + 5, Blocks.stained_hardened_clay, 8);
		this.setBlock(world, i + 7, j + 6, k + 6, Blocks.stained_hardened_clay, 0);
		this.setBlock(world, i + 7, j + 6, k + 7, Blocks.stained_hardened_clay, 0);
		this.setBlock(world, i + 7, j + 6, k + 8, Blocks.stained_hardened_clay, 0);
		this.setBlock(world, i + 7, j + 6, k + 9, Blocks.stained_hardened_clay, 0);
		this.setBlock(world, i + 7, j + 6, k + 10, Blocks.stained_hardened_clay, 8);
		this.setBlock(world, i + 7, j + 7, k + 5, Blocks.stained_hardened_clay, 8);
		this.setBlock(world, i + 7, j + 7, k + 6, Blocks.stained_hardened_clay, 0);
		this.setBlock(world, i + 7, j + 7, k + 7, Blocks.stained_hardened_clay, 0);
		this.setBlock(world, i + 7, j + 7, k + 9, Blocks.stained_hardened_clay, 0);
		this.setBlock(world, i + 7, j + 7, k + 10, Blocks.stained_hardened_clay, 8);
		this.setBlock(world, i + 7, j + 8, k + 6, Blocks.stained_hardened_clay, 8);
		this.setBlock(world, i + 7, j + 8, k + 7, Blocks.stained_hardened_clay, 0);
		this.setBlock(world, i + 7, j + 8, k + 8, Blocks.stained_hardened_clay, 0);
		this.setBlock(world, i + 7, j + 8, k + 9, Blocks.stained_hardened_clay, 8);
		this.setBlock(world, i + 7, j + 9, k + 7, Blocks.stained_hardened_clay, 8);
		this.setBlock(world, i + 7, j + 9, k + 8, Blocks.stained_hardened_clay, 8);
		this.setBlock(world, i + 8, j + 0, k + 0, Blocks.snow, 0);
		this.setBlock(world, i + 8, j + 0, k + 1, Blocks.snow, 0);
		this.setBlock(world, i + 8, j + 0, k + 2, Blocks.snow, 0);
		this.setBlock(world, i + 8, j + 0, k + 3, Blocks.snow, 0);
		this.setBlock(world, i + 8, j + 0, k + 4, Blocks.snow, 0);
		this.setBlock(world, i + 8, j + 0, k + 5, Blocks.snow, 0);
		this.setBlock(world, i + 8, j + 0, k + 6, Blocks.snow, 0);
		this.setBlock(world, i + 8, j + 0, k + 7, Blocks.snow, 0);
		this.setBlock(world, i + 8, j + 0, k + 8, Blocks.snow, 0);
		this.setBlock(world, i + 8, j + 0, k + 9, Blocks.snow, 0);
		this.setBlock(world, i + 8, j + 0, k + 10, Blocks.snow, 0);
		this.setBlock(world, i + 8, j + 0, k + 11, Blocks.snow, 0);
		this.setBlock(world, i + 8, j + 0, k + 12, Blocks.snow, 0);
		this.setBlock(world, i + 8, j + 0, k + 13, Blocks.snow, 0);
		this.setBlock(world, i + 8, j + 0, k + 14, Blocks.snow, 0);
		this.setBlock(world, i + 8, j + 0, k + 15, Blocks.snow, 0);
		this.setBlock(world, i + 8, j + 1, k + 1, Blocks.snow, 0);
		this.setBlock(world, i + 8, j + 1, k + 2, Blocks.snow, 0);
		this.setBlock(world, i + 8, j + 1, k + 3, Blocks.snow, 0);
		this.setBlock(world, i + 8, j + 1, k + 4, Blocks.stained_hardened_clay, 0);
		this.setBlock(world, i + 8, j + 1, k + 5, Blocks.stained_hardened_clay, 0);
		this.setBlock(world, i + 8, j + 1, k + 6, Blocks.stained_hardened_clay, 0);
		this.setBlock(world, i + 8, j + 1, k + 7, Blocks.stained_hardened_clay, 0);
		this.setBlock(world, i + 8, j + 1, k + 8, Blocks.stained_hardened_clay, 0);
		this.setBlock(world, i + 8, j + 1, k + 9, Blocks.stained_hardened_clay, 0);
		this.setBlock(world, i + 8, j + 1, k + 10, Blocks.stained_hardened_clay, 0);
		this.setBlock(world, i + 8, j + 1, k + 11, Blocks.stained_hardened_clay, 0);
		this.setBlock(world, i + 8, j + 1, k + 12, Blocks.snow, 0);
		this.setBlock(world, i + 8, j + 1, k + 13, Blocks.snow, 0);
		this.setBlock(world, i + 8, j + 1, k + 14, Blocks.snow, 0);
		this.setBlock(world, i + 8, j + 2, k + 2, Blocks.snow, 0);
		this.setBlock(world, i + 8, j + 2, k + 3, Blocks.snow, 0);
		this.setBlock(world, i + 8, j + 2, k + 4, Blocks.stained_hardened_clay, 0);
		this.setBlock(world, i + 8, j + 2, k + 11, Blocks.stained_hardened_clay, 0);
		this.setBlock(world, i + 8, j + 2, k + 12, Blocks.snow, 0);
		this.setBlock(world, i + 8, j + 2, k + 13, Blocks.snow, 0);
		this.setBlock(world, i + 8, j + 3, k + 3, Blocks.hardened_clay, 0);
		this.setBlock(world, i + 8, j + 3, k + 4, Blocks.stained_hardened_clay, 0);
		this.setBlock(world, i + 8, j + 3, k + 11, Blocks.stained_hardened_clay, 0);
		this.setBlock(world, i + 8, j + 3, k + 12, Blocks.hardened_clay, 0);
		this.setBlock(world, i + 8, j + 4, k + 3, Blocks.stained_hardened_clay, 8);
		this.setBlock(world, i + 8, j + 4, k + 4, Blocks.stained_hardened_clay, 0);
		this.setBlock(world, i + 8, j + 4, k + 11, Blocks.stained_hardened_clay, 0);
		this.setBlock(world, i + 8, j + 4, k + 12, Blocks.stained_hardened_clay, 8);
		this.setBlock(world, i + 8, j + 5, k + 4, Blocks.stained_hardened_clay, 8);
		this.setBlock(world, i + 8, j + 5, k + 5, Blocks.stained_hardened_clay, 0);
		this.setBlock(world, i + 8, j + 5, k + 10, Blocks.stained_hardened_clay, 0);
		this.setBlock(world, i + 8, j + 5, k + 11, Blocks.stained_hardened_clay, 8);
		this.setBlock(world, i + 8, j + 6, k + 4, Blocks.stained_hardened_clay, 8);
		this.setBlock(world, i + 8, j + 6, k + 5, Blocks.stained_hardened_clay, 0);
		this.setBlock(world, i + 8, j + 6, k + 6, Blocks.stained_hardened_clay, 0);
		this.setBlock(world, i + 8, j + 6, k + 9, Blocks.stained_hardened_clay, 0);
		this.setBlock(world, i + 8, j + 6, k + 10, Blocks.stained_hardened_clay, 0);
		this.setBlock(world, i + 8, j + 6, k + 11, Blocks.stained_hardened_clay, 8);
		this.setBlock(world, i + 8, j + 7, k + 5, Blocks.stained_hardened_clay, 8);
		this.setBlock(world, i + 8, j + 7, k + 6, Blocks.stained_hardened_clay, 0);
		this.setBlock(world, i + 8, j + 7, k + 7, Blocks.stained_hardened_clay, 0);
		this.setBlock(world, i + 8, j + 7, k + 8, Blocks.stained_hardened_clay, 0);
		this.setBlock(world, i + 8, j + 7, k + 9, Blocks.stained_hardened_clay, 0);
		this.setBlock(world, i + 8, j + 7, k + 10, Blocks.stained_hardened_clay, 8);
		this.setBlock(world, i + 8, j + 8, k + 5, Blocks.stained_hardened_clay, 8);
		this.setBlock(world, i + 8, j + 8, k + 6, Blocks.stained_hardened_clay, 0);
		this.setBlock(world, i + 8, j + 8, k + 7, Blocks.netherrack, 0);
		this.setBlock(world, i + 8, j + 8, k + 8, Blocks.netherrack, 0);
		this.setBlock(world, i + 8, j + 8, k + 9, Blocks.stained_hardened_clay, 0);
		this.setBlock(world, i + 8, j + 8, k + 10, Blocks.stained_hardened_clay, 8);
		this.setBlock(world, i + 8, j + 9, k + 6, Blocks.stained_hardened_clay, 8);
		this.setBlock(world, i + 8, j + 9, k + 7, Blocks.fire, 15);
		this.setBlock(world, i + 8, j + 9, k + 8, Blocks.fire, 15);
		this.setBlock(world, i + 8, j + 9, k + 9, Blocks.stained_hardened_clay, 8);
		this.setBlock(world, i + 9, j + 0, k + 0, Blocks.snow, 0);
		this.setBlock(world, i + 9, j + 0, k + 1, Blocks.snow, 0);
		this.setBlock(world, i + 9, j + 0, k + 2, Blocks.snow, 0);
		this.setBlock(world, i + 9, j + 0, k + 3, Blocks.snow, 0);
		this.setBlock(world, i + 9, j + 0, k + 4, Blocks.snow, 0);
		this.setBlock(world, i + 9, j + 0, k + 5, Blocks.snow, 0);
		this.setBlock(world, i + 9, j + 0, k + 6, Blocks.snow, 0);
		this.setBlock(world, i + 9, j + 0, k + 7, Blocks.snow, 0);
		this.setBlock(world, i + 9, j + 0, k + 8, Blocks.snow, 0);
		this.setBlock(world, i + 9, j + 0, k + 9, Blocks.snow, 0);
		this.setBlock(world, i + 9, j + 0, k + 10, Blocks.snow, 0);
		this.setBlock(world, i + 9, j + 0, k + 11, Blocks.snow, 0);
		this.setBlock(world, i + 9, j + 0, k + 12, Blocks.snow, 0);
		this.setBlock(world, i + 9, j + 0, k + 13, Blocks.snow, 0);
		this.setBlock(world, i + 9, j + 0, k + 14, Blocks.snow, 0);
		this.setBlock(world, i + 9, j + 0, k + 15, Blocks.snow, 0);
		this.setBlock(world, i + 9, j + 1, k + 1, Blocks.snow, 0);
		this.setBlock(world, i + 9, j + 1, k + 2, Blocks.snow, 0);
		this.setBlock(world, i + 9, j + 1, k + 3, Blocks.snow, 0);
		this.setBlock(world, i + 9, j + 1, k + 4, Blocks.stained_hardened_clay, 0);
		this.setBlock(world, i + 9, j + 1, k + 5, Blocks.stained_hardened_clay, 0);
		this.setBlock(world, i + 9, j + 1, k + 6, Blocks.stained_hardened_clay, 0);
		this.setBlock(world, i + 9, j + 1, k + 7, Blocks.stained_hardened_clay, 0);
		this.setBlock(world, i + 9, j + 1, k + 8, Blocks.stained_hardened_clay, 0);
		this.setBlock(world, i + 9, j + 1, k + 9, Blocks.stained_hardened_clay, 0);
		this.setBlock(world, i + 9, j + 1, k + 10, Blocks.stained_hardened_clay, 0);
		this.setBlock(world, i + 9, j + 1, k + 11, Blocks.stained_hardened_clay, 0);
		this.setBlock(world, i + 9, j + 1, k + 12, Blocks.snow, 0);
		this.setBlock(world, i + 9, j + 1, k + 13, Blocks.snow, 0);
		this.setBlock(world, i + 9, j + 1, k + 14, Blocks.snow, 0);
		this.setBlock(world, i + 9, j + 2, k + 2, Blocks.snow, 0);
		this.setBlock(world, i + 9, j + 2, k + 3, Blocks.snow, 0);
		this.setBlock(world, i + 9, j + 2, k + 4, Blocks.stained_hardened_clay, 0);
		this.setBlock(world, i + 9, j + 2, k + 11, Blocks.stained_hardened_clay, 0);
		this.setBlock(world, i + 9, j + 2, k + 12, Blocks.snow, 0);
		this.setBlock(world, i + 9, j + 2, k + 13, Blocks.snow, 0);
		this.setBlock(world, i + 9, j + 3, k + 3, Blocks.hardened_clay, 0);
		this.setBlock(world, i + 9, j + 3, k + 4, Blocks.stained_hardened_clay, 0);
		this.setBlock(world, i + 9, j + 3, k + 11, Blocks.stained_hardened_clay, 0);
		this.setBlock(world, i + 9, j + 3, k + 12, Blocks.hardened_clay, 0);
		this.setBlock(world, i + 9, j + 4, k + 3, Blocks.stained_hardened_clay, 8);
		this.setBlock(world, i + 9, j + 4, k + 4, Blocks.stained_hardened_clay, 0);
		this.setBlock(world, i + 9, j + 4, k + 11, Blocks.stained_hardened_clay, 0);
		this.setBlock(world, i + 9, j + 4, k + 12, Blocks.stained_hardened_clay, 8);
		this.setBlock(world, i + 9, j + 5, k + 4, Blocks.stained_hardened_clay, 8);
		this.setBlock(world, i + 9, j + 5, k + 5, Blocks.stained_hardened_clay, 0);
		this.setBlock(world, i + 9, j + 5, k + 10, Blocks.stained_hardened_clay, 0);
		this.setBlock(world, i + 9, j + 5, k + 11, Blocks.stained_hardened_clay, 8);
		this.setBlock(world, i + 9, j + 6, k + 4, Blocks.stained_hardened_clay, 8);
		this.setBlock(world, i + 9, j + 6, k + 5, Blocks.stained_hardened_clay, 0);
		this.setBlock(world, i + 9, j + 6, k + 6, Blocks.stained_hardened_clay, 0);
		this.setBlock(world, i + 9, j + 6, k + 9, Blocks.stained_hardened_clay, 0);
		this.setBlock(world, i + 9, j + 6, k + 10, Blocks.stained_hardened_clay, 0);
		this.setBlock(world, i + 9, j + 6, k + 11, Blocks.stained_hardened_clay, 8);
		this.setBlock(world, i + 9, j + 7, k + 5, Blocks.stained_hardened_clay, 8);
		this.setBlock(world, i + 9, j + 7, k + 6, Blocks.stained_hardened_clay, 0);
		this.setBlock(world, i + 9, j + 7, k + 7, Blocks.stained_hardened_clay, 0);
		this.setBlock(world, i + 9, j + 7, k + 8, Blocks.stained_hardened_clay, 0);
		this.setBlock(world, i + 9, j + 7, k + 9, Blocks.stained_hardened_clay, 0);
		this.setBlock(world, i + 9, j + 7, k + 10, Blocks.stained_hardened_clay, 8);
		this.setBlock(world, i + 9, j + 8, k + 5, Blocks.stained_hardened_clay, 8);
		this.setBlock(world, i + 9, j + 8, k + 6, Blocks.stained_hardened_clay, 0);
		this.setBlock(world, i + 9, j + 8, k + 7, Blocks.netherrack, 0);
		this.setBlock(world, i + 9, j + 8, k + 8, Blocks.netherrack, 0);
		this.setBlock(world, i + 9, j + 8, k + 9, Blocks.stained_hardened_clay, 0);
		this.setBlock(world, i + 9, j + 8, k + 10, Blocks.stained_hardened_clay, 8);
		this.setBlock(world, i + 9, j + 9, k + 6, Blocks.stained_hardened_clay, 8);
		this.setBlock(world, i + 9, j + 9, k + 7, Blocks.fire, 15);
		this.setBlock(world, i + 9, j + 9, k + 8, Blocks.fire, 15);
		this.setBlock(world, i + 9, j + 9, k + 9, Blocks.stained_hardened_clay, 8);
		this.setBlock(world, i + 10, j + 0, k + 0, Blocks.snow, 0);
		this.setBlock(world, i + 10, j + 0, k + 1, Blocks.snow, 0);
		this.setBlock(world, i + 10, j + 0, k + 2, Blocks.snow, 0);
		this.setBlock(world, i + 10, j + 0, k + 3, Blocks.snow, 0);
		this.setBlock(world, i + 10, j + 0, k + 4, Blocks.snow, 0);
		this.setBlock(world, i + 10, j + 0, k + 5, Blocks.snow, 0);
		this.setBlock(world, i + 10, j + 0, k + 6, Blocks.snow, 0);
		this.setBlock(world, i + 10, j + 0, k + 7, Blocks.snow, 0);
		this.setBlock(world, i + 10, j + 0, k + 8, Blocks.snow, 0);
		this.setBlock(world, i + 10, j + 0, k + 9, Blocks.snow, 0);
		this.setBlock(world, i + 10, j + 0, k + 10, Blocks.snow, 0);
		this.setBlock(world, i + 10, j + 0, k + 11, Blocks.snow, 0);
		this.setBlock(world, i + 10, j + 0, k + 12, Blocks.snow, 0);
		this.setBlock(world, i + 10, j + 0, k + 13, Blocks.snow, 0);
		this.setBlock(world, i + 10, j + 0, k + 14, Blocks.snow, 0);
		this.setBlock(world, i + 10, j + 0, k + 15, Blocks.snow, 0);
		this.setBlock(world, i + 10, j + 1, k + 1, Blocks.snow, 0);
		this.setBlock(world, i + 10, j + 1, k + 2, Blocks.snow, 0);
		this.setBlock(world, i + 10, j + 1, k + 3, Blocks.snow, 0);
		this.setBlock(world, i + 10, j + 1, k + 4, Blocks.stained_hardened_clay, 0);
		this.setBlock(world, i + 10, j + 1, k + 5, Blocks.stained_hardened_clay, 0);
		this.setBlock(world, i + 10, j + 1, k + 6, Blocks.stained_hardened_clay, 0);
		this.setBlock(world, i + 10, j + 1, k + 7, Blocks.stained_hardened_clay, 0);
		this.setBlock(world, i + 10, j + 1, k + 8, Blocks.stained_hardened_clay, 0);
		this.setBlock(world, i + 10, j + 1, k + 9, Blocks.stained_hardened_clay, 0);
		this.setBlock(world, i + 10, j + 1, k + 10, Blocks.stained_hardened_clay, 0);
		this.setBlock(world, i + 10, j + 1, k + 11, Blocks.stained_hardened_clay, 0);
		this.setBlock(world, i + 10, j + 1, k + 12, Blocks.snow, 0);
		this.setBlock(world, i + 10, j + 1, k + 13, Blocks.snow, 0);
		this.setBlock(world, i + 10, j + 1, k + 14, Blocks.snow, 0);
		this.setBlock(world, i + 10, j + 2, k + 2, Blocks.snow, 0);
		this.setBlock(world, i + 10, j + 2, k + 3, Blocks.snow, 0);
		this.setBlock(world, i + 10, j + 2, k + 4, Blocks.stained_hardened_clay, 0);
		this.setBlock(world, i + 10, j + 2, k + 11, Blocks.stained_hardened_clay, 0);
		this.setBlock(world, i + 10, j + 2, k + 12, Blocks.snow, 0);
		this.setBlock(world, i + 10, j + 2, k + 13, Blocks.snow, 0);
		this.setBlock(world, i + 10, j + 3, k + 3, Blocks.hardened_clay, 0);
		this.setBlock(world, i + 10, j + 3, k + 4, Blocks.obsidian, 0);
		this.setBlock(world, i + 10, j + 3, k + 11, Blocks.obsidian, 0);
		this.setBlock(world, i + 10, j + 3, k + 12, Blocks.hardened_clay, 0);
		this.setBlock(world, i + 10, j + 4, k + 3, Blocks.stained_hardened_clay, 8);
		this.setBlock(world, i + 10, j + 4, k + 4, Blocks.stained_hardened_clay, 0);
		this.setBlock(world, i + 10, j + 4, k + 11, Blocks.stained_hardened_clay, 0);
		this.setBlock(world, i + 10, j + 4, k + 12, Blocks.stained_hardened_clay, 8);
		this.setBlock(world, i + 10, j + 5, k + 4, Blocks.stained_hardened_clay, 8);
		this.setBlock(world, i + 10, j + 5, k + 5, Blocks.stained_hardened_clay, 0);
		this.setBlock(world, i + 10, j + 5, k + 10, Blocks.stained_hardened_clay, 0);
		this.setBlock(world, i + 10, j + 5, k + 11, Blocks.stained_hardened_clay, 8);
		this.setBlock(world, i + 10, j + 6, k + 4, Blocks.stained_hardened_clay, 8);
		this.setBlock(world, i + 10, j + 6, k + 5, Blocks.stained_hardened_clay, 0);
		this.setBlock(world, i + 10, j + 6, k + 6, Blocks.stained_hardened_clay, 0);
		this.setBlock(world, i + 10, j + 6, k + 9, Blocks.stained_hardened_clay, 0);
		this.setBlock(world, i + 10, j + 6, k + 10, Blocks.stained_hardened_clay, 0);
		this.setBlock(world, i + 10, j + 6, k + 11, Blocks.stained_hardened_clay, 8);
		this.setBlock(world, i + 10, j + 7, k + 5, Blocks.stained_hardened_clay, 8);
		this.setBlock(world, i + 10, j + 7, k + 6, Blocks.stained_hardened_clay, 0);
		this.setBlock(world, i + 10, j + 7, k + 7, Blocks.stained_hardened_clay, 0);
		this.setBlock(world, i + 10, j + 7, k + 8, Blocks.stained_hardened_clay, 0);
		this.setBlock(world, i + 10, j + 7, k + 9, Blocks.stained_hardened_clay, 0);
		this.setBlock(world, i + 10, j + 7, k + 10, Blocks.stained_hardened_clay, 8);
		this.setBlock(world, i + 10, j + 8, k + 5, Blocks.stained_hardened_clay, 8);
		this.setBlock(world, i + 10, j + 8, k + 6, Blocks.stained_hardened_clay, 0);
		this.setBlock(world, i + 10, j + 8, k + 7, Blocks.netherrack, 0);
		this.setBlock(world, i + 10, j + 8, k + 8, Blocks.netherrack, 0);
		this.setBlock(world, i + 10, j + 8, k + 9, Blocks.stained_hardened_clay, 0);
		this.setBlock(world, i + 10, j + 8, k + 10, Blocks.stained_hardened_clay, 8);
		this.setBlock(world, i + 10, j + 9, k + 6, Blocks.stained_hardened_clay, 8);
		this.setBlock(world, i + 10, j + 9, k + 7, Blocks.fire, 15);
		this.setBlock(world, i + 10, j + 9, k + 8, Blocks.fire, 15);
		this.setBlock(world, i + 10, j + 9, k + 9, Blocks.stained_hardened_clay, 8);
		this.setBlock(world, i + 11, j + 0, k + 0, Blocks.snow, 0);
		this.setBlock(world, i + 11, j + 0, k + 1, Blocks.snow, 0);
		this.setBlock(world, i + 11, j + 0, k + 2, Blocks.snow, 0);
		this.setBlock(world, i + 11, j + 0, k + 3, Blocks.snow, 0);
		this.setBlock(world, i + 11, j + 0, k + 4, Blocks.snow, 0);
		this.setBlock(world, i + 11, j + 0, k + 5, Blocks.snow, 0);
		this.setBlock(world, i + 11, j + 0, k + 6, Blocks.snow, 0);
		this.setBlock(world, i + 11, j + 0, k + 7, Blocks.snow, 0);
		this.setBlock(world, i + 11, j + 0, k + 8, Blocks.snow, 0);
		this.setBlock(world, i + 11, j + 0, k + 9, Blocks.snow, 0);
		this.setBlock(world, i + 11, j + 0, k + 10, Blocks.snow, 0);
		this.setBlock(world, i + 11, j + 0, k + 11, Blocks.snow, 0);
		this.setBlock(world, i + 11, j + 0, k + 12, Blocks.snow, 0);
		this.setBlock(world, i + 11, j + 0, k + 13, Blocks.snow, 0);
		this.setBlock(world, i + 11, j + 0, k + 14, Blocks.snow, 0);
		this.setBlock(world, i + 11, j + 0, k + 15, Blocks.snow, 0);
		this.setBlock(world, i + 11, j + 1, k + 1, Blocks.snow, 0);
		this.setBlock(world, i + 11, j + 1, k + 2, Blocks.snow, 0);
		this.setBlock(world, i + 11, j + 1, k + 3, Blocks.snow, 0);
		this.setBlock(world, i + 11, j + 1, k + 4, Blocks.stained_hardened_clay, 0);
		this.setBlock(world, i + 11, j + 1, k + 5, Blocks.stained_hardened_clay, 0);
		this.setBlock(world, i + 11, j + 1, k + 6, Blocks.stained_hardened_clay, 0);
		this.setBlock(world, i + 11, j + 1, k + 7, Blocks.stained_hardened_clay, 0);
		this.setBlock(world, i + 11, j + 1, k + 8, Blocks.stained_hardened_clay, 0);
		this.setBlock(world, i + 11, j + 1, k + 9, Blocks.stained_hardened_clay, 0);
		this.setBlock(world, i + 11, j + 1, k + 10, Blocks.stained_hardened_clay, 0);
		this.setBlock(world, i + 11, j + 1, k + 11, Blocks.stained_hardened_clay, 0);
		this.setBlock(world, i + 11, j + 1, k + 12, Blocks.snow, 0);
		this.setBlock(world, i + 11, j + 1, k + 13, Blocks.snow, 0);
		this.setBlock(world, i + 11, j + 1, k + 14, Blocks.snow, 0);
		this.setBlock(world, i + 11, j + 2, k + 2, Blocks.snow, 0);
		this.setBlock(world, i + 11, j + 2, k + 3, Blocks.snow, 0);
		this.setBlock(world, i + 11, j + 2, k + 4, Blocks.stained_hardened_clay, 0);
		this.setBlock(world, i + 11, j + 2, k + 11, Blocks.stained_hardened_clay, 0);
		this.setBlock(world, i + 11, j + 2, k + 12, Blocks.snow, 0);
		this.setBlock(world, i + 11, j + 2, k + 13, Blocks.snow, 0);
		this.setBlock(world, i + 11, j + 3, k + 3, Blocks.hardened_clay, 0);
		this.setBlock(world, i + 11, j + 3, k + 4, Blocks.stained_hardened_clay, 0);
		this.setBlock(world, i + 11, j + 3, k + 11, Blocks.stained_hardened_clay, 0);
		this.setBlock(world, i + 11, j + 3, k + 12, Blocks.hardened_clay, 0);
		this.setBlock(world, i + 11, j + 4, k + 3, Blocks.stained_hardened_clay, 8);
		this.setBlock(world, i + 11, j + 4, k + 4, Blocks.stained_hardened_clay, 0);
		this.setBlock(world, i + 11, j + 4, k + 11, Blocks.stained_hardened_clay, 0);
		this.setBlock(world, i + 11, j + 4, k + 12, Blocks.stained_hardened_clay, 8);
		this.setBlock(world, i + 11, j + 5, k + 4, Blocks.stained_hardened_clay, 8);
		this.setBlock(world, i + 11, j + 5, k + 5, Blocks.stained_hardened_clay, 0);
		this.setBlock(world, i + 11, j + 5, k + 10, Blocks.stained_hardened_clay, 0);
		this.setBlock(world, i + 11, j + 5, k + 11, Blocks.stained_hardened_clay, 8);
		this.setBlock(world, i + 11, j + 6, k + 4, Blocks.stained_hardened_clay, 8);
		this.setBlock(world, i + 11, j + 6, k + 5, Blocks.stained_hardened_clay, 0);
		this.setBlock(world, i + 11, j + 6, k + 6, Blocks.stained_hardened_clay, 0);
		this.setBlock(world, i + 11, j + 6, k + 9, Blocks.stained_hardened_clay, 0);
		this.setBlock(world, i + 11, j + 6, k + 10, Blocks.stained_hardened_clay, 0);
		this.setBlock(world, i + 11, j + 6, k + 11, Blocks.stained_hardened_clay, 8);
		this.setBlock(world, i + 11, j + 7, k + 5, Blocks.stained_hardened_clay, 8);
		this.setBlock(world, i + 11, j + 7, k + 6, Blocks.stained_hardened_clay, 0);
		this.setBlock(world, i + 11, j + 7, k + 7, Blocks.stained_hardened_clay, 0);
		this.setBlock(world, i + 11, j + 7, k + 8, Blocks.stained_hardened_clay, 0);
		this.setBlock(world, i + 11, j + 7, k + 9, Blocks.stained_hardened_clay, 0);
		this.setBlock(world, i + 11, j + 7, k + 10, Blocks.stained_hardened_clay, 8);
		this.setBlock(world, i + 11, j + 8, k + 5, Blocks.stained_hardened_clay, 8);
		this.setBlock(world, i + 11, j + 8, k + 6, Blocks.stained_hardened_clay, 0);
		this.setBlock(world, i + 11, j + 8, k + 7, Blocks.netherrack, 0);
		this.setBlock(world, i + 11, j + 8, k + 8, Blocks.netherrack, 0);
		this.setBlock(world, i + 11, j + 8, k + 9, Blocks.stained_hardened_clay, 0);
		this.setBlock(world, i + 11, j + 8, k + 10, Blocks.stained_hardened_clay, 8);
		this.setBlock(world, i + 11, j + 9, k + 6, Blocks.stained_hardened_clay, 8);
		this.setBlock(world, i + 11, j + 9, k + 7, Blocks.fire, 15);
		this.setBlock(world, i + 11, j + 9, k + 8, Blocks.fire, 15);
		this.setBlock(world, i + 11, j + 9, k + 9, Blocks.stained_hardened_clay, 8);
		this.setBlock(world, i + 12, j + 0, k + 0, Blocks.snow, 0);
		this.setBlock(world, i + 12, j + 0, k + 1, Blocks.snow, 0);
		this.setBlock(world, i + 12, j + 0, k + 2, Blocks.snow, 0);
		this.setBlock(world, i + 12, j + 0, k + 3, Blocks.snow, 0);
		this.setBlock(world, i + 12, j + 0, k + 4, Blocks.snow, 0);
		this.setBlock(world, i + 12, j + 0, k + 5, Blocks.snow, 0);
		this.setBlock(world, i + 12, j + 0, k + 6, Blocks.snow, 0);
		this.setBlock(world, i + 12, j + 0, k + 7, Blocks.snow, 0);
		this.setBlock(world, i + 12, j + 0, k + 8, Blocks.snow, 0);
		this.setBlock(world, i + 12, j + 0, k + 9, Blocks.snow, 0);
		this.setBlock(world, i + 12, j + 0, k + 10, Blocks.snow, 0);
		this.setBlock(world, i + 12, j + 0, k + 11, Blocks.snow, 0);
		this.setBlock(world, i + 12, j + 0, k + 12, Blocks.snow, 0);
		this.setBlock(world, i + 12, j + 0, k + 13, Blocks.snow, 0);
		this.setBlock(world, i + 12, j + 0, k + 14, Blocks.snow, 0);
		this.setBlock(world, i + 12, j + 0, k + 15, Blocks.snow, 0);
		this.setBlock(world, i + 12, j + 1, k + 1, Blocks.snow, 0);
		this.setBlock(world, i + 12, j + 1, k + 2, Blocks.snow, 0);
		this.setBlock(world, i + 12, j + 1, k + 3, Blocks.snow, 0);
		this.setBlock(world, i + 12, j + 1, k + 4, Blocks.stained_hardened_clay, 0);
		this.setBlock(world, i + 12, j + 1, k + 5, Blocks.stained_hardened_clay, 0);
		this.setBlock(world, i + 12, j + 1, k + 6, Blocks.stained_hardened_clay, 0);
		this.setBlock(world, i + 12, j + 1, k + 7, Blocks.stained_hardened_clay, 0);
		this.setBlock(world, i + 12, j + 1, k + 8, Blocks.stained_hardened_clay, 0);
		this.setBlock(world, i + 12, j + 1, k + 9, Blocks.stained_hardened_clay, 0);
		this.setBlock(world, i + 12, j + 1, k + 10, Blocks.stained_hardened_clay, 0);
		this.setBlock(world, i + 12, j + 1, k + 11, Blocks.stained_hardened_clay, 0);
		this.setBlock(world, i + 12, j + 1, k + 12, Blocks.snow, 0);
		this.setBlock(world, i + 12, j + 1, k + 13, Blocks.snow, 0);
		this.setBlock(world, i + 12, j + 1, k + 14, Blocks.snow, 0);
		this.setBlock(world, i + 12, j + 2, k + 2, Blocks.snow, 0);
		this.setBlock(world, i + 12, j + 2, k + 3, Blocks.snow, 0);
		this.setBlock(world, i + 12, j + 2, k + 4, Blocks.stained_hardened_clay, 0);
		this.setBlock(world, i + 12, j + 2, k + 8, Blocks.brick_block, 0);
		this.setBlock(world, i + 12, j + 2, k + 11, Blocks.stained_hardened_clay, 0);
		this.setBlock(world, i + 12, j + 2, k + 12, Blocks.snow, 0);
		this.setBlock(world, i + 12, j + 2, k + 13, Blocks.snow, 0);
		this.setBlock(world, i + 12, j + 3, k + 3, Blocks.hardened_clay, 0);
		this.setBlock(world, i + 12, j + 3, k + 4, Blocks.stained_hardened_clay, 0);
		this.setBlock(world, i + 12, j + 3, k + 11, Blocks.stained_hardened_clay, 0);
		this.setBlock(world, i + 12, j + 3, k + 12, Blocks.hardened_clay, 0);
		this.setBlock(world, i + 12, j + 4, k + 3, Blocks.stained_hardened_clay, 8);
		this.setBlock(world, i + 12, j + 4, k + 4, Blocks.stained_hardened_clay, 0);
		this.setBlock(world, i + 12, j + 4, k + 11, Blocks.stained_hardened_clay, 0);
		this.setBlock(world, i + 12, j + 4, k + 12, Blocks.stained_hardened_clay, 8);
		this.setBlock(world, i + 12, j + 5, k + 4, Blocks.stained_hardened_clay, 8);
		this.setBlock(world, i + 12, j + 5, k + 5, Blocks.stained_hardened_clay, 0);
		this.setBlock(world, i + 12, j + 5, k + 10, Blocks.stained_hardened_clay, 0);
		this.setBlock(world, i + 12, j + 5, k + 11, Blocks.stained_hardened_clay, 8);
		this.setBlock(world, i + 12, j + 6, k + 4, Blocks.stained_hardened_clay, 8);
		this.setBlock(world, i + 12, j + 6, k + 5, Blocks.stained_hardened_clay, 0);
		this.setBlock(world, i + 12, j + 6, k + 6, Blocks.stained_hardened_clay, 0);
		this.setBlock(world, i + 12, j + 6, k + 7, Blocks.stained_hardened_clay, 0);
		this.setBlock(world, i + 12, j + 6, k + 8, Blocks.stained_hardened_clay, 0);
		this.setBlock(world, i + 12, j + 6, k + 9, Blocks.stained_hardened_clay, 0);
		this.setBlock(world, i + 12, j + 6, k + 10, Blocks.stained_hardened_clay, 0);
		this.setBlock(world, i + 12, j + 6, k + 11, Blocks.stained_hardened_clay, 8);
		this.setBlock(world, i + 12, j + 7, k + 5, Blocks.stained_hardened_clay, 8);
		this.setBlock(world, i + 12, j + 7, k + 6, Blocks.stained_hardened_clay, 0);
		this.setBlock(world, i + 12, j + 7, k + 7, Blocks.stained_hardened_clay, 0);
		this.setBlock(world, i + 12, j + 7, k + 8, Blocks.stained_hardened_clay, 0);
		this.setBlock(world, i + 12, j + 7, k + 9, Blocks.stained_hardened_clay, 0);
		this.setBlock(world, i + 12, j + 7, k + 10, Blocks.stained_hardened_clay, 8);
		this.setBlock(world, i + 12, j + 8, k + 5, Blocks.stained_hardened_clay, 8);
		this.setBlock(world, i + 12, j + 8, k + 6, Blocks.stained_hardened_clay, 8);
		this.setBlock(world, i + 12, j + 8, k + 7, Blocks.stained_hardened_clay, 0);
		this.setBlock(world, i + 12, j + 8, k + 8, Blocks.stained_hardened_clay, 0);
		this.setBlock(world, i + 12, j + 8, k + 9, Blocks.stained_hardened_clay, 8);
		this.setBlock(world, i + 12, j + 8, k + 10, Blocks.stained_hardened_clay, 8);
		this.setBlock(world, i + 12, j + 9, k + 7, Blocks.stained_hardened_clay, 8);
		this.setBlock(world, i + 12, j + 9, k + 8, Blocks.stained_hardened_clay, 8);
		this.setBlock(world, i + 13, j + 0, k + 0, Blocks.snow, 0);
		this.setBlock(world, i + 13, j + 0, k + 1, Blocks.snow, 0);
		this.setBlock(world, i + 13, j + 0, k + 2, Blocks.snow, 0);
		this.setBlock(world, i + 13, j + 0, k + 3, Blocks.snow, 0);
		this.setBlock(world, i + 13, j + 0, k + 4, Blocks.snow, 0);
		this.setBlock(world, i + 13, j + 0, k + 5, Blocks.snow, 0);
		this.setBlock(world, i + 13, j + 0, k + 6, Blocks.snow, 0);
		this.setBlock(world, i + 13, j + 0, k + 7, Blocks.snow, 0);
		this.setBlock(world, i + 13, j + 0, k + 8, Blocks.snow, 0);
		this.setBlock(world, i + 13, j + 0, k + 9, Blocks.snow, 0);
		this.setBlock(world, i + 13, j + 0, k + 10, Blocks.snow, 0);
		this.setBlock(world, i + 13, j + 0, k + 11, Blocks.snow, 0);
		this.setBlock(world, i + 13, j + 0, k + 12, Blocks.snow, 0);
		this.setBlock(world, i + 13, j + 0, k + 13, Blocks.snow, 0);
		this.setBlock(world, i + 13, j + 0, k + 14, Blocks.snow, 0);
		this.setBlock(world, i + 13, j + 0, k + 15, Blocks.snow, 0);
		this.setBlock(world, i + 13, j + 1, k + 1, Blocks.snow, 0);
		this.setBlock(world, i + 13, j + 1, k + 2, Blocks.snow, 0);
		this.setBlock(world, i + 13, j + 1, k + 3, Blocks.snow, 0);
		this.setBlock(world, i + 13, j + 1, k + 4, Blocks.snow, 0);
		this.setBlock(world, i + 13, j + 1, k + 5, Blocks.stained_hardened_clay, 0);
		this.setBlock(world, i + 13, j + 1, k + 6, Blocks.stained_hardened_clay, 0);
		this.setBlock(world, i + 13, j + 1, k + 7, Blocks.stained_hardened_clay, 0);
		this.setBlock(world, i + 13, j + 1, k + 8, Blocks.stained_hardened_clay, 0);
		this.setBlock(world, i + 13, j + 1, k + 9, Blocks.stained_hardened_clay, 0);
		this.setBlock(world, i + 13, j + 1, k + 10, Blocks.stained_hardened_clay, 0);
		this.setBlock(world, i + 13, j + 1, k + 11, Blocks.snow, 0);
		this.setBlock(world, i + 13, j + 1, k + 12, Blocks.snow, 0);
		this.setBlock(world, i + 13, j + 1, k + 13, Blocks.snow, 0);
		this.setBlock(world, i + 13, j + 1, k + 14, Blocks.snow, 0);
		this.setBlock(world, i + 13, j + 2, k + 2, Blocks.snow, 0);
		this.setBlock(world, i + 13, j + 2, k + 3, Blocks.snow, 0);
		this.setBlock(world, i + 13, j + 2, k + 4, Blocks.stained_hardened_clay, 0);
		this.setBlock(world, i + 13, j + 2, k + 5, Blocks.stained_hardened_clay, 0);
		this.setBlock(world, i + 13, j + 2, k + 10, Blocks.stained_hardened_clay, 0);
		this.setBlock(world, i + 13, j + 2, k + 11, Blocks.snow, 0);
		this.setBlock(world, i + 13, j + 2, k + 12, Blocks.snow, 0);
		this.setBlock(world, i + 13, j + 2, k + 13, Blocks.snow, 0);
		this.setBlock(world, i + 13, j + 3, k + 3, Blocks.hardened_clay, 0);
		this.setBlock(world, i + 13, j + 3, k + 4, Blocks.stained_hardened_clay, 0);
		this.setBlock(world, i + 13, j + 3, k + 5, Blocks.stained_hardened_clay, 0);
		this.setBlock(world, i + 13, j + 3, k + 10, Blocks.stained_hardened_clay, 0);
		this.setBlock(world, i + 13, j + 3, k + 11, Blocks.stained_hardened_clay, 0);
		this.setBlock(world, i + 13, j + 3, k + 12, Blocks.hardened_clay, 0);
		this.setBlock(world, i + 13, j + 4, k + 3, Blocks.stained_hardened_clay, 8);
		this.setBlock(world, i + 13, j + 4, k + 4, Blocks.stained_hardened_clay, 0);
		this.setBlock(world, i + 13, j + 4, k + 5, Blocks.stained_hardened_clay, 0);
		this.setBlock(world, i + 13, j + 4, k + 10, Blocks.stained_hardened_clay, 0);
		this.setBlock(world, i + 13, j + 4, k + 11, Blocks.stained_hardened_clay, 0);
		this.setBlock(world, i + 13, j + 4, k + 12, Blocks.stained_hardened_clay, 8);
		this.setBlock(world, i + 13, j + 5, k + 4, Blocks.stained_hardened_clay, 8);
		this.setBlock(world, i + 13, j + 5, k + 5, Blocks.stained_hardened_clay, 0);
		this.setBlock(world, i + 13, j + 5, k + 6, Blocks.stained_hardened_clay, 0);
		this.setBlock(world, i + 13, j + 5, k + 7, Blocks.stained_hardened_clay, 0);
		this.setBlock(world, i + 13, j + 5, k + 8, Blocks.stained_hardened_clay, 0);
		this.setBlock(world, i + 13, j + 5, k + 9, Blocks.stained_hardened_clay, 0);
		this.setBlock(world, i + 13, j + 5, k + 10, Blocks.stained_hardened_clay, 0);
		this.setBlock(world, i + 13, j + 5, k + 11, Blocks.stained_hardened_clay, 8);
		this.setBlock(world, i + 13, j + 6, k + 5, Blocks.stained_hardened_clay, 8);
		this.setBlock(world, i + 13, j + 6, k + 6, Blocks.stained_hardened_clay, 0);
		this.setBlock(world, i + 13, j + 6, k + 7, Blocks.stained_hardened_clay, 0);
		this.setBlock(world, i + 13, j + 6, k + 8, Blocks.stained_hardened_clay, 0);
		this.setBlock(world, i + 13, j + 6, k + 9, Blocks.stained_hardened_clay, 0);
		this.setBlock(world, i + 13, j + 6, k + 10, Blocks.stained_hardened_clay, 8);
		this.setBlock(world, i + 13, j + 7, k + 5, Blocks.stained_hardened_clay, 8);
		this.setBlock(world, i + 13, j + 7, k + 6, Blocks.stained_hardened_clay, 8);
		this.setBlock(world, i + 13, j + 7, k + 7, Blocks.stained_hardened_clay, 8);
		this.setBlock(world, i + 13, j + 7, k + 8, Blocks.stained_hardened_clay, 8);
		this.setBlock(world, i + 13, j + 7, k + 9, Blocks.stained_hardened_clay, 8);
		this.setBlock(world, i + 13, j + 7, k + 10, Blocks.stained_hardened_clay, 8);
		this.setBlock(world, i + 13, j + 8, k + 6, Blocks.stained_hardened_clay, 8);
		this.setBlock(world, i + 13, j + 8, k + 7, Blocks.stained_hardened_clay, 8);
		this.setBlock(world, i + 13, j + 8, k + 8, Blocks.stained_hardened_clay, 8);
		this.setBlock(world, i + 13, j + 8, k + 9, Blocks.stained_hardened_clay, 8);
		this.setBlock(world, i + 14, j + 0, k + 0, Blocks.snow, 0);
		this.setBlock(world, i + 14, j + 0, k + 1, Blocks.snow, 0);
		this.setBlock(world, i + 14, j + 0, k + 2, Blocks.snow, 0);
		this.setBlock(world, i + 14, j + 0, k + 3, Blocks.snow, 0);
		this.setBlock(world, i + 14, j + 0, k + 4, Blocks.snow, 0);
		this.setBlock(world, i + 14, j + 0, k + 5, Blocks.snow, 0);
		this.setBlock(world, i + 14, j + 0, k + 6, Blocks.snow, 0);
		this.setBlock(world, i + 14, j + 0, k + 7, Blocks.snow, 0);
		this.setBlock(world, i + 14, j + 0, k + 8, Blocks.snow, 0);
		this.setBlock(world, i + 14, j + 0, k + 9, Blocks.snow, 0);
		this.setBlock(world, i + 14, j + 0, k + 10, Blocks.snow, 0);
		this.setBlock(world, i + 14, j + 0, k + 11, Blocks.snow, 0);
		this.setBlock(world, i + 14, j + 0, k + 12, Blocks.snow, 0);
		this.setBlock(world, i + 14, j + 0, k + 13, Blocks.snow, 0);
		this.setBlock(world, i + 14, j + 0, k + 14, Blocks.snow, 0);
		this.setBlock(world, i + 14, j + 0, k + 15, Blocks.snow, 0);
		this.setBlock(world, i + 14, j + 1, k + 1, Blocks.snow, 0);
		this.setBlock(world, i + 14, j + 1, k + 2, Blocks.snow, 0);
		this.setBlock(world, i + 14, j + 1, k + 3, Blocks.snow, 0);
		this.setBlock(world, i + 14, j + 1, k + 4, Blocks.snow, 0);
		this.setBlock(world, i + 14, j + 1, k + 5, Blocks.snow, 0);
		this.setBlock(world, i + 14, j + 1, k + 6, Blocks.stained_hardened_clay, 0);
		this.setBlock(world, i + 14, j + 1, k + 7, Blocks.stained_hardened_clay, 0);
		this.setBlock(world, i + 14, j + 1, k + 8, Blocks.stained_hardened_clay, 0);
		this.setBlock(world, i + 14, j + 1, k + 9, Blocks.stained_hardened_clay, 0);
		this.setBlock(world, i + 14, j + 1, k + 10, Blocks.snow, 0);
		this.setBlock(world, i + 14, j + 1, k + 11, Blocks.snow, 0);
		this.setBlock(world, i + 14, j + 1, k + 12, Blocks.snow, 0);
		this.setBlock(world, i + 14, j + 1, k + 13, Blocks.snow, 0);
		this.setBlock(world, i + 14, j + 1, k + 14, Blocks.snow, 0);
		this.setBlock(world, i + 14, j + 2, k + 2, Blocks.snow, 0);
		this.setBlock(world, i + 14, j + 2, k + 3, Blocks.snow, 0);
		this.setBlock(world, i + 14, j + 2, k + 4, Blocks.snow, 0);
		this.setBlock(world, i + 14, j + 2, k + 5, Blocks.stained_hardened_clay, 0);
		this.setBlock(world, i + 14, j + 2, k + 6, Blocks.stained_hardened_clay, 0);
		this.setBlock(world, i + 14, j + 2, k + 7, Blocks.stained_hardened_clay, 0);
		this.setBlock(world, i + 14, j + 2, k + 8, Blocks.stained_hardened_clay, 0);
		this.setBlock(world, i + 14, j + 2, k + 9, Blocks.stained_hardened_clay, 0);
		this.setBlock(world, i + 14, j + 2, k + 10, Blocks.snow, 0);
		this.setBlock(world, i + 14, j + 2, k + 11, Blocks.snow, 0);
		this.setBlock(world, i + 14, j + 2, k + 12, Blocks.snow, 0);
		this.setBlock(world, i + 14, j + 2, k + 13, Blocks.snow, 0);
		this.setBlock(world, i + 14, j + 3, k + 3, Blocks.hardened_clay, 0);
		this.setBlock(world, i + 14, j + 3, k + 4, Blocks.stained_hardened_clay, 0);
		this.setBlock(world, i + 14, j + 3, k + 5, Blocks.stained_hardened_clay, 0);
		this.setBlock(world, i + 14, j + 3, k + 6, Blocks.stained_hardened_clay, 0);
		this.setBlock(world, i + 14, j + 3, k + 7, Blocks.stained_hardened_clay, 0);
		this.setBlock(world, i + 14, j + 3, k + 8, Blocks.stained_hardened_clay, 0);
		this.setBlock(world, i + 14, j + 3, k + 9, Blocks.stained_hardened_clay, 0);
		this.setBlock(world, i + 14, j + 3, k + 10, Blocks.stained_hardened_clay, 0);
		this.setBlock(world, i + 14, j + 3, k + 11, Blocks.stained_hardened_clay, 0);
		this.setBlock(world, i + 14, j + 3, k + 12, Blocks.hardened_clay, 0);
		this.setBlock(world, i + 14, j + 4, k + 3, Blocks.stained_hardened_clay, 8);
		this.setBlock(world, i + 14, j + 4, k + 4, Blocks.stained_hardened_clay, 0);
		this.setBlock(world, i + 14, j + 4, k + 5, Blocks.stained_hardened_clay, 0);
		this.setBlock(world, i + 14, j + 4, k + 6, Blocks.stained_hardened_clay, 0);
		this.setBlock(world, i + 14, j + 4, k + 7, Blocks.stained_hardened_clay, 0);
		this.setBlock(world, i + 14, j + 4, k + 8, Blocks.stained_hardened_clay, 0);
		this.setBlock(world, i + 14, j + 4, k + 9, Blocks.stained_hardened_clay, 0);
		this.setBlock(world, i + 14, j + 4, k + 10, Blocks.stained_hardened_clay, 0);
		this.setBlock(world, i + 14, j + 4, k + 11, Blocks.stained_hardened_clay, 0);
		this.setBlock(world, i + 14, j + 4, k + 12, Blocks.stained_hardened_clay, 8);
		this.setBlock(world, i + 14, j + 5, k + 4, Blocks.stained_hardened_clay, 8);
		this.setBlock(world, i + 14, j + 5, k + 5, Blocks.stained_hardened_clay, 8);
		this.setBlock(world, i + 14, j + 5, k + 6, Blocks.stained_hardened_clay, 0);
		this.setBlock(world, i + 14, j + 5, k + 7, Blocks.stained_hardened_clay, 0);
		this.setBlock(world, i + 14, j + 5, k + 8, Blocks.stained_hardened_clay, 0);
		this.setBlock(world, i + 14, j + 5, k + 9, Blocks.stained_hardened_clay, 0);
		this.setBlock(world, i + 14, j + 5, k + 10, Blocks.stained_hardened_clay, 8);
		this.setBlock(world, i + 14, j + 5, k + 11, Blocks.stained_hardened_clay, 8);
		this.setBlock(world, i + 14, j + 6, k + 6, Blocks.stained_hardened_clay, 8);
		this.setBlock(world, i + 14, j + 6, k + 7, Blocks.stained_hardened_clay, 8);
		this.setBlock(world, i + 14, j + 6, k + 8, Blocks.stained_hardened_clay, 8);
		this.setBlock(world, i + 14, j + 6, k + 9, Blocks.stained_hardened_clay, 8);
		this.setBlock(world, i + 15, j + 0, k + 0, Blocks.snow, 0);
		this.setBlock(world, i + 15, j + 0, k + 1, Blocks.snow, 0);
		this.setBlock(world, i + 15, j + 0, k + 2, Blocks.snow, 0);
		this.setBlock(world, i + 15, j + 0, k + 3, Blocks.snow, 0);
		this.setBlock(world, i + 15, j + 0, k + 4, Blocks.snow, 0);
		this.setBlock(world, i + 15, j + 0, k + 5, Blocks.snow, 0);
		this.setBlock(world, i + 15, j + 0, k + 6, Blocks.snow, 0);
		this.setBlock(world, i + 15, j + 0, k + 7, Blocks.snow, 0);
		this.setBlock(world, i + 15, j + 0, k + 8, Blocks.snow, 0);
		this.setBlock(world, i + 15, j + 0, k + 9, Blocks.snow, 0);
		this.setBlock(world, i + 15, j + 0, k + 10, Blocks.snow, 0);
		this.setBlock(world, i + 15, j + 0, k + 11, Blocks.snow, 0);
		this.setBlock(world, i + 15, j + 0, k + 12, Blocks.snow, 0);
		this.setBlock(world, i + 15, j + 0, k + 13, Blocks.snow, 0);
		this.setBlock(world, i + 15, j + 0, k + 14, Blocks.snow, 0);
		this.setBlock(world, i + 15, j + 0, k + 15, Blocks.snow, 0);
		this.setBlock(world, i + 15, j + 1, k + 1, Blocks.snow, 0);
		this.setBlock(world, i + 15, j + 1, k + 2, Blocks.snow, 0);
		this.setBlock(world, i + 15, j + 1, k + 3, Blocks.snow, 0);
		this.setBlock(world, i + 15, j + 1, k + 4, Blocks.snow, 0);
		this.setBlock(world, i + 15, j + 1, k + 5, Blocks.snow, 0);
		this.setBlock(world, i + 15, j + 1, k + 6, Blocks.snow, 0);
		this.setBlock(world, i + 15, j + 1, k + 7, Blocks.stained_hardened_clay, 0);
		this.setBlock(world, i + 15, j + 1, k + 8, Blocks.stained_hardened_clay, 0);
		this.setBlock(world, i + 15, j + 1, k + 9, Blocks.snow, 0);
		this.setBlock(world, i + 15, j + 1, k + 10, Blocks.snow, 0);
		this.setBlock(world, i + 15, j + 1, k + 11, Blocks.snow, 0);
		this.setBlock(world, i + 15, j + 1, k + 12, Blocks.snow, 0);
		this.setBlock(world, i + 15, j + 1, k + 13, Blocks.snow, 0);
		this.setBlock(world, i + 15, j + 1, k + 14, Blocks.snow, 0);
		this.setBlock(world, i + 15, j + 2, k + 2, Blocks.snow, 0);
		this.setBlock(world, i + 15, j + 2, k + 3, Blocks.snow, 0);
		this.setBlock(world, i + 15, j + 2, k + 4, Blocks.snow, 0);
		this.setBlock(world, i + 15, j + 2, k + 5, Blocks.snow, 0);
		this.setBlock(world, i + 15, j + 2, k + 6, Blocks.snow, 0);
		this.setBlock(world, i + 15, j + 2, k + 7, Blocks.stained_hardened_clay, 0);
		this.setBlock(world, i + 15, j + 2, k + 8, Blocks.stained_hardened_clay, 0);
		this.setBlock(world, i + 15, j + 2, k + 9, Blocks.snow, 0);
		this.setBlock(world, i + 15, j + 2, k + 10, Blocks.snow, 0);
		this.setBlock(world, i + 15, j + 2, k + 11, Blocks.snow, 0);
		this.setBlock(world, i + 15, j + 2, k + 12, Blocks.snow, 0);
		this.setBlock(world, i + 15, j + 2, k + 13, Blocks.snow, 0);
		this.setBlock(world, i + 15, j + 3, k + 3, Blocks.hardened_clay, 0);
		this.setBlock(world, i + 15, j + 3, k + 4, Blocks.stained_hardened_clay, 0);
		this.setBlock(world, i + 15, j + 3, k + 5, Blocks.stained_hardened_clay, 0);
		this.setBlock(world, i + 15, j + 3, k + 6, Blocks.stained_hardened_clay, 0);
		this.setBlock(world, i + 15, j + 3, k + 7, Blocks.stained_hardened_clay, 0);
		this.setBlock(world, i + 15, j + 3, k + 8, Blocks.stained_hardened_clay, 0);
		this.setBlock(world, i + 15, j + 3, k + 9, Blocks.stained_hardened_clay, 0);
		this.setBlock(world, i + 15, j + 3, k + 10, Blocks.stained_hardened_clay, 0);
		this.setBlock(world, i + 15, j + 3, k + 11, Blocks.stained_hardened_clay, 0);
		this.setBlock(world, i + 15, j + 3, k + 12, Blocks.hardened_clay, 0);
		this.setBlock(world, i + 15, j + 4, k + 4, Blocks.stained_hardened_clay, 8);
		this.setBlock(world, i + 15, j + 4, k + 5, Blocks.stained_hardened_clay, 0);
		this.setBlock(world, i + 15, j + 4, k + 6, Blocks.stained_hardened_clay, 0);
		this.setBlock(world, i + 15, j + 4, k + 7, Blocks.stained_hardened_clay, 0);
		this.setBlock(world, i + 15, j + 4, k + 8, Blocks.stained_hardened_clay, 0);
		this.setBlock(world, i + 15, j + 4, k + 9, Blocks.stained_hardened_clay, 0);
		this.setBlock(world, i + 15, j + 4, k + 10, Blocks.stained_hardened_clay, 0);
		this.setBlock(world, i + 15, j + 4, k + 11, Blocks.stained_hardened_clay, 8);
		this.setBlock(world, i + 15, j + 5, k + 5, Blocks.stained_hardened_clay, 8);
		this.setBlock(world, i + 15, j + 5, k + 6, Blocks.stained_hardened_clay, 8);
		this.setBlock(world, i + 15, j + 5, k + 7, Blocks.stained_hardened_clay, 8);
		this.setBlock(world, i + 15, j + 5, k + 8, Blocks.stained_hardened_clay, 8);
		this.setBlock(world, i + 15, j + 5, k + 9, Blocks.stained_hardened_clay, 8);
		this.setBlock(world, i + 15, j + 5, k + 10, Blocks.stained_hardened_clay, 8);
		this.setBlock(world, i + 16, j + 0, k + 0, Blocks.snow, 0);
		this.setBlock(world, i + 16, j + 0, k + 1, Blocks.snow, 0);
		this.setBlock(world, i + 16, j + 0, k + 2, Blocks.snow, 0);
		this.setBlock(world, i + 16, j + 0, k + 3, Blocks.snow, 0);
		this.setBlock(world, i + 16, j + 0, k + 4, Blocks.snow, 0);
		this.setBlock(world, i + 16, j + 0, k + 5, Blocks.snow, 0);
		this.setBlock(world, i + 16, j + 0, k + 6, Blocks.snow, 0);
		this.setBlock(world, i + 16, j + 0, k + 7, Blocks.snow, 0);
		this.setBlock(world, i + 16, j + 0, k + 8, Blocks.snow, 0);
		this.setBlock(world, i + 16, j + 0, k + 9, Blocks.snow, 0);
		this.setBlock(world, i + 16, j + 0, k + 10, Blocks.snow, 0);
		this.setBlock(world, i + 16, j + 0, k + 11, Blocks.snow, 0);
		this.setBlock(world, i + 16, j + 0, k + 12, Blocks.snow, 0);
		this.setBlock(world, i + 16, j + 0, k + 13, Blocks.snow, 0);
		this.setBlock(world, i + 16, j + 0, k + 14, Blocks.snow, 0);
		this.setBlock(world, i + 16, j + 0, k + 15, Blocks.snow, 0);
		this.setBlock(world, i + 16, j + 1, k + 1, Blocks.snow, 0);
		this.setBlock(world, i + 16, j + 1, k + 2, Blocks.snow, 0);
		this.setBlock(world, i + 16, j + 1, k + 3, Blocks.snow, 0);
		this.setBlock(world, i + 16, j + 1, k + 4, Blocks.snow, 0);
		this.setBlock(world, i + 16, j + 1, k + 5, Blocks.snow, 0);
		this.setBlock(world, i + 16, j + 1, k + 6, Blocks.snow, 0);
		this.setBlock(world, i + 16, j + 1, k + 7, Blocks.snow, 0);
		this.setBlock(world, i + 16, j + 1, k + 8, Blocks.snow, 0);
		this.setBlock(world, i + 16, j + 1, k + 9, Blocks.snow, 0);
		this.setBlock(world, i + 16, j + 1, k + 10, Blocks.snow, 0);
		this.setBlock(world, i + 16, j + 1, k + 11, Blocks.snow, 0);
		this.setBlock(world, i + 16, j + 1, k + 12, Blocks.snow, 0);
		this.setBlock(world, i + 16, j + 1, k + 13, Blocks.snow, 0);
		this.setBlock(world, i + 16, j + 1, k + 14, Blocks.snow, 0);
		this.setBlock(world, i + 16, j + 2, k + 2, Blocks.snow, 0);
		this.setBlock(world, i + 16, j + 2, k + 3, Blocks.snow, 0);
		this.setBlock(world, i + 16, j + 2, k + 4, Blocks.snow, 0);
		this.setBlock(world, i + 16, j + 2, k + 5, Blocks.snow, 0);
		this.setBlock(world, i + 16, j + 2, k + 6, Blocks.snow, 0);
		this.setBlock(world, i + 16, j + 2, k + 7, Blocks.snow, 0);
		this.setBlock(world, i + 16, j + 2, k + 8, Blocks.snow, 0);
		this.setBlock(world, i + 16, j + 2, k + 9, Blocks.snow, 0);
		this.setBlock(world, i + 16, j + 2, k + 10, Blocks.snow, 0);
		this.setBlock(world, i + 16, j + 2, k + 11, Blocks.snow, 0);
		this.setBlock(world, i + 16, j + 2, k + 12, Blocks.snow, 0);
		this.setBlock(world, i + 16, j + 2, k + 13, Blocks.snow, 0);
		this.setBlock(world, i + 16, j + 3, k + 4, Blocks.hardened_clay, 0);
		this.setBlock(world, i + 16, j + 3, k + 5, Blocks.stained_hardened_clay, 0);
		this.setBlock(world, i + 16, j + 3, k + 6, Blocks.stained_hardened_clay, 0);
		this.setBlock(world, i + 16, j + 3, k + 7, Blocks.stained_hardened_clay, 0);
		this.setBlock(world, i + 16, j + 3, k + 8, Blocks.stained_hardened_clay, 0);
		this.setBlock(world, i + 16, j + 3, k + 9, Blocks.stained_hardened_clay, 0);
		this.setBlock(world, i + 16, j + 3, k + 10, Blocks.stained_hardened_clay, 0);
		this.setBlock(world, i + 16, j + 3, k + 11, Blocks.hardened_clay, 0);
		this.setBlock(world, i + 16, j + 4, k + 5, Blocks.stained_hardened_clay, 8);
		this.setBlock(world, i + 16, j + 4, k + 6, Blocks.stained_hardened_clay, 8);
		this.setBlock(world, i + 16, j + 4, k + 7, Blocks.stained_hardened_clay, 8);
		this.setBlock(world, i + 16, j + 4, k + 8, Blocks.stained_hardened_clay, 8);
		this.setBlock(world, i + 16, j + 4, k + 9, Blocks.stained_hardened_clay, 8);
		this.setBlock(world, i + 16, j + 4, k + 10, Blocks.stained_hardened_clay, 8);
		this.setBlock(world, i + 17, j + 0, k + 1, Blocks.snow, 0);
		this.setBlock(world, i + 17, j + 0, k + 2, Blocks.snow, 0);
		this.setBlock(world, i + 17, j + 0, k + 3, Blocks.snow, 0);
		this.setBlock(world, i + 17, j + 0, k + 4, Blocks.snow, 0);
		this.setBlock(world, i + 17, j + 0, k + 5, Blocks.snow, 0);
		this.setBlock(world, i + 17, j + 0, k + 6, Blocks.snow, 0);
		this.setBlock(world, i + 17, j + 0, k + 7, Blocks.snow, 0);
		this.setBlock(world, i + 17, j + 0, k + 8, Blocks.snow, 0);
		this.setBlock(world, i + 17, j + 0, k + 9, Blocks.snow, 0);
		this.setBlock(world, i + 17, j + 0, k + 10, Blocks.snow, 0);
		this.setBlock(world, i + 17, j + 0, k + 11, Blocks.snow, 0);
		this.setBlock(world, i + 17, j + 0, k + 12, Blocks.snow, 0);
		this.setBlock(world, i + 17, j + 0, k + 13, Blocks.snow, 0);
		this.setBlock(world, i + 17, j + 0, k + 14, Blocks.snow, 0);
		this.setBlock(world, i + 17, j + 1, k + 2, Blocks.snow, 0);
		this.setBlock(world, i + 17, j + 1, k + 3, Blocks.snow, 0);
		this.setBlock(world, i + 17, j + 1, k + 4, Blocks.snow, 0);
		this.setBlock(world, i + 17, j + 1, k + 5, Blocks.snow, 0);
		this.setBlock(world, i + 17, j + 1, k + 6, Blocks.snow, 0);
		this.setBlock(world, i + 17, j + 1, k + 7, Blocks.snow, 0);
		this.setBlock(world, i + 17, j + 1, k + 8, Blocks.snow, 0);
		this.setBlock(world, i + 17, j + 1, k + 9, Blocks.snow, 0);
		this.setBlock(world, i + 17, j + 1, k + 10, Blocks.snow, 0);
		this.setBlock(world, i + 17, j + 1, k + 11, Blocks.snow, 0);
		this.setBlock(world, i + 17, j + 1, k + 12, Blocks.snow, 0);
		this.setBlock(world, i + 17, j + 1, k + 13, Blocks.snow, 0);
		this.setBlock(world, i + 17, j + 2, k + 3, Blocks.snow, 0);
		this.setBlock(world, i + 17, j + 2, k + 4, Blocks.snow, 0);
		this.setBlock(world, i + 17, j + 2, k + 5, Blocks.snow, 0);
		this.setBlock(world, i + 17, j + 2, k + 6, Blocks.snow, 0);
		this.setBlock(world, i + 17, j + 2, k + 7, Blocks.snow, 0);
		this.setBlock(world, i + 17, j + 2, k + 8, Blocks.snow, 0);
		this.setBlock(world, i + 17, j + 2, k + 9, Blocks.snow, 0);
		this.setBlock(world, i + 17, j + 2, k + 10, Blocks.snow, 0);
		this.setBlock(world, i + 17, j + 2, k + 11, Blocks.snow, 0);
		this.setBlock(world, i + 17, j + 2, k + 12, Blocks.snow, 0);
		this.setBlock(world, i + 17, j + 3, k + 5, Blocks.hardened_clay, 0);
		this.setBlock(world, i + 17, j + 3, k + 6, Blocks.hardened_clay, 0);
		this.setBlock(world, i + 17, j + 3, k + 7, Blocks.hardened_clay, 0);
		this.setBlock(world, i + 17, j + 3, k + 8, Blocks.hardened_clay, 0);
		this.setBlock(world, i + 17, j + 3, k + 9, Blocks.hardened_clay, 0);
		this.setBlock(world, i + 17, j + 3, k + 10, Blocks.hardened_clay, 0);
		this.setBlock(world, i + 18, j + 0, k + 2, Blocks.snow, 0);
		this.setBlock(world, i + 18, j + 0, k + 3, Blocks.snow, 0);
		this.setBlock(world, i + 18, j + 0, k + 4, Blocks.snow, 0);
		this.setBlock(world, i + 18, j + 0, k + 5, Blocks.snow, 0);
		this.setBlock(world, i + 18, j + 0, k + 6, Blocks.snow, 0);
		this.setBlock(world, i + 18, j + 0, k + 7, Blocks.snow, 0);
		this.setBlock(world, i + 18, j + 0, k + 8, Blocks.snow, 0);
		this.setBlock(world, i + 18, j + 0, k + 9, Blocks.snow, 0);
		this.setBlock(world, i + 18, j + 0, k + 10, Blocks.snow, 0);
		this.setBlock(world, i + 18, j + 0, k + 11, Blocks.snow, 0);
		this.setBlock(world, i + 18, j + 0, k + 12, Blocks.snow, 0);
		this.setBlock(world, i + 18, j + 0, k + 13, Blocks.snow, 0);
		this.setBlock(world, i + 18, j + 1, k + 3, Blocks.snow, 0);
		this.setBlock(world, i + 18, j + 1, k + 4, Blocks.snow, 0);
		this.setBlock(world, i + 18, j + 1, k + 5, Blocks.snow, 0);
		this.setBlock(world, i + 18, j + 1, k + 6, Blocks.snow, 0);
		this.setBlock(world, i + 18, j + 1, k + 7, Blocks.snow, 0);
		this.setBlock(world, i + 18, j + 1, k + 8, Blocks.snow, 0);
		this.setBlock(world, i + 18, j + 1, k + 9, Blocks.snow, 0);
		this.setBlock(world, i + 18, j + 1, k + 10, Blocks.snow, 0);
		this.setBlock(world, i + 18, j + 1, k + 11, Blocks.snow, 0);
		this.setBlock(world, i + 18, j + 1, k + 12, Blocks.snow, 0);
		this.setBlock(world, i + 18, j + 2, k + 4, Blocks.snow, 0);
		this.setBlock(world, i + 18, j + 2, k + 5, Blocks.snow, 0);
		this.setBlock(world, i + 18, j + 2, k + 6, Blocks.snow, 0);
		this.setBlock(world, i + 18, j + 2, k + 7, Blocks.snow, 0);
		this.setBlock(world, i + 18, j + 2, k + 8, Blocks.snow, 0);
		this.setBlock(world, i + 18, j + 2, k + 9, Blocks.snow, 0);
		this.setBlock(world, i + 18, j + 2, k + 10, Blocks.snow, 0);
		this.setBlock(world, i + 18, j + 2, k + 11, Blocks.snow, 0);
		this.setBlock(world, i + 19, j + 0, k + 3, Blocks.snow, 0);
		this.setBlock(world, i + 19, j + 0, k + 4, Blocks.snow, 0);
		this.setBlock(world, i + 19, j + 0, k + 5, Blocks.snow, 0);
		this.setBlock(world, i + 19, j + 0, k + 6, Blocks.snow, 0);
		this.setBlock(world, i + 19, j + 0, k + 7, Blocks.snow, 0);
		this.setBlock(world, i + 19, j + 0, k + 8, Blocks.snow, 0);
		this.setBlock(world, i + 19, j + 0, k + 9, Blocks.snow, 0);
		this.setBlock(world, i + 19, j + 0, k + 10, Blocks.snow, 0);
		this.setBlock(world, i + 19, j + 0, k + 11, Blocks.snow, 0);
		this.setBlock(world, i + 19, j + 0, k + 12, Blocks.snow, 0);
		this.setBlock(world, i + 19, j + 1, k + 4, Blocks.snow, 0);
		this.setBlock(world, i + 19, j + 1, k + 5, Blocks.snow, 0);
		this.setBlock(world, i + 19, j + 1, k + 6, Blocks.snow, 0);
		this.setBlock(world, i + 19, j + 1, k + 7, Blocks.snow, 0);
		this.setBlock(world, i + 19, j + 1, k + 8, Blocks.snow, 0);
		this.setBlock(world, i + 19, j + 1, k + 9, Blocks.snow, 0);
		this.setBlock(world, i + 19, j + 1, k + 10, Blocks.snow, 0);
		this.setBlock(world, i + 19, j + 1, k + 11, Blocks.snow, 0);
		this.setBlock(world, i + 20, j + 0, k + 4, Blocks.snow, 0);
		this.setBlock(world, i + 20, j + 0, k + 5, Blocks.snow, 0);
		this.setBlock(world, i + 20, j + 0, k + 6, Blocks.snow, 0);
		this.setBlock(world, i + 20, j + 0, k + 7, Blocks.snow, 0);
		this.setBlock(world, i + 20, j + 0, k + 8, Blocks.snow, 0);
		this.setBlock(world, i + 20, j + 0, k + 9, Blocks.snow, 0);
		this.setBlock(world, i + 20, j + 0, k + 10, Blocks.snow, 0);
		this.setBlock(world, i + 20, j + 0, k + 11, Blocks.snow, 0);
		world.setBlockMetadataWithNotify(i + 7, j + 3, k + 6, 3, 2);
		world.setBlockMetadataWithNotify(i + 7, j + 3, k + 9, 4, 2);
		world.setBlockMetadataWithNotify(i + 8, j + 3, k + 5, 1, 2);
		world.setBlockMetadataWithNotify(i + 8, j + 3, k + 10, 1, 2);
		world.setBlockMetadataWithNotify(i + 12, j + 3, k + 5, 2, 2);
		world.setBlockMetadataWithNotify(i + 12, j + 3, k + 10, 2, 2);
		world.setBlockMetadataWithNotify(i + 13, j + 3, k + 6, 3, 2);
		world.setBlockMetadataWithNotify(i + 13, j + 3, k + 9, 4, 2);

		return true;
	}
}