/*
*** MADE BY MRPONYCAPTAIN'S .SCHEMATIC TO .JAVA CONVERTING TOOL v2.0 ***
*/

package com.zalthrion.zylroth.world.gen.structures;

import java.util.Random;

import cpw.mods.fml.common.IWorldGenerator;
import net.minecraft.block.Block;
import net.minecraft.init.Blocks;
import net.minecraft.world.World;
import net.minecraft.world.chunk.IChunkProvider;
import net.minecraft.world.gen.feature.WorldGenerator;

public class RegularWell extends WorldGenerator implements IWorldGenerator
{
	protected Block[] getValidSpawnBlocks() {
		return new Block[] {
			Blocks.sand
		};
	}

	public boolean locationIsValidSpawn(World world, int i, int j, int k){
		int distanceToAir = 0;
		Block check = world.getBlock(i, j, k);

		while (check != Blocks.air){
			if (distanceToAir > 0){
				return false;
			}

			distanceToAir++;
			check = world.getBlock(i, j + distanceToAir, k);
		}

		j += distanceToAir - 1;

		Block block = world.getBlock(i, j, k);
		Block blockAbove = world.getBlock(i, j+1, k);
		Block blockBelow = world.getBlock(i, j-1, k);
		
		for (Block x : getValidSpawnBlocks()){
			if (blockAbove != Blocks.air){
				return false;
			}
			if (block == x){
				return true;
			}else if (block == Blocks.snow && blockBelow == x){
				return true;
			}
		}
		
		return false;
	}

	public RegularWell() { }

	@Override
	public void generate(Random random, int chunkX, int chunkZ, World world, IChunkProvider chunkGenerator, IChunkProvider chunkProvider) { }

	public void setBlock(World world, int x, int y, int z, Block block, int metadata)
	{
		Block b1 = world.getBlock(x, y, z);

		if(b1.isAir(world, x, y, z) || b1.isLeaves(world, x, y, z))
		{
			world.setBlock(x, y, z, block, metadata, 2);
		}
	}

	@Override
	public boolean generate(World world, Random rand, int i, int j, int k) {
		//check that each corner is one of the valid spawn blocks
		if(!locationIsValidSpawn(world, i, j, k) || !locationIsValidSpawn(world, i + 8, j, k) || !locationIsValidSpawn(world, i + 8, j, k + 8) || !locationIsValidSpawn(world, i, j, k + 8))
		{
			return false;
		}

		k = k - 10;
		i = i - 10;

		this.setBlock(world, i + 0, j + 0, k + 0, Blocks.air, 0);
		this.setBlock(world, i + 0, j + 0, k + 1, Blocks.air, 0);
		this.setBlock(world, i + 0, j + 0, k + 2, Blocks.air, 0);
		this.setBlock(world, i + 0, j + 0, k + 3, Blocks.air, 0);
		this.setBlock(world, i + 0, j + 0, k + 4, Blocks.air, 0);
		this.setBlock(world, i + 0, j + 0, k + 5, Blocks.air, 0);
		this.setBlock(world, i + 0, j + 0, k + 6, Blocks.air, 0);
		this.setBlock(world, i + 0, j + 0, k + 7, Blocks.air, 0);
		this.setBlock(world, i + 0, j + 0, k + 8, Blocks.air, 0);
		this.setBlock(world, i + 0, j + 1, k + 0, Blocks.air, 0);
		this.setBlock(world, i + 0, j + 1, k + 1, Blocks.air, 0);
		this.setBlock(world, i + 0, j + 1, k + 2, Blocks.air, 0);
		this.setBlock(world, i + 0, j + 1, k + 3, Blocks.air, 0);
		this.setBlock(world, i + 0, j + 1, k + 4, Blocks.air, 0);
		this.setBlock(world, i + 0, j + 1, k + 5, Blocks.air, 0);
		this.setBlock(world, i + 0, j + 1, k + 6, Blocks.air, 0);
		this.setBlock(world, i + 0, j + 1, k + 7, Blocks.air, 0);
		this.setBlock(world, i + 0, j + 1, k + 8, Blocks.air, 0);
		this.setBlock(world, i + 0, j + 2, k + 0, Blocks.air, 0);
		this.setBlock(world, i + 0, j + 2, k + 1, Blocks.air, 0);
		this.setBlock(world, i + 0, j + 2, k + 2, Blocks.air, 0);
		this.setBlock(world, i + 0, j + 2, k + 3, Blocks.air, 0);
		this.setBlock(world, i + 0, j + 2, k + 4, Blocks.air, 0);
		this.setBlock(world, i + 0, j + 2, k + 5, Blocks.air, 0);
		this.setBlock(world, i + 0, j + 2, k + 6, Blocks.air, 0);
		this.setBlock(world, i + 0, j + 2, k + 7, Blocks.air, 0);
		this.setBlock(world, i + 0, j + 2, k + 8, Blocks.air, 0);
		this.setBlock(world, i + 0, j + 3, k + 0, Blocks.air, 0);
		this.setBlock(world, i + 0, j + 3, k + 1, Blocks.sand, 0);
		this.setBlock(world, i + 0, j + 3, k + 2, Blocks.sand, 0);
		this.setBlock(world, i + 0, j + 3, k + 3, Blocks.sand, 0);
		this.setBlock(world, i + 0, j + 3, k + 4, Blocks.sand, 0);
		this.setBlock(world, i + 0, j + 3, k + 5, Blocks.sand, 0);
		this.setBlock(world, i + 0, j + 3, k + 6, Blocks.sand, 0);
		this.setBlock(world, i + 0, j + 3, k + 7, Blocks.sand, 0);
		this.setBlock(world, i + 0, j + 4, k + 1, Blocks.sand, 0);
		this.setBlock(world, i + 0, j + 4, k + 2, Blocks.sand, 0);
		this.setBlock(world, i + 0, j + 4, k + 3, Blocks.sand, 0);
		this.setBlock(world, i + 0, j + 4, k + 4, Blocks.sand, 0);
		this.setBlock(world, i + 0, j + 4, k + 5, Blocks.sand, 0);
		this.setBlock(world, i + 0, j + 4, k + 6, Blocks.sand, 0);
		this.setBlock(world, i + 0, j + 4, k + 7, Blocks.sand, 0);
		this.setBlock(world, i + 0, j + 3, k + 8, Blocks.air, 0);
		this.setBlock(world, i + 0, j + 4, k + 0, Blocks.air, 0);
		this.setBlock(world, i + 0, j + 4, k + 1, Blocks.air, 0);
		this.setBlock(world, i + 0, j + 4, k + 2, Blocks.air, 0);
		this.setBlock(world, i + 0, j + 4, k + 3, Blocks.air, 0);
		this.setBlock(world, i + 0, j + 4, k + 4, Blocks.air, 0);
		this.setBlock(world, i + 0, j + 4, k + 5, Blocks.air, 0);
		this.setBlock(world, i + 0, j + 4, k + 6, Blocks.air, 0);
		this.setBlock(world, i + 0, j + 4, k + 7, Blocks.air, 0);
		this.setBlock(world, i + 0, j + 4, k + 8, Blocks.air, 0);
		this.setBlock(world, i + 0, j + 5, k + 0, Blocks.air, 0);
		this.setBlock(world, i + 0, j + 5, k + 1, Blocks.air, 0);
		this.setBlock(world, i + 0, j + 5, k + 2, Blocks.air, 0);
		this.setBlock(world, i + 0, j + 5, k + 3, Blocks.air, 0);
		this.setBlock(world, i + 0, j + 5, k + 4, Blocks.air, 0);
		this.setBlock(world, i + 0, j + 5, k + 5, Blocks.air, 0);
		this.setBlock(world, i + 0, j + 5, k + 6, Blocks.air, 0);
		this.setBlock(world, i + 0, j + 5, k + 7, Blocks.air, 0);
		this.setBlock(world, i + 0, j + 5, k + 8, Blocks.air, 0);
		this.setBlock(world, i + 0, j + 6, k + 0, Blocks.air, 0);
		this.setBlock(world, i + 0, j + 6, k + 1, Blocks.air, 0);
		this.setBlock(world, i + 0, j + 6, k + 2, Blocks.air, 0);
		this.setBlock(world, i + 0, j + 6, k + 3, Blocks.air, 0);
		this.setBlock(world, i + 0, j + 6, k + 4, Blocks.air, 0);
		this.setBlock(world, i + 0, j + 6, k + 5, Blocks.air, 0);
		this.setBlock(world, i + 0, j + 6, k + 6, Blocks.air, 0);
		this.setBlock(world, i + 0, j + 6, k + 7, Blocks.air, 0);
		this.setBlock(world, i + 0, j + 6, k + 8, Blocks.air, 0);
		this.setBlock(world, i + 0, j + 7, k + 0, Blocks.air, 0);
		this.setBlock(world, i + 0, j + 7, k + 1, Blocks.air, 0);
		this.setBlock(world, i + 0, j + 7, k + 2, Blocks.air, 0);
		this.setBlock(world, i + 0, j + 7, k + 3, Blocks.air, 0);
		this.setBlock(world, i + 0, j + 7, k + 4, Blocks.air, 0);
		this.setBlock(world, i + 0, j + 7, k + 5, Blocks.air, 0);
		this.setBlock(world, i + 0, j + 7, k + 6, Blocks.air, 0);
		this.setBlock(world, i + 0, j + 7, k + 7, Blocks.air, 0);
		this.setBlock(world, i + 0, j + 7, k + 8, Blocks.air, 0);
		this.setBlock(world, i + 0, j + 8, k + 0, Blocks.air, 0);
		this.setBlock(world, i + 0, j + 8, k + 1, Blocks.air, 0);
		this.setBlock(world, i + 0, j + 8, k + 2, Blocks.air, 0);
		this.setBlock(world, i + 0, j + 8, k + 3, Blocks.air, 0);
		this.setBlock(world, i + 0, j + 8, k + 4, Blocks.air, 0);
		this.setBlock(world, i + 0, j + 8, k + 5, Blocks.air, 0);
		this.setBlock(world, i + 0, j + 8, k + 6, Blocks.air, 0);
		this.setBlock(world, i + 0, j + 8, k + 7, Blocks.air, 0);
		this.setBlock(world, i + 0, j + 8, k + 8, Blocks.air, 0);
		this.setBlock(world, i + 1, j + 0, k + 0, Blocks.air, 0);
		this.setBlock(world, i + 1, j + 0, k + 1, Blocks.sandstone, 0);
		this.setBlock(world, i + 1, j + 0, k + 2, Blocks.sandstone, 0);
		this.setBlock(world, i + 1, j + 0, k + 3, Blocks.sandstone, 0);
		this.setBlock(world, i + 1, j + 0, k + 4, Blocks.sandstone, 0);
		this.setBlock(world, i + 1, j + 0, k + 5, Blocks.sandstone, 0);
		this.setBlock(world, i + 1, j + 0, k + 6, Blocks.sandstone, 0);
		this.setBlock(world, i + 1, j + 0, k + 7, Blocks.sandstone, 0);
		this.setBlock(world, i + 1, j + 0, k + 8, Blocks.air, 0);
		this.setBlock(world, i + 1, j + 1, k + 0, Blocks.air, 0);
		this.setBlock(world, i + 1, j + 1, k + 1, Blocks.sandstone, 0);
		this.setBlock(world, i + 1, j + 1, k + 2, Blocks.sandstone, 0);
		this.setBlock(world, i + 1, j + 1, k + 3, Blocks.sandstone, 0);
		this.setBlock(world, i + 1, j + 1, k + 4, Blocks.sandstone, 0);
		this.setBlock(world, i + 1, j + 1, k + 5, Blocks.sandstone, 0);
		this.setBlock(world, i + 1, j + 1, k + 6, Blocks.sandstone, 0);
		this.setBlock(world, i + 1, j + 1, k + 7, Blocks.sandstone, 0);
		this.setBlock(world, i + 1, j + 1, k + 8, Blocks.air, 0);
		this.setBlock(world, i + 1, j + 2, k + 0, Blocks.air, 0);
		this.setBlock(world, i + 1, j + 2, k + 1, Blocks.sandstone, 0);
		this.setBlock(world, i + 1, j + 2, k + 2, Blocks.sandstone, 0);
		this.setBlock(world, i + 1, j + 2, k + 3, Blocks.sandstone, 0);
		this.setBlock(world, i + 1, j + 2, k + 4, Blocks.sandstone, 0);
		this.setBlock(world, i + 1, j + 2, k + 5, Blocks.sandstone, 0);
		this.setBlock(world, i + 1, j + 2, k + 6, Blocks.sandstone, 0);
		this.setBlock(world, i + 1, j + 2, k + 7, Blocks.sandstone, 0);
		this.setBlock(world, i + 1, j + 2, k + 8, Blocks.air, 0);
		this.setBlock(world, i + 1, j + 3, k + 0, Blocks.sand, 0);
		this.setBlock(world, i + 1, j + 4, k + 0, Blocks.sand, 0);
		this.setBlock(world, i + 1, j + 3, k + 1, Blocks.sandstone, 0);
		this.setBlock(world, i + 1, j + 3, k + 2, Blocks.sandstone, 0);
		this.setBlock(world, i + 1, j + 3, k + 3, Blocks.sandstone, 0);
		this.setBlock(world, i + 1, j + 3, k + 4, Blocks.sandstone, 0);
		this.setBlock(world, i + 1, j + 3, k + 5, Blocks.sandstone, 0);
		this.setBlock(world, i + 1, j + 3, k + 6, Blocks.sandstone, 0);
		this.setBlock(world, i + 1, j + 3, k + 7, Blocks.sandstone, 0);
		this.setBlock(world, i + 1, j + 3, k + 8, Blocks.sand, 0);
		this.setBlock(world, i + 1, j + 4, k + 8, Blocks.sand, 0);
		this.setBlock(world, i + 1, j + 4, k + 0, Blocks.air, 0);
		this.setBlock(world, i + 1, j + 4, k + 1, Blocks.sandstone, 0);
		this.setBlock(world, i + 1, j + 4, k + 2, Blocks.air, 0);
		this.setBlock(world, i + 1, j + 4, k + 3, Blocks.air, 0);
		this.setBlock(world, i + 1, j + 4, k + 4, Blocks.air, 0);
		this.setBlock(world, i + 1, j + 4, k + 5, Blocks.air, 0);
		this.setBlock(world, i + 1, j + 4, k + 6, Blocks.air, 0);
		this.setBlock(world, i + 1, j + 4, k + 7, Blocks.sandstone, 0);
		this.setBlock(world, i + 1, j + 4, k + 8, Blocks.air, 0);
		this.setBlock(world, i + 1, j + 5, k + 0, Blocks.air, 0);
		this.setBlock(world, i + 1, j + 5, k + 1, Blocks.sandstone, 0);
		this.setBlock(world, i + 1, j + 5, k + 2, Blocks.air, 0);
		this.setBlock(world, i + 1, j + 5, k + 3, Blocks.air, 0);
		this.setBlock(world, i + 1, j + 5, k + 4, Blocks.air, 0);
		this.setBlock(world, i + 1, j + 5, k + 5, Blocks.air, 0);
		this.setBlock(world, i + 1, j + 5, k + 6, Blocks.air, 0);
		this.setBlock(world, i + 1, j + 5, k + 7, Blocks.sandstone, 0);
		this.setBlock(world, i + 1, j + 5, k + 8, Blocks.air, 0);
		this.setBlock(world, i + 1, j + 6, k + 0, Blocks.air, 0);
		this.setBlock(world, i + 1, j + 6, k + 1, Blocks.sandstone, 0);
		this.setBlock(world, i + 1, j + 6, k + 2, Blocks.air, 0);
		this.setBlock(world, i + 1, j + 6, k + 3, Blocks.air, 0);
		this.setBlock(world, i + 1, j + 6, k + 4, Blocks.air, 0);
		this.setBlock(world, i + 1, j + 6, k + 5, Blocks.air, 0);
		this.setBlock(world, i + 1, j + 6, k + 6, Blocks.air, 0);
		this.setBlock(world, i + 1, j + 6, k + 7, Blocks.sandstone, 0);
		this.setBlock(world, i + 1, j + 6, k + 8, Blocks.air, 0);
		this.setBlock(world, i + 1, j + 7, k + 0, Blocks.air, 0);
		this.setBlock(world, i + 1, j + 7, k + 1, Blocks.stone_slab, 1);
		this.setBlock(world, i + 1, j + 7, k + 2, Blocks.sandstone, 0);
		this.setBlock(world, i + 1, j + 7, k + 3, Blocks.sandstone, 0);
		this.setBlock(world, i + 1, j + 7, k + 4, Blocks.stone_slab, 9);
		this.setBlock(world, i + 1, j + 7, k + 5, Blocks.sandstone, 0);
		this.setBlock(world, i + 1, j + 7, k + 6, Blocks.sandstone, 0);
		this.setBlock(world, i + 1, j + 7, k + 7, Blocks.stone_slab, 1);
		this.setBlock(world, i + 1, j + 7, k + 8, Blocks.air, 0);
		this.setBlock(world, i + 1, j + 8, k + 0, Blocks.air, 0);
		this.setBlock(world, i + 1, j + 8, k + 1, Blocks.air, 0);
		this.setBlock(world, i + 1, j + 8, k + 2, Blocks.air, 0);
		this.setBlock(world, i + 1, j + 8, k + 3, Blocks.air, 0);
		this.setBlock(world, i + 1, j + 8, k + 4, Blocks.air, 0);
		this.setBlock(world, i + 1, j + 8, k + 5, Blocks.air, 0);
		this.setBlock(world, i + 1, j + 8, k + 6, Blocks.air, 0);
		this.setBlock(world, i + 1, j + 8, k + 7, Blocks.air, 0);
		this.setBlock(world, i + 1, j + 8, k + 8, Blocks.air, 0);
		this.setBlock(world, i + 2, j + 0, k + 0, Blocks.air, 0);
		this.setBlock(world, i + 2, j + 0, k + 1, Blocks.sandstone, 0);
		this.setBlock(world, i + 2, j + 0, k + 2, Blocks.sandstone, 0);
		this.setBlock(world, i + 2, j + 0, k + 3, Blocks.sandstone, 0);
		this.setBlock(world, i + 2, j + 0, k + 4, Blocks.sandstone, 0);
		this.setBlock(world, i + 2, j + 0, k + 5, Blocks.sandstone, 0);
		this.setBlock(world, i + 2, j + 0, k + 6, Blocks.sandstone, 0);
		this.setBlock(world, i + 2, j + 0, k + 7, Blocks.sandstone, 0);
		this.setBlock(world, i + 2, j + 0, k + 8, Blocks.air, 0);
		this.setBlock(world, i + 2, j + 1, k + 0, Blocks.air, 0);
		this.setBlock(world, i + 2, j + 1, k + 1, Blocks.sandstone, 0);
		this.setBlock(world, i + 2, j + 1, k + 2, Blocks.sandstone, 0);
		this.setBlock(world, i + 2, j + 1, k + 3, Blocks.sandstone, 0);
		this.setBlock(world, i + 2, j + 1, k + 4, Blocks.sandstone, 0);
		this.setBlock(world, i + 2, j + 1, k + 5, Blocks.sandstone, 0);
		this.setBlock(world, i + 2, j + 1, k + 6, Blocks.sandstone, 0);
		this.setBlock(world, i + 2, j + 1, k + 7, Blocks.sandstone, 0);
		this.setBlock(world, i + 2, j + 1, k + 8, Blocks.air, 0);
		this.setBlock(world, i + 2, j + 2, k + 0, Blocks.air, 0);
		this.setBlock(world, i + 2, j + 2, k + 1, Blocks.sandstone, 0);
		this.setBlock(world, i + 2, j + 2, k + 2, Blocks.sandstone, 0);
		this.setBlock(world, i + 2, j + 2, k + 3, Blocks.sandstone, 0);
		this.setBlock(world, i + 2, j + 2, k + 4, Blocks.sandstone, 0);
		this.setBlock(world, i + 2, j + 2, k + 5, Blocks.sandstone, 0);
		this.setBlock(world, i + 2, j + 2, k + 6, Blocks.sandstone, 0);
		this.setBlock(world, i + 2, j + 2, k + 7, Blocks.sandstone, 0);
		this.setBlock(world, i + 2, j + 2, k + 8, Blocks.air, 0);
		this.setBlock(world, i + 2, j + 3, k + 0, Blocks.sand, 0);
		this.setBlock(world, i + 2, j + 4, k + 0, Blocks.sand, 0);
		this.setBlock(world, i + 2, j + 3, k + 1, Blocks.sandstone, 0);
		this.setBlock(world, i + 2, j + 3, k + 2, Blocks.sandstone, 0);
		this.setBlock(world, i + 2, j + 3, k + 3, Blocks.sandstone, 0);
		this.setBlock(world, i + 2, j + 3, k + 4, Blocks.sandstone, 0);
		this.setBlock(world, i + 2, j + 3, k + 5, Blocks.sandstone, 0);
		this.setBlock(world, i + 2, j + 3, k + 6, Blocks.sandstone, 0);
		this.setBlock(world, i + 2, j + 3, k + 7, Blocks.sandstone, 0);
		this.setBlock(world, i + 2, j + 3, k + 8, Blocks.sand, 0);
		this.setBlock(world, i + 2, j + 4, k + 8, Blocks.sand, 0);
		this.setBlock(world, i + 2, j + 4, k + 0, Blocks.air, 0);
		this.setBlock(world, i + 2, j + 4, k + 1, Blocks.air, 0);
		this.setBlock(world, i + 2, j + 4, k + 2, Blocks.air, 0);
		this.setBlock(world, i + 2, j + 4, k + 3, Blocks.sandstone_stairs, 0);
		this.setBlock(world, i + 2, j + 4, k + 4, Blocks.sandstone_stairs, 0);
		this.setBlock(world, i + 2, j + 4, k + 5, Blocks.sandstone_stairs, 0);
		this.setBlock(world, i + 2, j + 4, k + 6, Blocks.air, 0);
		this.setBlock(world, i + 2, j + 4, k + 7, Blocks.air, 0);
		this.setBlock(world, i + 2, j + 4, k + 8, Blocks.air, 0);
		this.setBlock(world, i + 2, j + 5, k + 0, Blocks.air, 0);
		this.setBlock(world, i + 2, j + 5, k + 1, Blocks.air, 0);
		this.setBlock(world, i + 2, j + 5, k + 2, Blocks.air, 0);
		this.setBlock(world, i + 2, j + 5, k + 3, Blocks.air, 0);
		this.setBlock(world, i + 2, j + 5, k + 4, Blocks.air, 0);
		this.setBlock(world, i + 2, j + 5, k + 5, Blocks.air, 0);
		this.setBlock(world, i + 2, j + 5, k + 6, Blocks.air, 0);
		this.setBlock(world, i + 2, j + 5, k + 7, Blocks.air, 0);
		this.setBlock(world, i + 2, j + 5, k + 8, Blocks.air, 0);
		this.setBlock(world, i + 2, j + 6, k + 0, Blocks.air, 0);
		this.setBlock(world, i + 2, j + 6, k + 1, Blocks.stone_slab, 9);
		this.setBlock(world, i + 2, j + 6, k + 2, Blocks.air, 0);
		this.setBlock(world, i + 2, j + 6, k + 3, Blocks.air, 0);
		this.setBlock(world, i + 2, j + 6, k + 4, Blocks.air, 0);
		this.setBlock(world, i + 2, j + 6, k + 5, Blocks.air, 0);
		this.setBlock(world, i + 2, j + 6, k + 6, Blocks.air, 0);
		this.setBlock(world, i + 2, j + 6, k + 7, Blocks.stone_slab, 9);
		this.setBlock(world, i + 2, j + 6, k + 8, Blocks.air, 0);
		this.setBlock(world, i + 2, j + 7, k + 0, Blocks.air, 0);
		this.setBlock(world, i + 2, j + 7, k + 1, Blocks.sandstone, 0);
		this.setBlock(world, i + 2, j + 7, k + 2, Blocks.sandstone, 0);
		this.setBlock(world, i + 2, j + 7, k + 3, Blocks.stone_slab, 9);
		this.setBlock(world, i + 2, j + 7, k + 4, Blocks.air, 0);
		this.setBlock(world, i + 2, j + 7, k + 5, Blocks.stone_slab, 9);
		this.setBlock(world, i + 2, j + 7, k + 6, Blocks.sandstone, 0);
		this.setBlock(world, i + 2, j + 7, k + 7, Blocks.sandstone, 0);
		this.setBlock(world, i + 2, j + 7, k + 8, Blocks.air, 0);
		this.setBlock(world, i + 2, j + 8, k + 0, Blocks.air, 0);
		this.setBlock(world, i + 2, j + 8, k + 1, Blocks.air, 0);
		this.setBlock(world, i + 2, j + 8, k + 2, Blocks.stone_slab, 1);
		this.setBlock(world, i + 2, j + 8, k + 3, Blocks.sandstone, 0);
		this.setBlock(world, i + 2, j + 8, k + 4, Blocks.sandstone, 0);
		this.setBlock(world, i + 2, j + 8, k + 5, Blocks.sandstone, 0);
		this.setBlock(world, i + 2, j + 8, k + 6, Blocks.stone_slab, 1);
		this.setBlock(world, i + 2, j + 8, k + 7, Blocks.air, 0);
		this.setBlock(world, i + 2, j + 8, k + 8, Blocks.air, 0);
		this.setBlock(world, i + 3, j + 0, k + 0, Blocks.air, 0);
		this.setBlock(world, i + 3, j + 0, k + 1, Blocks.sandstone, 0);
		this.setBlock(world, i + 3, j + 0, k + 2, Blocks.sandstone, 0);
		this.setBlock(world, i + 3, j + 0, k + 3, Blocks.sandstone, 0);
		this.setBlock(world, i + 3, j + 0, k + 4, Blocks.sandstone, 0);
		this.setBlock(world, i + 3, j + 0, k + 5, Blocks.sandstone, 0);
		this.setBlock(world, i + 3, j + 0, k + 6, Blocks.sandstone, 0);
		this.setBlock(world, i + 3, j + 0, k + 7, Blocks.sandstone, 0);
		this.setBlock(world, i + 3, j + 0, k + 8, Blocks.air, 0);
		this.setBlock(world, i + 3, j + 1, k + 0, Blocks.air, 0);
		this.setBlock(world, i + 3, j + 1, k + 1, Blocks.sandstone, 0);
		this.setBlock(world, i + 3, j + 1, k + 2, Blocks.sandstone, 0);
		this.setBlock(world, i + 3, j + 1, k + 3, Blocks.sandstone, 0);
		this.setBlock(world, i + 3, j + 1, k + 4, Blocks.sandstone, 0);
		this.setBlock(world, i + 3, j + 1, k + 5, Blocks.sandstone, 0);
		this.setBlock(world, i + 3, j + 1, k + 6, Blocks.sandstone, 0);
		this.setBlock(world, i + 3, j + 1, k + 7, Blocks.sandstone, 0);
		this.setBlock(world, i + 3, j + 1, k + 8, Blocks.air, 0);
		this.setBlock(world, i + 3, j + 2, k + 0, Blocks.air, 0);
		this.setBlock(world, i + 3, j + 2, k + 1, Blocks.sandstone, 0);
		this.setBlock(world, i + 3, j + 2, k + 2, Blocks.sandstone, 0);
		this.setBlock(world, i + 3, j + 2, k + 6, Blocks.sandstone, 0);
		this.setBlock(world, i + 3, j + 2, k + 7, Blocks.sandstone, 0);
		this.setBlock(world, i + 3, j + 2, k + 8, Blocks.air, 0);
		this.setBlock(world, i + 3, j + 3, k + 0, Blocks.sand, 0);
		this.setBlock(world, i + 3, j + 4, k + 0, Blocks.sand, 0);
		this.setBlock(world, i + 3, j + 3, k + 1, Blocks.sandstone, 0);
		this.setBlock(world, i + 3, j + 3, k + 2, Blocks.sandstone, 0);
		this.setBlock(world, i + 3, j + 3, k + 6, Blocks.sandstone, 0);
		this.setBlock(world, i + 3, j + 3, k + 7, Blocks.sandstone, 0);
		this.setBlock(world, i + 3, j + 3, k + 8, Blocks.sand, 0);
		this.setBlock(world, i + 3, j + 4, k + 8, Blocks.sand, 0);
		this.setBlock(world, i + 3, j + 4, k + 0, Blocks.air, 0);
		this.setBlock(world, i + 3, j + 4, k + 1, Blocks.air, 0);
		this.setBlock(world, i + 3, j + 4, k + 2, Blocks.sandstone_stairs, 2);
		this.setBlock(world, i + 3, j + 4, k + 6, Blocks.sandstone_stairs, 3);
		this.setBlock(world, i + 3, j + 4, k + 7, Blocks.air, 0);
		this.setBlock(world, i + 3, j + 4, k + 8, Blocks.air, 0);
		this.setBlock(world, i + 3, j + 5, k + 0, Blocks.air, 0);
		this.setBlock(world, i + 3, j + 5, k + 1, Blocks.air, 0);
		this.setBlock(world, i + 3, j + 5, k + 2, Blocks.air, 0);
		this.setBlock(world, i + 3, j + 5, k + 3, Blocks.air, 0);
		this.setBlock(world, i + 3, j + 5, k + 4, Blocks.air, 0);
		this.setBlock(world, i + 3, j + 5, k + 5, Blocks.air, 0);
		this.setBlock(world, i + 3, j + 5, k + 6, Blocks.air, 0);
		this.setBlock(world, i + 3, j + 5, k + 7, Blocks.air, 0);
		this.setBlock(world, i + 3, j + 5, k + 8, Blocks.air, 0);
		this.setBlock(world, i + 3, j + 6, k + 0, Blocks.air, 0);
		this.setBlock(world, i + 3, j + 6, k + 1, Blocks.air, 0);
		this.setBlock(world, i + 3, j + 6, k + 2, Blocks.air, 0);
		this.setBlock(world, i + 3, j + 6, k + 3, Blocks.air, 0);
		this.setBlock(world, i + 3, j + 6, k + 4, Blocks.air, 0);
		this.setBlock(world, i + 3, j + 6, k + 5, Blocks.air, 0);
		this.setBlock(world, i + 3, j + 6, k + 6, Blocks.air, 0);
		this.setBlock(world, i + 3, j + 6, k + 7, Blocks.air, 0);
		this.setBlock(world, i + 3, j + 6, k + 8, Blocks.air, 0);
		this.setBlock(world, i + 3, j + 7, k + 0, Blocks.air, 0);
		this.setBlock(world, i + 3, j + 7, k + 1, Blocks.sandstone, 0);
		this.setBlock(world, i + 3, j + 7, k + 2, Blocks.stone_slab, 9);
		this.setBlock(world, i + 3, j + 7, k + 3, Blocks.air, 0);
		this.setBlock(world, i + 3, j + 7, k + 4, Blocks.air, 0);
		this.setBlock(world, i + 3, j + 7, k + 5, Blocks.air, 0);
		this.setBlock(world, i + 3, j + 7, k + 6, Blocks.stone_slab, 9);
		this.setBlock(world, i + 3, j + 7, k + 7, Blocks.sandstone, 0);
		this.setBlock(world, i + 3, j + 7, k + 8, Blocks.air, 0);
		this.setBlock(world, i + 3, j + 8, k + 0, Blocks.air, 0);
		this.setBlock(world, i + 3, j + 8, k + 1, Blocks.air, 0);
		this.setBlock(world, i + 3, j + 8, k + 2, Blocks.sandstone, 0);
		this.setBlock(world, i + 3, j + 8, k + 3, Blocks.leaves, 12);
		this.setBlock(world, i + 3, j + 8, k + 4, Blocks.leaves, 12);
		this.setBlock(world, i + 3, j + 8, k + 5, Blocks.leaves, 12);
		this.setBlock(world, i + 3, j + 8, k + 6, Blocks.sandstone, 0);
		this.setBlock(world, i + 3, j + 8, k + 7, Blocks.air, 0);
		this.setBlock(world, i + 3, j + 8, k + 8, Blocks.air, 0);
		this.setBlock(world, i + 4, j + 0, k + 0, Blocks.air, 0);
		this.setBlock(world, i + 4, j + 0, k + 1, Blocks.sandstone, 0);
		this.setBlock(world, i + 4, j + 0, k + 2, Blocks.sandstone, 0);
		this.setBlock(world, i + 4, j + 0, k + 3, Blocks.sandstone, 0);
		this.setBlock(world, i + 4, j + 0, k + 4, Blocks.sandstone, 0);
		this.setBlock(world, i + 4, j + 0, k + 5, Blocks.sandstone, 0);
		this.setBlock(world, i + 4, j + 0, k + 6, Blocks.sandstone, 0);
		this.setBlock(world, i + 4, j + 0, k + 7, Blocks.sandstone, 0);
		this.setBlock(world, i + 4, j + 0, k + 8, Blocks.air, 0);
		this.setBlock(world, i + 4, j + 1, k + 0, Blocks.air, 0);
		this.setBlock(world, i + 4, j + 1, k + 1, Blocks.sandstone, 0);
		this.setBlock(world, i + 4, j + 1, k + 2, Blocks.sandstone, 0);
		this.setBlock(world, i + 4, j + 1, k + 3, Blocks.sandstone, 0);
		this.setBlock(world, i + 4, j + 1, k + 4, Blocks.sandstone, 0);
		this.setBlock(world, i + 4, j + 1, k + 5, Blocks.sandstone, 0);
		this.setBlock(world, i + 4, j + 1, k + 6, Blocks.sandstone, 0);
		this.setBlock(world, i + 4, j + 1, k + 7, Blocks.sandstone, 0);
		this.setBlock(world, i + 4, j + 1, k + 8, Blocks.air, 0);
		this.setBlock(world, i + 4, j + 2, k + 0, Blocks.air, 0);
		this.setBlock(world, i + 4, j + 2, k + 1, Blocks.sandstone, 0);
		this.setBlock(world, i + 4, j + 2, k + 2, Blocks.sandstone, 0);
		this.setBlock(world, i + 4, j + 2, k + 6, Blocks.sandstone, 0);
		this.setBlock(world, i + 4, j + 2, k + 7, Blocks.sandstone, 0);
		this.setBlock(world, i + 4, j + 2, k + 8, Blocks.air, 0);
		this.setBlock(world, i + 4, j + 3, k + 0, Blocks.sand, 0);
		this.setBlock(world, i + 4, j + 4, k + 0, Blocks.sand, 0);
		this.setBlock(world, i + 4, j + 3, k + 1, Blocks.sandstone, 0);
		this.setBlock(world, i + 4, j + 3, k + 2, Blocks.sandstone, 0);
		this.setBlock(world, i + 4, j + 3, k + 6, Blocks.sandstone, 0);
		this.setBlock(world, i + 4, j + 3, k + 7, Blocks.sandstone, 0);
		this.setBlock(world, i + 4, j + 3, k + 8, Blocks.sand, 0);
		this.setBlock(world, i + 4, j + 4, k + 8, Blocks.sand, 0);
		this.setBlock(world, i + 4, j + 4, k + 0, Blocks.air, 0);
		this.setBlock(world, i + 4, j + 4, k + 1, Blocks.air, 0);
		this.setBlock(world, i + 4, j + 4, k + 2, Blocks.sandstone_stairs, 2);
		this.setBlock(world, i + 4, j + 4, k + 6, Blocks.sandstone_stairs, 3);
		this.setBlock(world, i + 4, j + 4, k + 7, Blocks.air, 0);
		this.setBlock(world, i + 4, j + 4, k + 8, Blocks.air, 0);
		this.setBlock(world, i + 4, j + 5, k + 0, Blocks.air, 0);
		this.setBlock(world, i + 4, j + 5, k + 1, Blocks.air, 0);
		this.setBlock(world, i + 4, j + 5, k + 2, Blocks.air, 0);
		this.setBlock(world, i + 4, j + 5, k + 3, Blocks.air, 0);
		this.setBlock(world, i + 4, j + 5, k + 4, Blocks.air, 0);
		this.setBlock(world, i + 4, j + 5, k + 5, Blocks.air, 0);
		this.setBlock(world, i + 4, j + 5, k + 6, Blocks.air, 0);
		this.setBlock(world, i + 4, j + 5, k + 7, Blocks.air, 0);
		this.setBlock(world, i + 4, j + 5, k + 8, Blocks.air, 0);
		this.setBlock(world, i + 4, j + 6, k + 0, Blocks.air, 0);
		this.setBlock(world, i + 4, j + 6, k + 1, Blocks.air, 0);
		this.setBlock(world, i + 4, j + 6, k + 2, Blocks.air, 0);
		this.setBlock(world, i + 4, j + 6, k + 3, Blocks.air, 0);
		this.setBlock(world, i + 4, j + 6, k + 4, Blocks.air, 0);
		this.setBlock(world, i + 4, j + 6, k + 5, Blocks.air, 0);
		this.setBlock(world, i + 4, j + 6, k + 6, Blocks.air, 0);
		this.setBlock(world, i + 4, j + 6, k + 7, Blocks.air, 0);
		this.setBlock(world, i + 4, j + 6, k + 8, Blocks.air, 0);
		this.setBlock(world, i + 4, j + 7, k + 0, Blocks.air, 0);
		this.setBlock(world, i + 4, j + 7, k + 1, Blocks.stone_slab, 9);
		this.setBlock(world, i + 4, j + 7, k + 2, Blocks.air, 0);
		this.setBlock(world, i + 4, j + 7, k + 3, Blocks.air, 0);
		this.setBlock(world, i + 4, j + 7, k + 4, Blocks.air, 0);
		this.setBlock(world, i + 4, j + 7, k + 5, Blocks.air, 0);
		this.setBlock(world, i + 4, j + 7, k + 6, Blocks.air, 0);
		this.setBlock(world, i + 4, j + 7, k + 7, Blocks.stone_slab, 9);
		this.setBlock(world, i + 4, j + 7, k + 8, Blocks.air, 0);
		this.setBlock(world, i + 4, j + 8, k + 0, Blocks.air, 0);
		this.setBlock(world, i + 4, j + 8, k + 1, Blocks.air, 0);
		this.setBlock(world, i + 4, j + 8, k + 2, Blocks.sandstone, 0);
		this.setBlock(world, i + 4, j + 8, k + 3, Blocks.leaves, 12);
		this.setBlock(world, i + 4, j + 8, k + 4, Blocks.leaves, 12);
		this.setBlock(world, i + 4, j + 8, k + 5, Blocks.leaves, 12);
		this.setBlock(world, i + 4, j + 8, k + 6, Blocks.sandstone, 0);
		this.setBlock(world, i + 4, j + 8, k + 7, Blocks.air, 0);
		this.setBlock(world, i + 4, j + 8, k + 8, Blocks.air, 0);
		this.setBlock(world, i + 5, j + 0, k + 0, Blocks.air, 0);
		this.setBlock(world, i + 5, j + 0, k + 1, Blocks.sandstone, 0);
		this.setBlock(world, i + 5, j + 0, k + 2, Blocks.sandstone, 0);
		this.setBlock(world, i + 5, j + 0, k + 3, Blocks.sandstone, 0);
		this.setBlock(world, i + 5, j + 0, k + 4, Blocks.sandstone, 0);
		this.setBlock(world, i + 5, j + 0, k + 5, Blocks.sandstone, 0);
		this.setBlock(world, i + 5, j + 0, k + 6, Blocks.sandstone, 0);
		this.setBlock(world, i + 5, j + 0, k + 7, Blocks.sandstone, 0);
		this.setBlock(world, i + 5, j + 0, k + 8, Blocks.air, 0);
		this.setBlock(world, i + 5, j + 1, k + 0, Blocks.air, 0);
		this.setBlock(world, i + 5, j + 1, k + 1, Blocks.sandstone, 0);
		this.setBlock(world, i + 5, j + 1, k + 2, Blocks.sandstone, 0);
		this.setBlock(world, i + 5, j + 1, k + 3, Blocks.sandstone, 0);
		this.setBlock(world, i + 5, j + 1, k + 4, Blocks.sandstone, 0);
		this.setBlock(world, i + 5, j + 1, k + 5, Blocks.sandstone, 0);
		this.setBlock(world, i + 5, j + 1, k + 6, Blocks.sandstone, 0);
		this.setBlock(world, i + 5, j + 1, k + 7, Blocks.sandstone, 0);
		this.setBlock(world, i + 5, j + 1, k + 8, Blocks.air, 0);
		this.setBlock(world, i + 5, j + 2, k + 0, Blocks.air, 0);
		this.setBlock(world, i + 5, j + 2, k + 1, Blocks.sandstone, 0);
		this.setBlock(world, i + 5, j + 2, k + 2, Blocks.sandstone, 0);
		this.setBlock(world, i + 5, j + 2, k + 6, Blocks.sandstone, 0);
		this.setBlock(world, i + 5, j + 2, k + 7, Blocks.sandstone, 0);
		this.setBlock(world, i + 5, j + 2, k + 8, Blocks.air, 0);
		this.setBlock(world, i + 5, j + 3, k + 0, Blocks.sand, 0);
		this.setBlock(world, i + 5, j + 43, k + 0, Blocks.sand, 0);
		this.setBlock(world, i + 5, j + 3, k + 1, Blocks.sandstone, 0);
		this.setBlock(world, i + 5, j + 3, k + 2, Blocks.sandstone, 0);
		this.setBlock(world, i + 5, j + 3, k + 6, Blocks.sandstone, 0);
		this.setBlock(world, i + 5, j + 3, k + 7, Blocks.sandstone, 0);
		this.setBlock(world, i + 5, j + 3, k + 8, Blocks.sand, 0);
		this.setBlock(world, i + 5, j + 4, k + 8, Blocks.sand, 0);
		this.setBlock(world, i + 5, j + 4, k + 0, Blocks.air, 0);
		this.setBlock(world, i + 5, j + 4, k + 1, Blocks.air, 0);
		this.setBlock(world, i + 5, j + 4, k + 2, Blocks.sandstone_stairs, 2);
		this.setBlock(world, i + 5, j + 4, k + 6, Blocks.sandstone_stairs, 3);
		this.setBlock(world, i + 5, j + 4, k + 7, Blocks.air, 0);
		this.setBlock(world, i + 5, j + 4, k + 8, Blocks.air, 0);
		this.setBlock(world, i + 5, j + 5, k + 0, Blocks.air, 0);
		this.setBlock(world, i + 5, j + 5, k + 1, Blocks.air, 0);
		this.setBlock(world, i + 5, j + 5, k + 2, Blocks.air, 0);
		this.setBlock(world, i + 5, j + 5, k + 3, Blocks.air, 0);
		this.setBlock(world, i + 5, j + 5, k + 4, Blocks.air, 0);
		this.setBlock(world, i + 5, j + 5, k + 5, Blocks.air, 0);
		this.setBlock(world, i + 5, j + 5, k + 6, Blocks.air, 0);
		this.setBlock(world, i + 5, j + 5, k + 7, Blocks.air, 0);
		this.setBlock(world, i + 5, j + 5, k + 8, Blocks.air, 0);
		this.setBlock(world, i + 5, j + 6, k + 0, Blocks.air, 0);
		this.setBlock(world, i + 5, j + 6, k + 1, Blocks.air, 0);
		this.setBlock(world, i + 5, j + 6, k + 2, Blocks.air, 0);
		this.setBlock(world, i + 5, j + 6, k + 3, Blocks.air, 0);
		this.setBlock(world, i + 5, j + 6, k + 4, Blocks.air, 0);
		this.setBlock(world, i + 5, j + 6, k + 5, Blocks.air, 0);
		this.setBlock(world, i + 5, j + 6, k + 6, Blocks.air, 0);
		this.setBlock(world, i + 5, j + 6, k + 7, Blocks.air, 0);
		this.setBlock(world, i + 5, j + 6, k + 8, Blocks.air, 0);
		this.setBlock(world, i + 5, j + 7, k + 0, Blocks.air, 0);
		this.setBlock(world, i + 5, j + 7, k + 1, Blocks.sandstone, 0);
		this.setBlock(world, i + 5, j + 7, k + 2, Blocks.stone_slab, 9);
		this.setBlock(world, i + 5, j + 7, k + 3, Blocks.air, 0);
		this.setBlock(world, i + 5, j + 7, k + 4, Blocks.air, 0);
		this.setBlock(world, i + 5, j + 7, k + 5, Blocks.air, 0);
		this.setBlock(world, i + 5, j + 7, k + 6, Blocks.stone_slab, 9);
		this.setBlock(world, i + 5, j + 7, k + 7, Blocks.sandstone, 0);
		this.setBlock(world, i + 5, j + 7, k + 8, Blocks.air, 0);
		this.setBlock(world, i + 5, j + 8, k + 0, Blocks.air, 0);
		this.setBlock(world, i + 5, j + 8, k + 1, Blocks.air, 0);
		this.setBlock(world, i + 5, j + 8, k + 2, Blocks.sandstone, 0);
		this.setBlock(world, i + 5, j + 8, k + 3, Blocks.leaves, 12);
		this.setBlock(world, i + 5, j + 8, k + 4, Blocks.leaves, 12);
		this.setBlock(world, i + 5, j + 8, k + 5, Blocks.leaves, 12);
		this.setBlock(world, i + 5, j + 8, k + 6, Blocks.sandstone, 0);
		this.setBlock(world, i + 5, j + 8, k + 7, Blocks.air, 0);
		this.setBlock(world, i + 5, j + 8, k + 8, Blocks.air, 0);
		this.setBlock(world, i + 6, j + 0, k + 0, Blocks.air, 0);
		this.setBlock(world, i + 6, j + 0, k + 1, Blocks.sandstone, 0);
		this.setBlock(world, i + 6, j + 0, k + 2, Blocks.sandstone, 0);
		this.setBlock(world, i + 6, j + 0, k + 3, Blocks.sandstone, 0);
		this.setBlock(world, i + 6, j + 0, k + 4, Blocks.sandstone, 0);
		this.setBlock(world, i + 6, j + 0, k + 5, Blocks.sandstone, 0);
		this.setBlock(world, i + 6, j + 0, k + 6, Blocks.sandstone, 0);
		this.setBlock(world, i + 6, j + 0, k + 7, Blocks.sandstone, 0);
		this.setBlock(world, i + 6, j + 0, k + 8, Blocks.air, 0);
		this.setBlock(world, i + 6, j + 1, k + 0, Blocks.air, 0);
		this.setBlock(world, i + 6, j + 1, k + 1, Blocks.sandstone, 0);
		this.setBlock(world, i + 6, j + 1, k + 2, Blocks.sandstone, 0);
		this.setBlock(world, i + 6, j + 1, k + 3, Blocks.sandstone, 0);
		this.setBlock(world, i + 6, j + 1, k + 4, Blocks.sandstone, 0);
		this.setBlock(world, i + 6, j + 1, k + 5, Blocks.sandstone, 0);
		this.setBlock(world, i + 6, j + 1, k + 6, Blocks.sandstone, 0);
		this.setBlock(world, i + 6, j + 1, k + 7, Blocks.sandstone, 0);
		this.setBlock(world, i + 6, j + 1, k + 8, Blocks.air, 0);
		this.setBlock(world, i + 6, j + 2, k + 0, Blocks.air, 0);
		this.setBlock(world, i + 6, j + 2, k + 1, Blocks.sandstone, 0);
		this.setBlock(world, i + 6, j + 2, k + 2, Blocks.sandstone, 0);
		this.setBlock(world, i + 6, j + 2, k + 3, Blocks.sandstone, 0);
		this.setBlock(world, i + 6, j + 2, k + 4, Blocks.sandstone, 0);
		this.setBlock(world, i + 6, j + 2, k + 5, Blocks.sandstone, 0);
		this.setBlock(world, i + 6, j + 2, k + 6, Blocks.sandstone, 0);
		this.setBlock(world, i + 6, j + 2, k + 7, Blocks.sandstone, 0);
		this.setBlock(world, i + 6, j + 2, k + 8, Blocks.air, 0);
		this.setBlock(world, i + 6, j + 3, k + 0, Blocks.sand, 0);
		this.setBlock(world, i + 6, j + 4, k + 0, Blocks.sand, 0);
		this.setBlock(world, i + 6, j + 3, k + 1, Blocks.sandstone, 0);
		this.setBlock(world, i + 6, j + 3, k + 2, Blocks.sandstone, 0);
		this.setBlock(world, i + 6, j + 3, k + 3, Blocks.sandstone, 0);
		this.setBlock(world, i + 6, j + 3, k + 4, Blocks.sandstone, 0);
		this.setBlock(world, i + 6, j + 3, k + 5, Blocks.sandstone, 0);
		this.setBlock(world, i + 6, j + 3, k + 6, Blocks.sandstone, 0);
		this.setBlock(world, i + 6, j + 3, k + 7, Blocks.sandstone, 0);
		this.setBlock(world, i + 6, j + 3, k + 8, Blocks.sand, 0);
		this.setBlock(world, i + 6, j + 4, k + 8, Blocks.sand, 0);
		this.setBlock(world, i + 6, j + 4, k + 0, Blocks.air, 0);
		this.setBlock(world, i + 6, j + 4, k + 1, Blocks.air, 0);
		this.setBlock(world, i + 6, j + 4, k + 2, Blocks.air, 0);
		this.setBlock(world, i + 6, j + 4, k + 3, Blocks.sandstone_stairs, 1);
		this.setBlock(world, i + 6, j + 4, k + 4, Blocks.sandstone_stairs, 1);
		this.setBlock(world, i + 6, j + 4, k + 5, Blocks.sandstone_stairs, 1);
		this.setBlock(world, i + 6, j + 4, k + 6, Blocks.air, 0);
		this.setBlock(world, i + 6, j + 4, k + 7, Blocks.air, 0);
		this.setBlock(world, i + 6, j + 4, k + 8, Blocks.air, 0);
		this.setBlock(world, i + 6, j + 5, k + 0, Blocks.air, 0);
		this.setBlock(world, i + 6, j + 5, k + 1, Blocks.air, 0);
		this.setBlock(world, i + 6, j + 5, k + 2, Blocks.air, 0);
		this.setBlock(world, i + 6, j + 5, k + 3, Blocks.air, 0);
		this.setBlock(world, i + 6, j + 5, k + 4, Blocks.air, 0);
		this.setBlock(world, i + 6, j + 5, k + 5, Blocks.air, 0);
		this.setBlock(world, i + 6, j + 5, k + 6, Blocks.air, 0);
		this.setBlock(world, i + 6, j + 5, k + 7, Blocks.air, 0);
		this.setBlock(world, i + 6, j + 5, k + 8, Blocks.air, 0);
		this.setBlock(world, i + 6, j + 6, k + 0, Blocks.air, 0);
		this.setBlock(world, i + 6, j + 6, k + 1, Blocks.stone_slab, 9);
		this.setBlock(world, i + 6, j + 6, k + 2, Blocks.air, 0);
		this.setBlock(world, i + 6, j + 6, k + 3, Blocks.air, 0);
		this.setBlock(world, i + 6, j + 6, k + 4, Blocks.air, 0);
		this.setBlock(world, i + 6, j + 6, k + 5, Blocks.air, 0);
		this.setBlock(world, i + 6, j + 6, k + 6, Blocks.air, 0);
		this.setBlock(world, i + 6, j + 6, k + 7, Blocks.stone_slab, 9);
		this.setBlock(world, i + 6, j + 6, k + 8, Blocks.air, 0);
		this.setBlock(world, i + 6, j + 7, k + 0, Blocks.air, 0);
		this.setBlock(world, i + 6, j + 7, k + 1, Blocks.sandstone, 0);
		this.setBlock(world, i + 6, j + 7, k + 2, Blocks.sandstone, 0);
		this.setBlock(world, i + 6, j + 7, k + 3, Blocks.stone_slab, 9);
		this.setBlock(world, i + 6, j + 7, k + 4, Blocks.air, 0);
		this.setBlock(world, i + 6, j + 7, k + 5, Blocks.stone_slab, 9);
		this.setBlock(world, i + 6, j + 7, k + 6, Blocks.sandstone, 0);
		this.setBlock(world, i + 6, j + 7, k + 7, Blocks.sandstone, 0);
		this.setBlock(world, i + 6, j + 7, k + 8, Blocks.air, 0);
		this.setBlock(world, i + 6, j + 8, k + 0, Blocks.air, 0);
		this.setBlock(world, i + 6, j + 8, k + 1, Blocks.air, 0);
		this.setBlock(world, i + 6, j + 8, k + 2, Blocks.stone_slab, 1);
		this.setBlock(world, i + 6, j + 8, k + 3, Blocks.sandstone, 0);
		this.setBlock(world, i + 6, j + 8, k + 4, Blocks.sandstone, 0);
		this.setBlock(world, i + 6, j + 8, k + 5, Blocks.sandstone, 0);
		this.setBlock(world, i + 6, j + 8, k + 6, Blocks.stone_slab, 1);
		this.setBlock(world, i + 6, j + 8, k + 7, Blocks.air, 0);
		this.setBlock(world, i + 6, j + 8, k + 8, Blocks.air, 0);
		this.setBlock(world, i + 7, j + 0, k + 0, Blocks.air, 0);
		this.setBlock(world, i + 7, j + 0, k + 1, Blocks.sandstone, 0);
		this.setBlock(world, i + 7, j + 0, k + 2, Blocks.sandstone, 0);
		this.setBlock(world, i + 7, j + 0, k + 3, Blocks.sandstone, 0);
		this.setBlock(world, i + 7, j + 0, k + 4, Blocks.sandstone, 0);
		this.setBlock(world, i + 7, j + 0, k + 5, Blocks.sandstone, 0);
		this.setBlock(world, i + 7, j + 0, k + 6, Blocks.sandstone, 0);
		this.setBlock(world, i + 7, j + 0, k + 7, Blocks.sandstone, 0);
		this.setBlock(world, i + 7, j + 0, k + 8, Blocks.air, 0);
		this.setBlock(world, i + 7, j + 1, k + 0, Blocks.air, 0);
		this.setBlock(world, i + 7, j + 1, k + 1, Blocks.sandstone, 0);
		this.setBlock(world, i + 7, j + 1, k + 2, Blocks.sandstone, 0);
		this.setBlock(world, i + 7, j + 1, k + 3, Blocks.sandstone, 0);
		this.setBlock(world, i + 7, j + 1, k + 4, Blocks.sandstone, 0);
		this.setBlock(world, i + 7, j + 1, k + 5, Blocks.sandstone, 0);
		this.setBlock(world, i + 7, j + 1, k + 6, Blocks.sandstone, 0);
		this.setBlock(world, i + 7, j + 1, k + 7, Blocks.sandstone, 0);
		this.setBlock(world, i + 7, j + 1, k + 8, Blocks.air, 0);
		this.setBlock(world, i + 7, j + 2, k + 0, Blocks.air, 0);
		this.setBlock(world, i + 7, j + 2, k + 1, Blocks.sandstone, 0);
		this.setBlock(world, i + 7, j + 2, k + 2, Blocks.sandstone, 0);
		this.setBlock(world, i + 7, j + 2, k + 3, Blocks.sandstone, 0);
		this.setBlock(world, i + 7, j + 2, k + 4, Blocks.sandstone, 0);
		this.setBlock(world, i + 7, j + 2, k + 5, Blocks.sandstone, 0);
		this.setBlock(world, i + 7, j + 2, k + 6, Blocks.sandstone, 0);
		this.setBlock(world, i + 7, j + 2, k + 7, Blocks.sandstone, 0);
		this.setBlock(world, i + 7, j + 2, k + 8, Blocks.air, 0);
		this.setBlock(world, i + 7, j + 3, k + 0, Blocks.sand, 0);
		this.setBlock(world, i + 7, j + 4, k + 0, Blocks.sand, 0);
		this.setBlock(world, i + 7, j + 3, k + 1, Blocks.sandstone, 0);
		this.setBlock(world, i + 7, j + 3, k + 2, Blocks.sandstone, 0);
		this.setBlock(world, i + 7, j + 3, k + 3, Blocks.sandstone, 0);
		this.setBlock(world, i + 7, j + 3, k + 4, Blocks.sandstone, 0);
		this.setBlock(world, i + 7, j + 3, k + 5, Blocks.sandstone, 0);
		this.setBlock(world, i + 7, j + 3, k + 6, Blocks.sandstone, 0);
		this.setBlock(world, i + 7, j + 3, k + 7, Blocks.sandstone, 0);
		this.setBlock(world, i + 7, j + 3, k + 8, Blocks.sand, 0);
		this.setBlock(world, i + 7, j + 4, k + 8, Blocks.sand, 0);
		this.setBlock(world, i + 7, j + 4, k + 0, Blocks.air, 0);
		this.setBlock(world, i + 7, j + 4, k + 1, Blocks.sandstone, 0);
		this.setBlock(world, i + 7, j + 4, k + 2, Blocks.air, 0);
		this.setBlock(world, i + 7, j + 4, k + 3, Blocks.air, 0);
		this.setBlock(world, i + 7, j + 4, k + 4, Blocks.air, 0);
		this.setBlock(world, i + 7, j + 4, k + 5, Blocks.air, 0);
		this.setBlock(world, i + 7, j + 4, k + 6, Blocks.air, 0);
		this.setBlock(world, i + 7, j + 4, k + 7, Blocks.sandstone, 0);
		this.setBlock(world, i + 7, j + 4, k + 8, Blocks.air, 0);
		this.setBlock(world, i + 7, j + 5, k + 0, Blocks.air, 0);
		this.setBlock(world, i + 7, j + 5, k + 1, Blocks.sandstone, 0);
		this.setBlock(world, i + 7, j + 5, k + 2, Blocks.air, 0);
		this.setBlock(world, i + 7, j + 5, k + 3, Blocks.air, 0);
		this.setBlock(world, i + 7, j + 5, k + 4, Blocks.air, 0);
		this.setBlock(world, i + 7, j + 5, k + 5, Blocks.air, 0);
		this.setBlock(world, i + 7, j + 5, k + 6, Blocks.air, 0);
		this.setBlock(world, i + 7, j + 5, k + 7, Blocks.sandstone, 0);
		this.setBlock(world, i + 7, j + 5, k + 8, Blocks.air, 0);
		this.setBlock(world, i + 7, j + 6, k + 0, Blocks.air, 0);
		this.setBlock(world, i + 7, j + 6, k + 1, Blocks.sandstone, 0);
		this.setBlock(world, i + 7, j + 6, k + 2, Blocks.stone_slab, 9);
		this.setBlock(world, i + 7, j + 6, k + 3, Blocks.air, 0);
		this.setBlock(world, i + 7, j + 6, k + 4, Blocks.air, 0);
		this.setBlock(world, i + 7, j + 6, k + 5, Blocks.air, 0);
		this.setBlock(world, i + 7, j + 6, k + 6, Blocks.stone_slab, 9);
		this.setBlock(world, i + 7, j + 6, k + 7, Blocks.sandstone, 0);
		this.setBlock(world, i + 7, j + 6, k + 8, Blocks.air, 0);
		this.setBlock(world, i + 7, j + 7, k + 0, Blocks.air, 0);
		this.setBlock(world, i + 7, j + 7, k + 1, Blocks.stone_slab, 1);
		this.setBlock(world, i + 7, j + 7, k + 2, Blocks.sandstone, 0);
		this.setBlock(world, i + 7, j + 7, k + 3, Blocks.sandstone, 0);
		this.setBlock(world, i + 7, j + 7, k + 4, Blocks.stone_slab, 9);
		this.setBlock(world, i + 7, j + 7, k + 5, Blocks.sandstone, 0);
		this.setBlock(world, i + 7, j + 7, k + 6, Blocks.sandstone, 0);
		this.setBlock(world, i + 7, j + 7, k + 7, Blocks.stone_slab, 1);
		this.setBlock(world, i + 7, j + 7, k + 8, Blocks.air, 0);
		this.setBlock(world, i + 7, j + 8, k + 0, Blocks.air, 0);
		this.setBlock(world, i + 7, j + 8, k + 1, Blocks.air, 0);
		this.setBlock(world, i + 7, j + 8, k + 2, Blocks.air, 0);
		this.setBlock(world, i + 7, j + 8, k + 3, Blocks.air, 0);
		this.setBlock(world, i + 7, j + 8, k + 4, Blocks.air, 0);
		this.setBlock(world, i + 7, j + 8, k + 5, Blocks.air, 0);
		this.setBlock(world, i + 7, j + 8, k + 6, Blocks.air, 0);
		this.setBlock(world, i + 7, j + 8, k + 7, Blocks.air, 0);
		this.setBlock(world, i + 7, j + 8, k + 8, Blocks.air, 0);
		this.setBlock(world, i + 8, j + 0, k + 0, Blocks.air, 0);
		this.setBlock(world, i + 8, j + 0, k + 1, Blocks.air, 0);
		this.setBlock(world, i + 8, j + 0, k + 2, Blocks.air, 0);
		this.setBlock(world, i + 8, j + 0, k + 3, Blocks.air, 0);
		this.setBlock(world, i + 8, j + 0, k + 4, Blocks.air, 0);
		this.setBlock(world, i + 8, j + 0, k + 5, Blocks.air, 0);
		this.setBlock(world, i + 8, j + 0, k + 6, Blocks.air, 0);
		this.setBlock(world, i + 8, j + 0, k + 7, Blocks.air, 0);
		this.setBlock(world, i + 8, j + 0, k + 8, Blocks.air, 0);
		this.setBlock(world, i + 8, j + 1, k + 0, Blocks.air, 0);
		this.setBlock(world, i + 8, j + 1, k + 1, Blocks.air, 0);
		this.setBlock(world, i + 8, j + 1, k + 2, Blocks.air, 0);
		this.setBlock(world, i + 8, j + 1, k + 3, Blocks.air, 0);
		this.setBlock(world, i + 8, j + 1, k + 4, Blocks.air, 0);
		this.setBlock(world, i + 8, j + 1, k + 5, Blocks.air, 0);
		this.setBlock(world, i + 8, j + 1, k + 6, Blocks.air, 0);
		this.setBlock(world, i + 8, j + 1, k + 7, Blocks.air, 0);
		this.setBlock(world, i + 8, j + 1, k + 8, Blocks.air, 0);
		this.setBlock(world, i + 8, j + 2, k + 0, Blocks.air, 0);
		this.setBlock(world, i + 8, j + 2, k + 1, Blocks.air, 0);
		this.setBlock(world, i + 8, j + 2, k + 2, Blocks.air, 0);
		this.setBlock(world, i + 8, j + 2, k + 3, Blocks.air, 0);
		this.setBlock(world, i + 8, j + 2, k + 4, Blocks.air, 0);
		this.setBlock(world, i + 8, j + 2, k + 5, Blocks.air, 0);
		this.setBlock(world, i + 8, j + 2, k + 6, Blocks.air, 0);
		this.setBlock(world, i + 8, j + 2, k + 7, Blocks.air, 0);
		this.setBlock(world, i + 8, j + 2, k + 8, Blocks.air, 0);
		this.setBlock(world, i + 8, j + 3, k + 0, Blocks.air, 0);
		this.setBlock(world, i + 8, j + 3, k + 1, Blocks.sand, 0);
		this.setBlock(world, i + 8, j + 3, k + 2, Blocks.sand, 0);
		this.setBlock(world, i + 8, j + 3, k + 3, Blocks.sand, 0);
		this.setBlock(world, i + 8, j + 3, k + 4, Blocks.sand, 0);
		this.setBlock(world, i + 8, j + 3, k + 5, Blocks.sand, 0);
		this.setBlock(world, i + 8, j + 3, k + 6, Blocks.sand, 0);
		this.setBlock(world, i + 8, j + 3, k + 7, Blocks.sand, 0);
		this.setBlock(world, i + 8, j + 4, k + 1, Blocks.sand, 0);
		this.setBlock(world, i + 8, j + 4, k + 2, Blocks.sand, 0);
		this.setBlock(world, i + 8, j + 4, k + 3, Blocks.sand, 0);
		this.setBlock(world, i + 8, j + 4, k + 4, Blocks.sand, 0);
		this.setBlock(world, i + 8, j + 4, k + 5, Blocks.sand, 0);
		this.setBlock(world, i + 8, j + 4, k + 6, Blocks.sand, 0);
		this.setBlock(world, i + 8, j + 4, k + 7, Blocks.sand, 0);
		this.setBlock(world, i + 8, j + 3, k + 8, Blocks.air, 0);
		this.setBlock(world, i + 8, j + 4, k + 0, Blocks.air, 0);
		this.setBlock(world, i + 8, j + 4, k + 1, Blocks.air, 0);
		this.setBlock(world, i + 8, j + 4, k + 2, Blocks.air, 0);
		this.setBlock(world, i + 8, j + 4, k + 3, Blocks.air, 0);
		this.setBlock(world, i + 8, j + 4, k + 4, Blocks.air, 0);
		this.setBlock(world, i + 8, j + 4, k + 5, Blocks.air, 0);
		this.setBlock(world, i + 8, j + 4, k + 6, Blocks.air, 0);
		this.setBlock(world, i + 8, j + 4, k + 7, Blocks.air, 0);
		this.setBlock(world, i + 8, j + 4, k + 8, Blocks.air, 0);
		this.setBlock(world, i + 8, j + 5, k + 0, Blocks.air, 0);
		this.setBlock(world, i + 8, j + 5, k + 1, Blocks.air, 0);
		this.setBlock(world, i + 8, j + 5, k + 2, Blocks.air, 0);
		this.setBlock(world, i + 8, j + 5, k + 3, Blocks.air, 0);
		this.setBlock(world, i + 8, j + 5, k + 4, Blocks.air, 0);
		this.setBlock(world, i + 8, j + 5, k + 5, Blocks.air, 0);
		this.setBlock(world, i + 8, j + 5, k + 6, Blocks.air, 0);
		this.setBlock(world, i + 8, j + 5, k + 7, Blocks.air, 0);
		this.setBlock(world, i + 8, j + 5, k + 8, Blocks.air, 0);
		this.setBlock(world, i + 8, j + 6, k + 0, Blocks.air, 0);
		this.setBlock(world, i + 8, j + 6, k + 1, Blocks.air, 0);
		this.setBlock(world, i + 8, j + 6, k + 2, Blocks.air, 0);
		this.setBlock(world, i + 8, j + 6, k + 3, Blocks.air, 0);
		this.setBlock(world, i + 8, j + 6, k + 4, Blocks.air, 0);
		this.setBlock(world, i + 8, j + 6, k + 5, Blocks.air, 0);
		this.setBlock(world, i + 8, j + 6, k + 6, Blocks.air, 0);
		this.setBlock(world, i + 8, j + 6, k + 7, Blocks.air, 0);
		this.setBlock(world, i + 8, j + 6, k + 8, Blocks.air, 0);
		this.setBlock(world, i + 8, j + 7, k + 0, Blocks.air, 0);
		this.setBlock(world, i + 8, j + 7, k + 1, Blocks.air, 0);
		this.setBlock(world, i + 8, j + 7, k + 2, Blocks.air, 0);
		this.setBlock(world, i + 8, j + 7, k + 3, Blocks.air, 0);
		this.setBlock(world, i + 8, j + 7, k + 4, Blocks.air, 0);
		this.setBlock(world, i + 8, j + 7, k + 5, Blocks.air, 0);
		this.setBlock(world, i + 8, j + 7, k + 6, Blocks.air, 0);
		this.setBlock(world, i + 8, j + 7, k + 7, Blocks.air, 0);
		this.setBlock(world, i + 8, j + 7, k + 8, Blocks.air, 0);
		this.setBlock(world, i + 8, j + 8, k + 0, Blocks.air, 0);
		this.setBlock(world, i + 8, j + 8, k + 1, Blocks.air, 0);
		this.setBlock(world, i + 8, j + 8, k + 2, Blocks.air, 0);
		this.setBlock(world, i + 8, j + 8, k + 3, Blocks.air, 0);
		this.setBlock(world, i + 8, j + 8, k + 4, Blocks.air, 0);
		this.setBlock(world, i + 8, j + 8, k + 5, Blocks.air, 0);
		this.setBlock(world, i + 8, j + 8, k + 6, Blocks.air, 0);
		this.setBlock(world, i + 8, j + 8, k + 7, Blocks.air, 0);
		this.setBlock(world, i + 8, j + 8, k + 8, Blocks.air, 0);
		this.setBlock(world, i + 3, j + 2, k + 3, Blocks.water, 0);
		this.setBlock(world, i + 3, j + 2, k + 4, Blocks.water, 0);
		this.setBlock(world, i + 3, j + 2, k + 5, Blocks.water, 0);
		this.setBlock(world, i + 3, j + 3, k + 3, Blocks.water, 0);
		this.setBlock(world, i + 3, j + 3, k + 4, Blocks.water, 0);
		this.setBlock(world, i + 3, j + 3, k + 5, Blocks.water, 0);
		this.setBlock(world, i + 3, j + 4, k + 3, Blocks.water, 0);
		this.setBlock(world, i + 3, j + 4, k + 4, Blocks.water, 0);
		this.setBlock(world, i + 3, j + 4, k + 5, Blocks.water, 0);
		this.setBlock(world, i + 4, j + 2, k + 3, Blocks.water, 0);
		this.setBlock(world, i + 4, j + 2, k + 4, Blocks.water, 0);
		this.setBlock(world, i + 4, j + 2, k + 5, Blocks.water, 0);
		this.setBlock(world, i + 4, j + 3, k + 3, Blocks.water, 0);
		this.setBlock(world, i + 4, j + 3, k + 4, Blocks.water, 0);
		this.setBlock(world, i + 4, j + 3, k + 5, Blocks.water, 0);
		this.setBlock(world, i + 4, j + 4, k + 3, Blocks.water, 0);
		this.setBlock(world, i + 4, j + 4, k + 4, Blocks.water, 0);
		this.setBlock(world, i + 4, j + 4, k + 5, Blocks.water, 0);
		this.setBlock(world, i + 5, j + 2, k + 3, Blocks.water, 0);
		this.setBlock(world, i + 5, j + 2, k + 4, Blocks.water, 0);
		this.setBlock(world, i + 5, j + 2, k + 5, Blocks.water, 0);
		this.setBlock(world, i + 5, j + 3, k + 3, Blocks.water, 0);
		this.setBlock(world, i + 5, j + 3, k + 4, Blocks.water, 0);
		this.setBlock(world, i + 5, j + 3, k + 5, Blocks.water, 0);
		this.setBlock(world, i + 5, j + 4, k + 3, Blocks.water, 0);
		this.setBlock(world, i + 5, j + 4, k + 4, Blocks.water, 0);
		this.setBlock(world, i + 5, j + 4, k + 5, Blocks.water, 0);

		return true;
	}
}